Workbook

Sheet Settings
A1: Settings | B1: همه نرخ‌ها/ضرایب سازمانی اینجا ویرایش می‌شوند؛ پیش‌فرض‌ها ASSUMPTION هستند (هیچ عددی داخل فرمول‌ها Hard-code نشده).
A2: Key | B2: Value | C2: Data_Type | D2: ASSUMPTION | E2: Description
A3: Labor_Rate_Per_Hour | B3: 2500000 | C3: Number | D3: YES | E3: ASSUMPTION: نرخ دستمزد ساعتی (IRR)
A4: Manufacturing_Overhead_Rate | B4: 2 | C4: Number | D4: YES | E4: ASSUMPTION: نرخ سربار تولید (× دستمزد مستقیم)
A5: Scrap_Factor | B5: 0.02 | C5: Number | D5: YES | E5: ASSUMPTION: درصد ضایعات فرآیند
A6: Financial_Cost_Rate_Annual | B6: 0.18 | C6: Number | D6: YES | E6: ASSUMPTION: نرخ هزینه مالی سالانه اعتبار
A7: SG&A_Rate | B7: 0.05 | C7: Number | D7: YES | E7: ASSUMPTION: نرخ اداری/فروش (در صورت اعمال سیاست)
A8: Apply_SGA | B8: 1 | C8: Number | D8: YES | E8: 1=اعمال SG&A در Costing (سیاست سازمان)
A9: Tooling_Cost_Per_Project | B9: 100000000 | C9: Number | D9: YES | E9: ASSUMPTION: هزینه قالب پروژه (تسهیم خطی)
A10: Logistics_Base_Cost | B10: 150000000 | C10: Number | D10: YES | E10: ASSUMPTION: هزینه لجستیک پایه پروژه
A11: Packaging_Unit_Cost | B11: 12000000 | C11: Number | D11: NO | E11: از قیمت تأمین‌کننده (MAT-001548)
A12: Reporting_Currency | B12: IRR | C12: Text | D12: NO | E12: ارز گزارشگری
A13: Fx_USD_TO_IRR | B13: 500000 | C13: Number | D13: YES | E13: ASSUMPTION: نرخ تبدیل USD→IRR
A14: Stale_Price_Days | B14: 90 | C14: Number | D14: NO | E14: آستانه قیمت قدیمی (روز)
A15: Max_Margin_Percent | B15: 0.35 | C15: Number | D15: NO | E15: سقف منطقی مارجین برای E-008
A16: Default_Validity_Days | B16: 30 | C16: Number | D16: NO | E16: اعتبار پیش‌فرض پیشنهاد
A17: Seq_Customer | B17: 3 | C17: Number | D17: NO | E17: شمارنده مشتری
A18: Seq_Project | B18: 127 | C18: Number | D18: NO | E18: شمارنده پروژه
A19: Seq_Order | B19: 323 | C19: Number | D19: NO | E19: شمارنده سفارش
A20: Seq_Product | B20: 127 | C20: Number | D20: NO | E20: شمارنده محصول
A21: Seq_Material | B21: 1549 | C21: Number | D21: NO | E21: شمارنده ماده
A22: Seq_Supplier | B22: 91 | C22: Number | D22: NO | E22: شمارنده تأمین‌کننده
A23: Seq_Quote | B23: 550 | C23: Number | D23: NO | E23: شمارنده استعلام
A24: Seq_Quotation | B24: 126 | C24: Number | D24: NO | E24: شمارنده پیشنهاد

Sheet Lists
A1: Lists | B1: فهرست‌های Data Validation (داده‌های مجاز).
A2: List_Name | B2: Value
A3: UoM | B3: pcs
A4: UoM | B4: kg
A5: UoM | B5: m
A6: UoM | B6: m2
A7: UoM | B7: liter
A8: UoM | B8: set
A9: UoM | B9: ton
A10: Currency | B10: IRR
A11: Currency | B11: USD
A12: Currency | B12: EUR
... A70: Price_Status | B70: Expired

Sheet Statuses
A1: Statuses | B1: وضعیت سراسری (Universal Status) — همه جداول از این فهرست استفاده می‌کنند.
A2: Status_ID | B2: Status_Name | C2: Status_Group | D2: Sequence
A3: ST-01 | B3: Draft | C3: Draft | D3: 1
A4: ST-02 | B4: In Review | C4: Review | D4: 2
A5: ST-03 | B5: Waiting Approval | C5: Approval | D5: 3
A6: ST-04 | B6: Approved | C6: Approved | D6: 4
A7: ST-05 | B7: Rejected | C7: Rejected | D7: 5
A8: ST-06 | B8: Returned | C8: Rejected | D8: 6
A9: ST-07 | B9: Closed | C9: Closed | D9: 7
A10: ST-08 | B10: Cancelled | C10: Closed | D10: 8

Sheet Departments
A1: Departments
A2: Department_ID | B2: Department_Name
A3: DEP-01 | B3: Sales
A4: DEP-02 | B4: Engineering
A5: DEP-03 | B5: Planning
A6: DEP-04 | B6: Procurement
A7: DEP-05 | B7: Finance
A8: DEP-06 | B8: PMO
A9: DEP-07 | B9: Management

Sheet Roles
A1: Roles
A2: Role_ID | B2: Role_Name
A3: ROL-01 | B3: Sales Manager
A4: ROL-02 | B4: Sales Rep
A5: ROL-03 | B5: Project Manager
A6: ROL-04 | B6: Engineering Lead
A7: ROL-05 | B7: Planning Manager
A8: ROL-06 | B8: Procurement Manager
A9: ROL-07 | B9: Finance Manager
A10: ROL-08 | B10: Senior Management
A11: ROL-09 | B11: Admin

Sheet Users
A1: Users | B1: کاربران سازمانی؛ Approval_Level پایه ماتریس تأیید است.
A2: User_ID | B2: Name | C2: Department_ID | D2: Role_ID | E2: Email | F2: Approval_Level | G2: Is_Active
A3: USR-01 | B3: Babak A | C3: DEP-01 | D3: ROL-01 | E3: babak@example.com | F3: 2 | G3: 1
A4: USR-02 | B4: Sara S | C4: DEP-01 | D4: ROL-02 | E4: sara@example.com | F4: 1 | G4: 1
A5: USR-03 | B5: Reza M | C5: DEP-06 | D5: ROL-03 | E5: reza@example.com | F5: 3 | G5: 1
A6: USR-04 | B6: Neda E | C6: DEP-02 | D6: ROL-04 | E6: neda@example.com | F6: 3 | G6: 1
A7: USR-05 | B7: Kaveh P | C7: DEP-03 | D7: ROL-05 | E7: kaveh@example.com | F7: 2 | G7: 1
A8: USR-06 | B8: Mina T | C8: DEP-04 | D8: ROL-06 | E8: mina@example.com | F8: 3 | G8: 1
A9: USR-07 | B9: Ali F | C9: DEP-05 | D9: ROL-07 | E9: ali@example.com | F9: 4 | G9: 1
A10: USR-08 | B10: Borna G | C10: DEP-07 | D10: ROL-08 | E10: borna@example.com | F10: 5 | G10: 1

Sheet Approval_Matrix
A1: Approval_Matrix
A2: Entity | B2: Gate | C2: Approver_Role | D2: Min_Approval_Level | E2: Responsible | F2: Reviewer | G2: Approver | H2: Informed
A3: Order | B3: Sales Review | C3: ROL-01 | D3: 2 | E3: Sales Rep | F3: Sales Manager | G3: Sales Manager | H3: PMO
A4: Project | B4: Project Created | C4: ROL-03 | D4: 3 | E4: Project Manager | F4: PMO | G4: PMO | H4: All
A5: BOM | B5: BOM Approval | C5: ROL-04 | D5: 3 | E5: Engineering | F5: Engineering Lead | G5: Engineering Lead | H5: PMO
A6: Supplier | B6: Supplier Selection | C6: ROL-06 | D6: 3 | E6: Procurement | F6: Procurement Manager | G6: Procurement Manager | H6: Finance
A7: Purchase Price | B7: Price Confirm | C7: ROL-06 | D7: 3 | E7: Procurement | F7: Procurement Manager | G7: Procurement Manager | H7: Finance
A8: Costing | B8: Finance Review | C8: ROL-07 | D8: 4 | E8: Finance | F8: Finance Manager | G8: Finance Manager | H8: Sales
A9: Quotation | B9: Sales Quotation | C9: ROL-01 | D9: 3 | E9: Sales Manager | F9: Sales Manager | G9: Sales Manager | H9: Management
A10: Quotation | B10: Management Approval | C10: ROL-08 | D10: 5 | E10: Sales Manager | F10: Senior Management | G10: Senior Management | H10: All
A11: * | B11: Post-Approval Change | C11: ROL-08 | D11: 5 | E11: Owner | F11: Owner Approver | G11: Owner Approver | H11: Management

Sheet RACI
A1: RACI
A2: Activity | B2: Sales | C2: Engineering | D2: Planning | E2: Procurement | F2: Finance | G2: PMO | H2: Management
A3: Register Order | B3: R/A | C3: I
A4: Initial Check | B4: R | C4: C | G4: I
A5: Create Project | B5: I | C5: I | D5: I | E5: I | F5: I | G5: R/A | H5: I
A6: Engineering + BOM | B6: C | C6: R/A | D6: C | E6: C | G6: I
A7: BOM Approval | B7: I | C7: A | D7: C | E7: C | G7: I | H7: I
A8: Planning | B8: I | C8: C | D8: R/A | E8: I | G8: I
A9: Scheduling | B9: I | C9: C | D9: R/A | E9: C | G9: I | H9: I
A10: Supplier Enquiry | C10: C | D10: I | E10: R | F10: I | G10: I
A11: Supplier Selection | C11: C | D11: I | E11: R/A | F11: C | G11: I | H11: I
A12: Purchase Price Register | C12: C | D12: I | E12: R | F12: I | G12: I
A13: Costing | B13: C | C13: C | D13: C | E13: C | F13: R/A | G13: I | H13: I
A14: Budget | B14: I | C14: C | D14: C | E14: C | F14: R/A | G14: I | H14: I
A15: Sales Quotation | B15: R/A | C15: C | D15: I | E15: C | F15: C | G15: I | H15: I
A16: Payment Terms | B16: R | F16: C | H16: A
A17: Management Decision | B17: I | C17: I | D17: I | E17: I | F17: I | G17: I | H17: R/A

Sheet Customers
A1: Customers
A2: System_ID | B2: Customer_Code | C2: Customer_Name | D2: Legal_Name | E2: Customer_Type | F2: Country | G2: City | H2: Delivery_Location | I2: Payment_Condition | J2: Credit_Limit | K2: Currency | L2: Tax_Status | M2: Is_Active | N2: Sales_Owner | O2: Notes
A3: CUS-000001 | B3: CUS-1 | C3: صنایع پتروشیمی صبا | D3: شرکت صنایع پتروشیمی صبا (سهامی خاص) | E3: Corporate | F3: Iran | G3: عسلویه | H3: سایت عسلویه، فاز ۲ | I3: 30% پیش‌پرداخت + 70% اعتبار 60 روزه | J3: 25000000000 | K3: IRR | L3: VAT | M3: 1 | N3: USR-02 | O3: مشتری کلیدی؛ سابقه پرداخت خوب
A4: CUS-000002 | B4: CUS-2 | C4: پالایش نفت ستاره | D4: شرکت پالایش نفت ستاره | E4: Corporate | F4: Iran | G4: بندرعباس | H4: انبار مرکزی بندرعباس | I4: LC دیداری | J4: 20000000000 | K4: IRR | L4: VAT | M4: 1 | N4: USR-02 | O4: سفارش‌های فصلی

Sheet Products
A1: Products
A2: System_ID | B2: Product_Code | C2: Product_Name | D2: Product_Type | E2: Base_UoM | F2: Category | G2: Is_Active
A3: PRD-000125 | B3: PMP-250 | C3: پمپ گریز از مرکز سرویس سنگین PMP-250 | D3: Finished Good | E3: pcs | F3: Pumps | G3: 1
A4: PRD-000126 | B4: PMP-150 | C4: پمپ گریز از مرکز PMP-150 | D4: Finished Good | E4: pcs | F4: Pumps | G4: 1

Sheet Product_Revisions
A1: Product_Revisions
A2: System_ID | B2: Product_ID | C2: Revision_No | D2: Drawing_No | E2: Drawing_Revision | F2: BOM_Policy | G2: Approved_By | H2: Approve_Date | I2: Change_Reason
A3: PRV-000125-R03 | B3: PRD-000125 | C3: R03 | D3: DRW-250-A | E3: Rev C | F3: Each Rev = New BOM Revision | G3: USR-04 | H3: 46275 | I3: به‌روزرسانی متریال پروانه طبق استاندارد جدید
A4: PRV-000126-R02 | B4: PRD-000126 | C4: R02 | D4: DRW-150-B | E4: Rev B | F4: Each Rev = New BOM Revision | G4: USR-04 | H4: 46174 | I4: اصلاح تلورانس

Sheet Materials
A1: Materials
A2: System_ID | B2: Material_Code | C2: Material_Description | D2: Material_Type | E2: Specification | F2: UoM | G2: Make_Buy_Default | H2: Preferred_Supplier | I2: Is_Active
A3: MAT-001542 | B3: MAT-01 | C3: پوسته چدنی (Cast Iron Casing) | D3: Raw Material | E3: GG-25 مطابق DIN 1691 | F3: kg | G3: Make | I3: 1
A4: MAT-001543 | B4: MAT-02 | C4: پروانه فولاد ضدزنگ (Impeller SS316) | D4: Raw Material | E4: AISI 316L | F4: kg | G4: Make | I4: 1
A5: MAT-001544 | B5: MAT-03 | C5: بلبرینگ کف‌گرد (Thrust Bearing) | D5: Purchased Part | E5: SKF 29420 E | F5: pcs | G5: Buy | H5: SUP-000089 | I5: 1
A6: MAT-001545 | B6: MAT-04 | C6: مکانیکال سیل (Mechanical Seal) | D6: Purchased Part | E6: EagleBurgmann H74 | F6: pcs | G6: Buy | H6: SUP-000088 | I6: 1
A7: MAT-001546 | B7: MAT-05 | C7: الکتروموتور 45kW | D7: Purchased Part | E7: IEC 400V 50Hz IM B3 | F7: pcs | G7: Buy | H7: SUP-000087 | I7: 1
A8: MAT-001547 | B8: MAT-06 | C8: شفت فولادی (Shaft CK45) | D8: Raw Material | E8: CK45 مطابق DIN 17200 | F8: kg | G8: Make | I8: 1
A9: MAT-001548 | B9: MAT-07 | C9: بسته‌بندی صادراتی چوبی | D9: Packaging | E9: ISPM-15 | F9: pcs | G9: Buy | H9: SUP-000086 | I9: 1

Sheet Suppliers
A1: Suppliers
A2: System_ID | B2: Supplier_Code | C2: Supplier_Name | D2: Legal_Name | E2: Country | F2: Currency | G2: Payment_Terms_Default | H2: Incoterm_Default | I2: Rating | J2: Approval_Status | K2: Contact | L2: Is_Active
A3: SUP-000086 | B3: SUP-86 | C3: بسته‌بندی پارس | D3: بسته‌بندی پارس (چوب) | E3: Iran | F3: IRR | G3: 30 روزه | H3: EXW | I3: 4 | J3: Approved | K3: تلفن 021-1111 | L3: 1
A4: SUP-000087 | B4: SUP-87 | C4: الکتروموتور توان | D4: موتور توان (نماینده زیمنس) | E4: Iran | F4: IRR | G4: 45 روزه | H4: CPT | I4: 4 | J4: Approved | K4: تلفن 021-2222 | L4: 1
A5: SUP-000088 | B5: SUP-88 | C5: سیل آریا | D5: سیل‌های مکانیکی آریا | E5: Iran | F5: IRR | G5: 30 روزه | H5: CPT | I5: 5 | J5: Approved | K5: تلفن 021-3333 | L5: 1
A6: SUP-000089 | B6: SUP-89 | C6: بلبرینگ ایران | D6: بلبرینگ‌های صنعتی ایران | E6: Iran | F6: IRR | G6: 30 روزه | H6: CPT | I6: 4 | J6: Approved | K6: تلفن 021-4444 | L6: 1
A7: SUP-000090 | B7: SUP-90 | C7: فولاد جنوب | D7: فولاد جنوب (ریخته‌گری) | E7: Iran | F7: IRR | G7: 45 روزه | H7: EXW | I7: 3 | J7: Approved | K7: تلفن 071-5555 | L7: 1

Sheet Inventory
A1: Inventory | B1: موجودی/رزرو برای محاسبه کسری در Planning.
A2: System_ID | B2: Material_ID | C2: Stock_On_Hand | D2: Reserved
A3: INV-0001 | B3: MAT-001542 | C3: 500 | D3: 0
A4: INV-0002 | B4: MAT-001543 | C4: 120 | D4: 0
A5: INV-0003 | B5: MAT-001544 | C5: 6 | D5: 2
A6: INV-0004 | B6: MAT-001545 | C6: 4 | D6: 1
A7: INV-0005 | B7: MAT-001546 | C7: 2 | D7: 0
A8: INV-0006 | B8: MAT-001547 | C8: 80 | D8: 0
A9: INV-0007 | B9: MAT-001548 | C9: 3 | D9: 0

Sheet Orders
A1: Orders | B1: کنترل اولیه سفارش (CO_01..CO_04)؛ تا Ready_Flag=READY نباشد ورود به مهندسی مجاز نیست.
A2: System_ID | B2: Customer_ID | C2: Order_Date | D2: Requested_Delivery_Date | E2: Request_Type | F2: Total_Qty | G2: Delivery_Terms | H2: Payment_Terms | I2: Validity_Days | J2: Confidentiality_Level | K2: Sales_Responsible | L2: Doc_Ref | M2: Status_ID | N2: CO_01_Customer_Valid | O2: CO_02_Qty_Defined | P2: CO_03_Delivery_Defined | Q2: CO_04_Payment_Defined | R2: Ready_Flag | S2: Duplicate_Flag | T2: Create_Date | U2: Created_By
A3: ORD-2026-00321 | B3: CUS-000001 | C3: 46285 | D3: 46376 | E3: New | F3: =SUMIF(Order_Lines!$B$3:$B$20,$A3,Order_Lines!$E$3:$E$20) | G3: CPT سایت عسلویه | H3: 30% پیش‌پرداخت + 70% اعتبار 60 روزه | I3: 30 | J3: Confidential | K3: USR-02 | L3: RFQ-SABA-2026-09-001 | M3: Approved | N3: =IF(TRIM($B3)<>"","OK","MISSING") | O3: =IF(SUMIF(Order_Lines!$B$3:$B$20,$A3,Order_Lines!$E$3:$E$20)>0,"OK","MISSING") | P3: =IF(TRIM($D3)<>"","OK","MISSING") | Q3: =IF(TRIM($H3)<>"","OK","MISSING") | R3: =IF(AND($N3="OK",$O3="OK",$P3="OK",$Q3="OK"),"READY","INCOMPLETE") | S3: =IF(COUNTIF($A$3:$A$1000,$A3)>1,"DUP","OK") | T3: 46285 | U3: USR-02
A4: ORD-2026-00322 | B4: CUS-000002 | C4: 46286 | D4: 46402 | E4: New | F4: =SUMIF(Order_Lines!$B$3:$B$20,$A4,Order_Lines!$E$3:$E$20) | G4: CPT بندرعباس | H4: LC | I4: 45 | J4: Internal | K4: USR-02 | L4: RFQ-STAREH-2026-09-002 | M4: Draft | N4: =IF(TRIM($B4)<>"","OK","MISSING") | O4: =IF(SUMIF(Order_Lines!$B$3:$B$20,$A4,Order_Lines!$E$3:$E$20)>0,"OK","MISSING") | P4: =IF(TRIM($D4)<>"","OK","MISSING") | Q4: =IF(TRIM($H4)<>"","OK","MISSING") | R4: =IF(AND($N4="OK",$O4="OK",$P4="OK",$Q4="OK"),"READY","INCOMPLETE") | S4: =IF(COUNTIF($A$3:$A$1000,$A4)>1,"DUP","OK") | T4: 46285 | U4: USR-02
A5: ORD-2026-00323 | B5: CUS-000001 | C5: 46286 | E5: New | F5: =SUMIF(Order_Lines!$B$3:$B$20,$A5,Order_Lines!$E$3:$E$20) | I5: 30 | J5: Internal | K5: USR-02 | L5: RFQ-SABA-2026-09-009 | M5: Draft | N5: =IF(TRIM($B5)<>"","OK","MISSING") | O5: =IF(SUMIF(Order_Lines!$B$3:$B$20,$A5,Order_Lines!$E$3:$E$20)>0,"OK","MISSING") | P5: =IF(TRIM($D5)<>"","OK","MISSING") | Q5: =IF(TRIM($H5)<>"","OK","MISSING") | R5: =IF(AND($N5="OK",$O5="OK",$P5="OK",$Q5="OK"),"READY","INCOMPLETE") | S5: =IF(COUNTIF($A$3:$A$1000,$A5)>1,"DUP","OK") | T5: 46285 | U5: USR-02

Sheet Order_Lines
A1: Order_Lines | B1: هر سفارش می‌تواند چند ردیف محصول داشته باشد (Order → Order_Line → Product).
A2: System_ID | B2: Order_ID | C2: Line_No | D2: Product_ID | E2: Quantity | F2: UoM | G2: Latest_FLAG | H2: Create_Date | I2: Created_By
A3: OLN-000456 | B3: ORD-2026-00321 | C3: 1 | D3: PRD-000125 | E3: 2 | F3: pcs | G3: 1 | H3: 46285 | I3: USR-02
A4: OLN-000457 | B4: ORD-2026-00321 | C4: 2 | D4: PRD-000126 | E4: 1 | F4: pcs | G4: 1 | H4: 46285 | I4: USR-02
A5: OLN-000458 | B5: ORD-2026-00322 | C5: 1 | D5: PRD-000125 | E5: 1 | F5: pcs | G5: 1 | H5: 46285 | I5: USR-02

Sheet Projects
A1: Projects
A2: System_ID | B2: Project_Code | C2: Order_ID | D2: Customer_ID | E2: Product_ID | F2: Project_Name | G2: Project_Manager | H2: Start_Date | I2: Due_Date | J2: Priority | K2: Status_ID | L2: Progress_% | M2: Sponsor | N2: Team_List | O2: Overdue_Flag | P2: Create_Date | Q2: Created_By
A3: PRJ-2026-00125 | B3: PRJ-001 | C3: ORD-2026-00321 | D3: CUS-000001 | E3: PRD-000125 | F3: پمپ PMP-250 صبا | G3: USR-03 | H3: 46286 | I3: 46376 | J3: High | K3: Approved | L3: 0.45 | M3: USR-08 | N3: Neda E, Kaveh P, Mina T, Ali F | O3: =IF(ISBLANK($I3),0,IF(AND($I3<TODAY(),$K3<>"Closed"),1,0)) | P3: 46286 | Q3: USR-03
A4: PRJ-2026-00126 | B4: PRJ-002 | C4: ORD-2026-00322 | D4: CUS-000002 | E4: PRD-000125 | F4: پمپ PMP-250 ستاره | G4: USR-03 | H4: 46287 | I4: 46402 | J4: Medium | K4: Draft | L4: 0.05 | M4: USR-08 | N4: TBD | O4: =IF(ISBLANK($I4),0,IF(AND($I4<TODAY(),$K4<>"Closed"),1,0)) | P4: 46286 | Q4: USR-03

Sheet Project_Statuses
A1: Project_Statuses
A2: System_ID | B2: Project_ID | C2: Stage | D2: Stage_Status | E2: Start_Date | F2: End_Date | G2: Remark
A3: PS-0001 | B3: PRJ-2026-00125 | C3: Sales | D3: Completed | E3: 46285 | F3: 46286
A4: PS-0002 | B4: PRJ-2026-00125 | C4: Engineering | D4: Completed | E4: 46286 | F4: 46295 | G4: BOM R5 تأیید شد
A5: PS-0003 | B5: PRJ-2026-00125 | C5: Planning | D5: In Progress | E5: 46296 | G5: برآورد نیاز در حال انجام
A6: PS-0004 | B6: PRJ-2026-00125 | C6: Procurement | D6: Pending
A7: PS-0005 | B7: PRJ-2026-00125 | C7: Finance | D7: Pending
A8: PS-0006 | B8: PRJ-2026-00125 | C8: Management | D8: Pending
A9: PS-0007 | B9: PRJ-2026-00126 | C9: Sales | D9: In Review | E9: 46286
A10: PS-0008 | B10: PRJ-2026-00126 | C10: Engineering | D10: Pending
A11: PS-0009 | B11: PRJ-2026-00126 | C11: Planning | D11: Pending
A12: PS-0010 | B12: PRJ-2026-00126 | C12: Procurement | D12: Pending
A13: PS-0011 | B13: PRJ-2026-00126 | C13: Finance | D13: Pending
A14: PS-0012 | B14: PRJ-2026-00126 | C14: Management | D14: Pending

Sheet Engineering
A1: Engineering
A2: System_ID | B2: Project_ID | C2: Product_ID | D2: Product_Revision_ID | E2: Drawing_No | F2: Drawing_Revision | G2: BOM_Revision_ID | H2: Status_ID | I2: Process | J2: Machine | K2: Tooling | L2: Packaging | M2: Engineering_Notes | N2: Submitted_By | O2: Approved_By | P2: Create_Date | Q2: Created_By
A3: ENG-000125 | B3: PRJ-2026-00125 | C3: PRD-000125 | D3: PRV-000125-R03 | E3: DRW-250-A | F3: Rev C | G3: BOM-000215-R05 | H3: Approved | I3: Machining + Assembly | J3: CNC-5Axis | K3: Fixture-250 | L3: ISPM-15 | M3: مطابق نقشه DRW | N3: USR-04 | O3: USR-04 | P3: 46290 | Q3: USR-04
A4: ENG-000126 | B4: PRJ-2026-00125 | C4: PRD-000126 | D4: PRV-000126-R02 | E4: DRW-150-B | F4: Rev B | G4: BOM-000216-R02 | H4: Approved | I4: Machining + Assembly | J4: CNC-5Axis | K4: Fixture-250 | L4: ISPM-15 | M4: مطابق نقشه DRW | N4: USR-04 | O4: USR-04 | P4: 46290 | Q4: USR-04

Sheet BOM_Header
A1: BOM_Header | B1: نسخه‌بندی BOM؛ نسخه قبلی هرگز Overwrite نمی‌شود (Is_Active=0 / Status=Superseded).
A2: System_ID | B2: BOM_ID | C2: Product_Revision_ID | D2: Revision_No | E2: Rev_Date | F2: Change_Reason | G2: Changed_By | H2: Approved_By | I2: Status_ID | J2: Is_Active | K2: Create_Date | L2: Created_By
A3: BOM-000215-R05 | B3: BOM-000215 | C3: PRV-000125-R03 | D3: R05 | E3: 46293 | F3: تغییر تأمین‌کننده مکانیکال سیل و افزودن شفت | G3: USR-04 | H3: USR-04 | I3: Approved | J3: 1 | K3: 46293 | L3: USR-04
A4: BOM-000215-R04 | B4: BOM-000215 | C4: PRV-000125-R03 | D4: R04 | E4: 46235 | F4: نسخه قبلی (نگهداری برای Audit — بدون Overwrite) | G4: USR-04 | H4: USR-04 | I4: Superseded | J4: 0 | K4: 46235 | L4: USR-04
A5: BOM-000216-R02 | B5: BOM-000216 | C5: PRV-000126-R02 | D5: R02 | E5: 46178 | F5: نسخه اولیه | G5: USR-04 | H5: USR-04 | I5: Approved | J5: 1 | K5: 46178 | L5: USR-04

Sheet BOM_Detail
A1: BOM_Detail | B1: BOM چندسطحی (Parent_BOM_Line_ID / Level_No / Sequence_No). Gross_Qty = Qty_Per × (1 + Scrap%).
A2: System_ID | B2: BOM_Revision_ID | C2: Parent_BOM_Line_ID | D2: Level_No | E2: Sequence_No | F2: Material_ID | G2: Qty_Per | H2: UoM | I2: Scrap_% | J2: Net_Qty | K2: Gross_Qty | L2: Make_Buy | M2: Approved_Supplier | N2: Create_Date | O2: Created_By
A3: BLI-000987 | B3: BOM-000215-R05 | D3: 0 | E3: 10 | F3: PRD-000125 | G3: 1 | H3: pcs | I3: 0 | J3: =$G3 | K3: =ROUND($G3*(1+$I3),3) | L3: Make | N3: 46293 | O3: USR-04
A4: BLI-000988 | B4: BOM-000215-R05 | C4: BLI-000987 | D4: 1 | E4: 20 | F4: MAT-001542 | G4: 180 | H4: kg | I4: 0.05 | J4: =$G4 | K4: =ROUND($G4*(1+$I4),3) | L4: Make | N4: 46293 | O4: USR-04
A5: BLI-000989 | B5: BOM-000215-R05 | C5: BLI-000987 | D5: 1 | E5: 30 | F5: MAT-001543 | G5: 55 | H5: kg | I5: 0.05 | J5: =$G5 | K5: =ROUND($G5*(1+$I5),3) | L5: Make | N5: 46293 | O5: USR-04
A6: BLI-000990 | B6: BOM-000215-R05 | C6: BLI-000987 | D6: 1 | E6: 40 | F6: MAT-001547 | G6: 22 | H6: kg | I6: 0.05 | J6: =$G6 | K6: =ROUND($G6*(1+$I6),3) | L6: Make | N6: 46293 | O6: USR-04
A7: BLI-000991 | B7: BOM-000215-R05 | C7: BLI-000987 | D7: 1 | E7: 50 | F7: MAT-001544 | G7: 1 | H7: pcs | I7: 0 | J7: =$G7 | K7: =ROUND($G7*(1+$I7),3) | L7: Buy | M7: SUP-000089 | N7: 46293 | O7: USR-04
A8: BLI-000992 | B8: BOM-000215-R05 | C8: BLI-000987 | D8: 1 | E8: 60 | F8: MAT-001545 | G8: 1 | H8: pcs | I8: 0 | J8: =$G8 | K8: =ROUND($G8*(1+$I8),3) | L8: Buy | M8: SUP-000088 | N8: 46293 | O8: USR-04
A9: BLI-000993 | B9: BOM-000215-R05 | C9: BLI-000987 | D9: 1 | E9: 70 | F9: MAT-001546 | G9: 1 | H9: pcs | I9: 0 | J9: =$G9 | K9: =ROUND($G9*(1+$I9),3) | L9: Buy | M9: SUP-000087 | N9: 46293 | O9: USR-04
A10: BLI-000994 | B10: BOM-000215-R05 | C10: BLI-000987 | D10: 1 | E10: 80 | F10: MAT-001548 | G10: 1 | H10: pcs | I10: 0 | J10: =$G10 | K10: =ROUND($G10*(1+$I10),3) | L10: Buy | M10: SUP-000086 | N10: 46293 | O10: USR-04
A11: BLI-000950 | B11: BOM-000215-R04 | D11: 0 | E11: 10 | F11: PRD-000125 | G11: 1 | H11: pcs | I11: 0 | J11: =$G11 | K11: =ROUND($G11*(1+$I11),3) | L11: Make | N11: 46293 | O11: USR-04
A12: BLI-000951 | B12: BOM-000215-R04 | C12: BLI-000950 | D12: 1 | E12: 20 | F12: MAT-001542 | G12: 180 | H12: kg | I12: 0.05 | J12: =$G12 | K12: =ROUND($G12*(1+$I12),3) | L12: Make | N12: 46293 | O12: USR-04
A13: BLI-000952 | B13: BOM-000215-R04 | C13: BLI-000950 | D13: 1 | E13: 30 | F13: MAT-001543 | G13: 55 | H13: kg | I13: 0.05 | J13: =$G13 | K13: =ROUND($G13*(1+$I13),3) | L13: Make | N13: 46293 | O13: USR-04
A14: BLI-000953 | B14: BOM-000215-R04 | C14: BLI-000950 | D14: 1 | E14: 40 | F14: MAT-001547 | G14: 22 | H14: kg | I14: 0.05 | J14: =$G14 | K14: =ROUND($G14*(1+$I14),3) | L14: Make | N14: 46293 | O14: USR-04
A15: BLI-000954 | B15: BOM-000215-R04 | C15: BLI-000950 | D15: 1 | E15: 50 | F15: MAT-001544 | G15: 1 | H15: pcs | I15: 0 | J15: =$G15 | K15: =ROUND($G15*(1+$I15),3) | L15: Buy | M15: SUP-000089 | N15: 46293 | O15: USR-04
A16: BLI-000955 | B16: BOM-000215-R04 | C16: BLI-000950 | D16: 1 | E16: 60 | F16: MAT-001545 | G16: 1 | H16: pcs | I16: 0 | J16: =$G16 | K16: =ROUND($G16*(1+$I16),3) | L16: Buy | M16: SUP-000088 | N16: 46293 | O16: USR-04
A17: BLI-000956 | B17: BOM-000215-R04 | C17: BLI-000950 | D17: 1 | E17: 70 | F17: MAT-001546 | G17: 1 | H17: pcs | I17: 0 | J17: =$G17 | K17: =ROUND($G17*(1+$I17),3) | L17: Buy | M17: SUP-000087 | N17: 46293 | O17: USR-04
A18: BLI-000957 | B18: BOM-000215-R04 | C18: BLI-000950 | D18: 1 | E18: 80 | F18: MAT-001548 | G18: 1 | H18: pcs | I18: 0 | J18: =$G18 | K18: =ROUND($G18*(1+$I18),3) | L18: Buy | M18: SUP-000086 | N18: 46293 | O18: USR-04
A19: BLI-000900 | B19: BOM-000216-R02 | D19: 0 | E19: 10 | F19: PRD-000126 | G19: 1 | H19: pcs | I19: 0 | J19: =$G19 | K19: =ROUND($G19*(1+$I19),3) | L19: Make | N19: 46293 | O19: USR-04
A20: BLI-000901 | B20: BOM-000216-R02 | C20: BLI-000900 | D20: 1 | E20: 20 | F20: MAT-001542 | G20: 95 | H20: kg | I20: 0.05 | J20: =$G20 | K20: =ROUND($G20*(1+$I20),3) | L20: Make | N20: 46293 | O20: USR-04
A21: BLI-000902 | B21: BOM-000216-R02 | C21: BLI-000900 | D21: 1 | E21: 30 | F21: MAT-001547 | G21: 14 | H21: kg | I21: 0.05 | J21: =$G21 | K21: =ROUND($G21*(1+$I21),3) | L21: Make | N21: 46293 | O21: USR-04
A22: BLI-000903 | B22: BOM-000216-R02 | C22: BLI-000900 | D22: 1 | E22: 40 | F22: MAT-001544 | G22: 1 | H22: pcs | I22: 0 | J22: =$G22 | K22: =ROUND($G22*(1+$I22),3) | L22: Buy | M22: SUP-000089 | N22: 46293 | O22: USR-04
A23: BLI-000904 | B23: BOM-000216-R02 | C23: BLI-000900 | D23: 1 | E23: 50 | F23: MAT-001545 | G23: 1 | H23: pcs | I23: 0 | J23: =$G23 | K23: =ROUND($G23*(1+$I23),3) | L23: Buy | M23: SUP-000088 | N23: 46293 | O23: USR-04
A24: BLI-000905 | B24: BOM-000216-R02 | C24: BLI-000900 | D24: 1 | E24: 60 | F24: MAT-001546 | G24: 1 | H24: pcs | I24: 0 | J24: =$G24 | K24: =ROUND($G24*(1+$I24),3) | L24: Buy | M24: SUP-000087 | N24: 46293 | O24: USR-04
A25: BLI-000906 | B25: BOM-000216-R02 | C25: BLI-000900 | D25: 1 | E25: 70 | F25: MAT-001548 | G25: 1 | H25: pcs | I25: 0 | J25: =$G25 | K25: =ROUND($G25*(1+$I25),3) | L25: Buy | M25: SUP-000086 | N25: 46293 | O25: USR-04

Sheet Supplier_Quotes
A1: Supplier_Quotes | B1: استعلام به تفکیک ماده؛ انتخاب تأمین‌کننده در ردیف‌ها (نه فقط کمترین قیمت) توسط مسئول مجاز.
A2: System_ID | B2: Project_ID | C2: Material_ID | D2: Qty_Required | E2: Quoted_Date | F2: Valid_Until | G2: Status_ID | H2: Selected_Line_ID | I2: Create_Date | J2: Created_By
A3: SQT-2026-00545 | B3: PRJ-2026-00125 | C3: MAT-001545 | D3: 2 | E3: 46280 | F3: 46366 | G3: Closed | H3: SQL-002354 | I3: 46280 | J3: USR-06
A4: SQT-2026-00546 | B4: PRJ-2026-00125 | C4: MAT-001544 | D4: 2 | E4: 46280 | F4: 46346 | G4: Closed | H4: SQL-002360 | I4: 46280 | J4: USR-06
A5: SQT-2026-00547 | B5: PRJ-2026-00125 | C5: MAT-001546 | D5: 2 | E5: 46280 | F5: 46357 | G5: Closed | H5: SQL-002364 | I5: 46280 | J5: USR-06
A6: SQT-2026-00548 | B6: PRJ-2026-00125 | C6: MAT-001548 | D6: 2 | E6: 46280 | F6: 46376 | G6: Closed | H6: SQL-002368 | I6: 46280 | J6: USR-06

Sheet Supplier_Quote_Lines
A1: Supplier_Quote_Lines | B1: معیارهای قیمت/کیفیت/زمان/ریسک؛ Score_Total صرفاً جنبه مقایسه دارد و سیستم به‌طور خودکار «بهترین» را اعلام نمی‌کند.
A2: System_ID | B2: Supplier_Quote_ID | C2: Supplier_ID | D2: Unit_Price | E2: Currency | F2: MOQ | G2: Lead_Time_Days | H2: Payment_Terms | I2: Incoterm | J2: Freight | K2: Valid_To | L2: Price_Source | M2: Price_Confirm_Status | N2: Quality_Score | O2: OnTime_Score | P2: Capacity_Score | Q2: Risk_Score | R2: Longevity_Score | S2: Score_Total | T2: Selected | U2: Landed_Estimate | V2: Create_Date | W2: Created_By
A3: SQL-002354 | B3: SQT-2026-00545 | C3: SUP-000088 | D3: 185000000 | E3: IRR | F3: 1 | G3: 30 | H3: 30 days | I3: CPT | J3: 2000000 | K3: 46356 | L3: Email Quote 12-Sep | M3: Confirmed | N3: 5 | O3: 5 | P3: 4 | Q3: 2 | R3: 3 | S3: =SUM($N3:$R3) | T3: 1 | U3: =$D3+$J3 | V3: 46280 | W3: USR-06
A4: SQL-002355 | B4: SQT-2026-00545 | C4: SUP-000089 | D4: 172000000 | E4: IRR | F4: 2 | G4: 45 | H4: 60 days | I4: CPT | J4: 2500000 | K4: 46341 | L4: Portal RFQ | M4: Confirmed | N4: 4 | O4: 4 | P4: 3 | Q4: 3 | R4: 3 | S4: =SUM($N4:$R4) | T4: 0 | U4: =$D4+$J4 | V4: 46280 | W4: USR-06
A5: SQL-002356 | B5: SQT-2026-00545 | C5: SUP-000090 | D5: 190000000 | E5: IRR | F5: 1 | G5: 25 | H5: advance | I5: EXW | J5: 3000000 | K5: 46366 | L5: Phone + Email | M5: Confirmed | N5: 3 | O5: 3 | P5: 2 | Q5: 4 | R5: 2 | S5: =SUM($N5:$R5) | T5: 0 | U5: =$D5+$J5 | V5: 46280 | W5: USR-06
A6: SQL-002360 | B6: SQT-2026-00546 | C6: SUP-000089 | D6: 95000000 | E6: IRR | F6: 1 | G6: 25 | H6: 30 days | I6: CPT | J6: 1200000 | K6: 46346 | L6: Email Quote 14-Sep | M6: Confirmed | N6: 5 | O6: 4 | P6: 4 | Q6: 2 | R6: 4 | S6: =SUM($N6:$R6) | T6: 1 | U6: =$D6+$J6 | V6: 46280 | W6: USR-06
A7: SQL-002361 | B7: SQT-2026-00546 | C7: SUP-000090 | D7: 99000000 | E7: IRR | F7: 1 | G7: 30 | H7: 45 days | I7: EXW | J7: 1500000 | K7: 46336 | L7: Portal RFQ | M7: Confirmed | N7: 4 | O7: 3 | P7: 3 | Q7: 3 | R7: 3 | S7: =SUM($N7:$R7) | T7: 0 | U7: =$D7+$J7 | V7: 46280 | W7: USR-06
A8: SQL-002364 | B8: SQT-2026-00547 | C8: SUP-000087 | D8: 2500 | E8: USD | F8: 1 | G8: 45 | H8: 45 days | I8: CPT | J8: 30 | K8: 46357 | L8: Signed Quote | M8: Confirmed | N8: 5 | O8: 4 | P8: 5 | Q8: 2 | R8: 5 | S8: =SUM($N8:$R8) | T8: 1 | U8: =$D8+$J8 | V8: 46280 | W8: USR-06
A9: SQL-002365 | B9: SQT-2026-00547 | C9: SUP-000090 | D9: 1220000000 | E9: IRR | F9: 2 | G9: 60 | H9: 60 days | I9: EXW | J9: 18000000 | K9: 46351 | L9: Email Quote | M9: Confirmed | N9: 4 | O9: 3 | P9: 4 | Q9: 3 | R9: 4 | S9: =SUM($N9:$R9) | T9: 0 | U9: =$D9+$J9 | V9: 46280 | W9: USR-06
A10: SQL-002368 | B10: SQT-2026-00548 | C10: SUP-000086 | D10: 12000000 | E10: IRR | F10: 1 | G10: 10 | H10: cash | I10: EXW | J10: 0 | K10: 46376 | L10: Price list | M10: Confirmed | N10: 4 | O10: 5 | P10: 5 | Q10: 1 | R10: 5 | S10: =SUM($N10:$R10) | T10: 1 | U10: =$D10+$J10 | V10: 46280 | W10: USR-06

Sheet Procurement
A1: Procurement | B1: تصمیم خرید تأییدشده + Price Build-up: Unit + Freight + Insurance + Customs + Handling + Other = Landed (با تبدیل ارز).
A2: System_ID | B2: Project_ID | C2: Material_ID | D2: Supplier_ID | E2: Buyer | F2: Currency | G2: Fx_Rate | H2: Buy_Qty | I2: Unit_Purchase_Price | J2: MOQ_Applied | K2: Lead_Time_Days | L2: Payment_Terms | M2: Incoterm | N2: Freight_Per_Unit | O2: Insurance_Per_Unit | P2: Customs_Per_Unit | Q2: Handling_Per_Unit | R2: Other_Per_Unit | S2: Landed_Cost_Unit | T2: Price_Date | U2: Price_Source | V2: Price_Valid_To | W2: Price_Expired_Flag | X2: Status_ID | Y2: Create_Date | Z2: Created_By
A3: PRC-0001 | B3: PRJ-2026-00125 | C3: MAT-001545 | D3: SUP-000088 | E3: USR-06 | F3: IRR | G3: 1 | H3: 2 | I3: 185000000 | J3: 1 | K3: 30 | L3: 30 days | M3: CPT | N3: 2000000 | O3: 0 | P3: 0 | Q3: 0 | R3: 0 | S3: =ROUND(($I3+$N3+$O3+$P3+$Q3+$R3)*$G3,0) | T3: 46280 | U3: Email Quote 12-Sep | V3: 46356 | W3: =IF(ISBLANK($V3),"",IF($V3<TODAY(),1,0)) | X3: Approved | Y3: 46293 | Z3: USR-06
A4: PRC-0002 | B4: PRJ-2026-00125 | C4: MAT-001544 | D4: SUP-000089 | E4: USR-06 | F4: IRR | G4: 1 | H4: 2 | I4: 95000000 | J4: 1 | K4: 25 | L4: 30 days | M4: CPT | N4: 1200000 | O4: 0 | P4: 0 | Q4: 0 | R4: 0 | S4: =ROUND(($I4+$N4+$O4+$P4+$Q4+$R4)*$G4,0) | T4: 46280 | U4: Email Quote 14-Sep | V4: 46346 | W4: =IF(ISBLANK($V4),"",IF($V4<TODAY(),1,0)) | X4: Approved | Y4: 46293 | Z4: USR-06
A5: PRC-0003 | B5: PRJ-2026-00125 | C5: MAT-001546 | D5: SUP-000087 | E5: USR-06 | F5: USD | G5: 500000 | H5: 2 | I5: 2500 | J5: 1 | K5: 45 | L5: 45 days | M5: CPT | N5: 30 | O5: 0 | P5: 0 | Q5: 0 | R5: 0 | S5: =ROUND(($I5+$N5+$O5+$P5+$Q5+$R5)*$G5,0) | T5: 46280 | U5: Signed Quote | V5: 46357 | W5: =IF(ISBLANK($V5),"",IF($V5<TODAY(),1,0)) | X5: Approved | Y5: 46293 | Z5: USR-06
A6: PRC-0004 | B6: PRJ-2026-00125 | C6: MAT-001548 | D6: SUP-000086 | E6: USR-06 | F6: IRR | G6: 1 | H6: 2 | I6: 12000000 | J6: 1 | K6: 10 | L6: cash | M6: EXW | N6: 0 | O6: 0 | P6: 0 | Q6: 0 | R6: 0 | S6: =ROUND(($I6+$N6+$O6+$P6+$Q6+$R6)*$G6,0) | T6: 46280 | U6: Price list | V6: 46376 | W6: =IF(ISBLANK($V6),"",IF($V6<TODAY(),1,0)) | X6: Approved | Y6: 46293 | Z6: USR-06

Sheet Purchase_Prices
A1: Purchase_Prices | B1: قیمت خرید با Revision؛ Expired_Flag=1 یعنی قیمت منقضی و از Costing کنار گذاشته می‌شود. Landed=(اجزا)×Fx.
A2: System_ID | B2: Material_ID | C2: Supplier_ID | D2: Revision | E2: Price_Date | F2: Price_Source | G2: Currency | H2: Fx_Rate | I2: Unit_Price | J2: Freight_Per_Unit | K2: Insurance_Per_Unit | L2: Customs_Per_Unit | M2: Handling_Per_Unit | N2: Other_Per_Unit | O2: Landed_Cost_Unit | P2: Valid_From | Q2: Valid_To | R2: Expired_Flag | S2: Status_ID | T2: Approved_By | U2: Create_Date | V2: Created_By
A3: PPR-000554 | B3: MAT-001542 | C3: SUP-000090 | D3: R01 | E3: 46280 | F3: Signed Quote | G3: USD | H3: 500000 | I3: 1.15 | J3: 0.05 | K3: 0 | L3: 0 | M3: 0 | N3: 0 | O3: =ROUND(($I3+$J3+$K3+$L3+$M3+$N3)*$H3,0) | P3: 46280 | Q3: 46356 | R3: =IF(ISBLANK($Q3),1,IF($Q3<TODAY(),1,0)) | S3: Approved | T3: USR-06 | U3: 46280 | V3: USR-06
A4: PPR-000555 | B4: MAT-001543 | C4: SUP-000090 | D4: R01 | E4: 46280 | F4: Signed Quote | G4: USD | H4: 500000 | I4: 3.2 | J4: 0.05 | K4: 0 | L4: 0 | M4: 0 | N4: 0 | O4: =ROUND(($I4+$J4+$K4+$L4+$M4+$N4)*$H4,0) | P4: 46280 | Q4: 46356 | R4: =IF(ISBLANK($Q4),1,IF($Q4<TODAY(),1,0)) | S4: Approved | T4: USR-06 | U4: 46280 | V4: USR-06
A5: PPR-000556 | B5: MAT-001544 | C5: SUP-000089 | D5: R01 | E5: 46280 | F5: Email Quote | G5: IRR | H5: 1 | I5: 95000000 | J5: 1200000 | K5: 0 | L5: 0 | M5: 0 | N5: 0 | O5: =ROUND(($I5+$J5+$K5+$L5+$M5+$N5)*$H5,0) | P5: 46280 | Q5: 46346 | R5: =IF(ISBLANK($Q5),1,IF($Q5<TODAY(),1,0)) | S5: Approved | T5: USR-06 | U5: 46280 | V5: USR-06
A6: PPR-000557 | B6: MAT-001545 | C6: SUP-000088 | D6: R01 | E6: 46280 | F6: Email Quote | G6: IRR | H6: 1 | I6: 185000000 | J6: 2000000 | K6: 0 | L6: 0 | M6: 0 | N6: 0 | O6: =ROUND(($I6+$J6+$K6+$L6+$M6+$N6)*$H6,0) | P6: 46280 | Q6: 46356 | R6: =IF(ISBLANK($Q6),1,IF($Q6<TODAY(),1,0)) | S6: Approved | T6: USR-06 | U6: 46280 | V6: USR-06
A7: PPR-000558 | B7: MAT-001546 | C7: SUP-000087 | D7: R01 | E7: 46280 | F7: Signed Quote | G7: USD | H7: 500000 | I7: 2500 | J7: 30 | K7: 0 | L7: 0 | M7: 0 | N7: 0 | O7: =ROUND(($I7+$J7+$K7+$L7+$M7+$N7)*$H7,0) | P7: 46280 | Q7: 46357 | R7: =IF(ISBLANK($Q7),1,IF($Q7<TODAY(),1,0)) | S7: Approved | T7: USR-06 | U7: 46280 | V7: USR-06
A8: PPR-000559 | B8: MAT-001547 | C8: SUP-000090 | D8: R01 | E8: 46280 | F8: Signed Quote | G8: IRR | H8: 1 | I8: 2200000 | J8: 0 | K8: 0 | L8: 0 | M8: 0 | N8: 0 | O8: =ROUND(($I8+$J8+$K8+$L8+$M8+$N8)*$H8,0) | P8: 46280 | Q8: 46275 | R8: =IF(ISBLANK($Q8),1,IF($Q8<TODAY(),1,0)) | S8: Expired | T8: USR-06 | U8: 46280 | V8: USR-06
A9: PPR-000560 | B9: MAT-001547 | C9: SUP-000090 | D9: R02 | E9: 46295 | F9: Revised Quote | G9: IRR | H9: 1 | I9: 2450000 | J9: 0 | K9: 0 | L9: 0 | M9: 0 | N9: 0 | O9: =ROUND(($I9+$J9+$K9+$L9+$M9+$N9)*$H9,0) | P9: 46296 | Q9: 46357 | R9: =IF(ISBLANK($Q9),1,IF($Q9<TODAY(),1,0)) | S9: Approved | T9: USR-06 | U9: 46295 | V9: USR-06
A10: PPR-000561 | B10: MAT-001548 | C10: SUP-000086 | D10: R01 | E10: 46280 | F10: Price list | G10: IRR | H10: 1 | I10: 12000000 | J10: 0 | K10: 0 | L10: 0 | M10: 0 | N10: 0 | O10: =ROUND(($I10+$J10+$K10+$L10+$M10+$N10)*$H10,0) | P10: 46280 | Q10: 46376 | R10: =IF(ISBLANK($Q10),1,IF($Q10<TODAY(),1,0)) | S10: Approved | T10: USR-06 | U10: 46280 | V10: USR-06

Sheet Planning
A1: Planning | B1: Required = Bom_Qty × (1+Scrap%) × Order_Qty. Order_Qty زنده از Order_Lines خوانده می‌شود (تغییر مقدار سفارش خودکار منتشر می‌شود).
A2: System_ID | B2: Project_ID | C2: BOM_Revision_ID | D2: BOM_Line_ID | E2: Product_ID | F2: Material_ID | G2: Make_Buy | H2: Order_Qty | I2: Bom_Qty_Per | J2: Scrap_% | K2: Required_Qty | L2: Stock_On_Hand | M2: Reserved | N2: Deficit | O2: Buy_Qty | P2: Lead_Time_Days | Q2: Supply_Date | R2: Status_ID | S2: Create_Date | T2: Created_By
A3: PLN-000001 | B3: PRJ-2026-00125 | C3: BOM-000215-R05 | D3: BLI-000988 | E3: PRD-000125 | F3: MAT-001542 | G3: Make | H3: =SUMIFS(Order_Lines!$E$3:$E$20,Order_Lines!$D$3:$D$20,$E3,Order_Lines!$B$3:$B$20,XLOOKUP($B3,Projects!$A$3:$A$10,Projects!$C$3:$C$10,0)) | I3: 180 | J3: 0.05 | K3: =ROUND($H3*$I3*(1+$J3),2) | L3: =IFERROR(XLOOKUP($F3,Inventory!$B$3:$B$20,Inventory!$C$3:$C$20,0),0) | M3: =IFERROR(XLOOKUP($F3,Inventory!$B$3:$B$20,Inventory!$D$3:$D$20,0),0) | N3: =MAX($K3-($L3-$M3),0) | O3: =$N3 | P3: 15 | Q3: =TODAY()+$P3 | R3: Approved | S3: 46296 | T3: USR-05
A4: PLN-000002 | B4: PRJ-2026-00125 | C4: BOM-000215-R05 | D4: BLI-000989 | E4: PRD-000125 | F4: MAT-001543 | G4: Make | H4: =SUMIFS(Order_Lines!$E$3:$E$20,Order_Lines!$D$3:$D$20,$E4,Order_Lines!$B$3:$B$20,XLOOKUP($B4,Projects!$A$3:$A$10,Projects!$C$3:$C$10,0)) | I4: 55 | J4: 0.05 | K4: =ROUND($H4*$I4*(1+$J4),2) | L4: =IFERROR(XLOOKUP($F4,Inventory!$B$3:$B$20,Inventory!$C$3:$C$20,0),0) | M4: =IFERROR(XLOOKUP($F4,Inventory!$B$3:$B$20,Inventory!$D$3:$D$20,0),0) | N4: =MAX($K4-($L4-$M4),0) | O4: =$N4 | P4: 15 | Q4: =TODAY()+$P4 | R4: Approved | S4: 46296 | T4: USR-05
A5: PLN-000003 | B5: PRJ-2026-00125 | C5: BOM-000215-R05 | D5: BLI-000990 | E5: PRD-000125 | F5: MAT-001547 | G5: Make | H5: =SUMIFS(Order_Lines!$E$3:$E$20,Order_Lines!$D$3:$D$20,$E5,Order_Lines!$B$3:$B$20,XLOOKUP($B5,Projects!$A$3:$A$10,Projects!$C$3:$C$10,0)) | I5: 22 | J5: 0.05 | K5: =ROUND($H5*$I5*(1+$J5),2) | L5: =IFERROR(XLOOKUP($F5,Inventory!$B$3:$B$20,Inventory!$C$3:$C$20,0),0) | M5: =IFERROR(XLOOKUP($F5,Inventory!$B$3:$B$20,Inventory!$D$3:$D$20,0),0) | N5: =MAX($K5-($L5-$M5),0) | O5: =$N5 | P5: 15 | Q5: =TODAY()+$P5 | R5: Approved | S5: 46296 | T5: USR-05
A6: PLN-000004 | B6: PRJ-2026-00125 | C6: BOM-000215-R05 | D6: BLI-000991 | E6: PRD-000125 | F6: MAT-001544 | G6: Buy | H6: =SUMIFS(Order_Lines!$E$3:$E$20,Order_Lines!$D$3:$D$20,$E6,Order_Lines!$B$3:$B$20,XLOOKUP($B6,Projects!$A$3:$A$10,Projects!$C$3:$C$10,0)) | I6: 1 | J6: 0 | K6: =ROUND($H6*$I6*(1+$J6),2) | L6: =IFERROR(XLOOKUP($F6,Inventory!$B$3:$B$20,Inventory!$C$3:$C$20,0),0) | M6: =IFERROR(XLOOKUP($F6,Inventory!$B$3:$B$20,Inventory!$D$3:$D$20,0),0) | N6: =MAX($K6-($L6-$M6),0) | O6: =$N6 | P6: 15 | Q6: =TODAY()+$P6 | R6: Approved | S6: 46296 | T6: USR-05
A7: PLN-000005 | B7: PRJ-2026-00125 | C7: BOM-000215-R05 | D7: BLI-000992 | E7: PRD-000125 | F7: MAT-001545 | G7: Buy | H7: =SUMIFS(Order_Lines!$E$3:$E$20,Order_Lines!$D$3:$D$20,$E7,Order_Lines!$B$3:$B$20,XLOOKUP($B7,Projects!$A$3:$A$10,Projects!$C$3:$C$10,0)) | I7: 1 | J7: 0 | K7: =ROUND($H7*$I7*(1+$J7),2) | L7: =IFERROR(XLOOKUP($F7,Inventory!$B$3:$B$20,Inventory!$C$3:$C$20,0),0) | M7: =IFERROR(XLOOKUP($F7,Inventory!$B$3:$B$20,Inventory!$D$3:$D$20,0),0) | N7: =MAX($K7-($L7-$M7),0) | O7: =$N7 | P7: 15 | Q7: =TODAY()+$P7 | R7: Approved | S7: 46296 | T7: USR-05
A8: PLN-000006 | B8: PRJ-2026-00125 | C8: BOM-000215-R05 | D8: BLI-000993 | E8: PRD-000125 | F8: MAT-001546 | G8: Buy | H8: =SUMIFS(Order_Lines!$E$3:$E$20,Order_Lines!$D$3:$D$20,$E8,Order_Lines!$B$3:$B$20,XLOOKUP($B8,Projects!$A$3:$A$10,Projects!$C$3:$C$10,0)) | I8: 1 | J8: 0 | K8: =ROUND($H8*$I8*(1+$J8),2) | L8: =IFERROR(XLOOKUP($F8,Inventory!$B$3:$B$20,Inventory!$C$3:$C$20,0),0) | M8: =IFERROR(XLOOKUP($F8,Inventory!$B$3:$B$20,Inventory!$D$3:$D$20,0),0) | N8: =MAX($K8-($L8-$M8),0) | O8: =$N8 | P8: 15 | Q8: =TODAY()+$P8 | R8: Approved | S8: 46296 | T8: USR-05
A9: PLN-000007 | B9: PRJ-2026-00125 | C9: BOM-000215-R05 | D9: BLI-000994 | E9: PRD-000125 | F9: MAT-001548 | G9: Buy | H9: =SUMIFS(Order_Lines!$E$3:$E$20,Order_Lines!$D$3:$D$20,$E9,Order_Lines!$B$3:$B$20,XLOOKUP($B9,Projects!$A$3:$A$10,Projects!$C$3:$C$10,0)) | I9: 1 | J9: 0 | K9: =ROUND($H9*$I9*(1+$J9),2) | L9: =IFERROR(XLOOKUP($F9,Inventory!$B$3:$B$20,Inventory!$C$3:$C$20,0),0) | M9: =IFERROR(XLOOKUP($F9,Inventory!$B$3:$B$20,Inventory!$D$3:$D$20,0),0) | N9: =MAX($K9-($L9-$M9),0) | O9: =$N9 | P9: 15 | Q9: =TODAY()+$P9 | R9: Approved | S9: 46296 | T9: USR-05
A10: PLN-000008 | B10: PRJ-2026-00125 | C10: BOM-000216-R02 | D10: BLI-000901 | E10: PRD-000126 | F10: MAT-001542 | G10: Make | H10: =SUMIFS(Order_Lines!$E$3:$E$20,Order_Lines!$D$3:$D$20,$E10,Order_Lines!$B$3:$B$20,XLOOKUP($B10,Projects!$A$3:$A$10,Projects!$C$3:$C$10,0)) | I10: 95 | J10: 0.05 | K10: =ROUND($H10*$I10*(1+$J10),2) | L10: =IFERROR(XLOOKUP($F10,Inventory!$B$3:$B$20,Inventory!$C$3:$C$20,0),0) | M10: =IFERROR(XLOOKUP($F10,Inventory!$B$3:$B$20,Inventory!$D$3:$D$20,0),0) | N10: =MAX($K10-($L10-$M10),0) | O10: =$N10 | P10: 15 | Q10: =TODAY()+$P10 | R10: Approved | S10: 46296 | T10: USR-05
A11: PLN-000009 | B11: PRJ-2026-00125 | C11: BOM-000216-R02 | D11: BLI-000902 | E11: PRD-000126 | F11: MAT-001547 | G11: Make | H11: =SUMIFS(Order_Lines!$E$3:$E$20,Order_Lines!$D$3:$D$20,$E11,Order_Lines!$B$3:$B$20,XLOOKUP($B11,Projects!$A$3:$A$10,Projects!$C$3:$C$10,0)) | I11: 14 | J11: 0.05 | K11: =ROUND($H11*$I11*(1+$J11),2) | L11: =IFERROR(XLOOKUP($F11,Inventory!$B$3:$B$20,Inventory!$C$3:$C$20,0),0) | M11: =IFERROR(XLOOKUP($F11,Inventory!$B$3:$B$20,Inventory!$D$3:$D$20,0),0) | N11: =MAX($K11-($L11-$M11),0) | O11: =$N11 | P11: 15 | Q11: =TODAY()+$P11 | R11: Approved | S11: 46296 | T11: USR-05
A12: PLN-000010 | B12: PRJ-2026-00125 | C12: BOM-000216-R02 | D12: BLI-000903 | E12: PRD-000126 | F12: MAT-001544 | G12: Buy | H12: =SUMIFS(Order_Lines!$E$3:$E$20,Order_Lines!$D$3:$D$20,$E12,Order_Lines!$B$3:$B$20,XLOOKUP($B12,Projects!$A$3:$A$10,Projects!$C$3:$C$10,0)) | I12: 1 | J12: 0 | K12: =ROUND($H12*$I12*(1+$J12),2) | L12: =IFERROR(XLOOKUP($F12,Inventory!$B$3:$B$20,Inventory!$C$3:$C$20,0),0) | M12: =IFERROR(XLOOKUP($F12,Inventory!$B$3:$B$20,Inventory!$D$3:$D$20,0),0) | N12: =MAX($K12-($L12-$M12),0) | O12: =$N12 | P12: 15 | Q12: =TODAY()+$P12 | R12: Approved | S12: 46296 | T12: USR-05
A13: PLN-000011 | B13: PRJ-2026-00125 | C13: BOM-000216-R02 | D13: BLI-000904 | E13: PRD-000126 | F13: MAT-001545 | G13: Buy | H13: =SUMIFS(Order_Lines!$E$3:$E$20,Order_Lines!$D$3:$D$20,$E13,Order_Lines!$B$3:$B$20,XLOOKUP($B13,Projects!$A$3:$A$10,Projects!$C$3:$C$10,0)) | I13: 1 | J13: 0 | K13: =ROUND($H13*$I13*(1+$J13),2) | L13: =IFERROR(XLOOKUP($F13,Inventory!$B$3:$B$20,Inventory!$C$3:$C$20,0),0) | M13: =IFERROR(XLOOKUP($F13,Inventory!$B$3:$B$20,Inventory!$D$3:$D$20,0),0) | N13: =MAX($K13-($L13-$M13),0) | O13: =$N13 | P13: 15 | Q13: =TODAY()+$P13 | R13: Approved | S13: 46296 | T13: USR-05
A14: PLN-000012 | B14: PRJ-2026-00125 | C14: BOM-000216-R02 | D14: BLI-000905 | E14: PRD-000126 | F14: MAT-001546 | G14: Buy | H14: =SUMIFS(Order_Lines!$E$3:$E$20,Order_Lines!$D$3:$D$20,$E14,Order_Lines!$B$3:$B$20,XLOOKUP($B14,Projects!$A$3:$A$10,Projects!$C$3:$C$10,0)) | I14: 1 | J14: 0 | K14: =ROUND($H14*$I14*(1+$J14),2) | L14: =IFERROR(XLOOKUP($F14,Inventory!$B$3:$B$20,Inventory!$C$3:$C$20,0),0) | M14: =IFERROR(XLOOKUP($F14,Inventory!$B$3:$B$20,Inventory!$D$3:$D$20,0),0) | N14: =MAX($K14-($L14-$M14),0) | O14: =$N14 | P14: 15 | Q14: =TODAY()+$P14 | R14: Approved | S14: 46296 | T14: USR-05
A15: PLN-000013 | B15: PRJ-2026-00125 | C15: BOM-000216-R02 | D15: BLI-000906 | E15: PRD-000126 | F15: MAT-001548 | G15: Buy | H15: =SUMIFS(Order_Lines!$E$3:$E$20,Order_Lines!$D$3:$D$20,$E15,Order_Lines!$B$3:$B$20,XLOOKUP($B15,Projects!$A$3:$A$10,Projects!$C$3:$C$10,0)) | I15: 1 | J15: 0 | K15: =ROUND($H15*$I15*(1+$J15),2) | L15: =IFERROR(XLOOKUP($F15,Inventory!$B$3:$B$20,Inventory!$C$3:$C$20,0),0) | M15: =IFERROR(XLOOKUP($F15,Inventory!$B$3:$B$20,Inventory!$D$3:$D$20,0),0) | N15: =MAX($K15-($L15-$M15),0) | O15: =$N15 | P15: 15 | Q15: =TODAY()+$P15 | R15: Approved | S15: 46296 | T15: USR-05

Sheet Schedule
A1: Schedule | B1: زمان‌بندی فعالیت‌ها؛ Duration = End - Start + 1 و Delay برای فعالیت‌های معوق محاسبه می‌شود.
A2: System_ID | B2: Project_ID | C2: Activity | D2: Start_Date | E2: End_Date | F2: Duration | G2: Responsible | H2: Dependency | I2: Status_ID | J2: Delay_Days | K2: Delay_Reason | L2: Create_Date | M2: Created_By
A3: SCH-000256 | B3: PRJ-2026-00125 | C3: Engineering | D3: 46286 | E3: 46295 | F3: =IF(ISBLANK($E3),0,$E3-$D3+1) | G3: USR-04 | I3: Done | J3: =IF(ISBLANK($E3),0,IF($I3="Done",0,IF(AND($I3<>"Done",TODAY()>$D3),TODAY()-$D3,0))) | L3: 46293 | M3: USR-05
A4: SCH-000257 | B4: PRJ-2026-00125 | C4: BOM Release | D4: 46293 | E4: 46295 | F4: =IF(ISBLANK($E4),0,$E4-$D4+1) | G4: USR-04 | H4: Engineering | I4: Done | J4: =IF(ISBLANK($E4),0,IF($I4="Done",0,IF(AND($I4<>"Done",TODAY()>$D4),TODAY()-$D4,0))) | L4: 46293 | M4: USR-05
A5: SCH-000258 | B5: PRJ-2026-00125 | C5: Procurement | D5: 46296 | E5: 46315 | F5: =IF(ISBLANK($E5),0,$E5-$D5+1) | G5: USR-06 | H5: BOM Release | I5: In Progress | J5: =IF(ISBLANK($E5),0,IF($I5="Done",0,IF(AND($I5<>"Done",TODAY()>$D5),TODAY()-$D5,0))) | L5: 46293 | M5: USR-05
A6: SCH-000259 | B6: PRJ-2026-00125 | C6: Supplier Confirmation | D6: 46300 | E6: 46315 | F6: =IF(ISBLANK($E6),0,$E6-$D6+1) | G6: USR-06 | H6: Procurement | I6: In Progress | J6: =IF(ISBLANK($E6),0,IF($I6="Done",0,IF(AND($I6<>"Done",TODAY()>$D6),TODAY()-$D6,0))) | L6: 46293 | M6: USR-05
A7: SCH-000260 | B7: PRJ-2026-00125 | C7: Material Arrival | D7: 46327 | E7: 46341 | F7: =IF(ISBLANK($E7),0,$E7-$D7+1) | G7: USR-06 | H7: Supplier Confirmation | I7: Not Started | J7: =IF(ISBLANK($E7),0,IF($I7="Done",0,IF(AND($I7<>"Done",TODAY()>$D7),TODAY()-$D7,0))) | L7: 46293 | M7: USR-05
A8: SCH-000261 | B8: PRJ-2026-00125 | C8: Production Planning | D8: 46336 | E8: 46346 | F8: =IF(ISBLANK($E8),0,$E8-$D8+1) | G8: USR-05 | H8: Material Arrival | I8: Not Started | J8: =IF(ISBLANK($E8),0,IF($I8="Done",0,IF(AND($I8<>"Done",TODAY()>$D8),TODAY()-$D8,0))) | L8: 46293 | M8: USR-05
A9: SCH-000262 | B9: PRJ-2026-00125 | C9: Production | D9: 46346 | E9: 46361 | F9: =IF(ISBLANK($E9),0,$E9-$D9+1) | G9: USR-05 | H9: Production Planning | I9: Not Started | J9: =IF(ISBLANK($E9),0,IF($I9="Done",0,IF(AND($I9<>"Done",TODAY()>$D9),TODAY()-$D9,0))) | L9: 46293 | M9: USR-05
A10: SCH-000263 | B10: PRJ-2026-00125 | C10: QC | D10: 46362 | E10: 46366 | F10: =IF(ISBLANK($E10),0,$E10-$D10+1) | G10: USR-04 | H10: Production | I10: Not Started | J10: =IF(ISBLANK($E10),0,IF($I10="Done",0,IF(AND($I10<>"Done",TODAY()>$D10),TODAY()-$D10,0))) | L10: 46293 | M10: USR-05
A11: SCH-000264 | B11: PRJ-2026-00125 | C11: Packing | D11: 46367 | E11: 46370 | F11: =IF(ISBLANK($E11),0,$E11-$D11+1) | G11: USR-05 | H11: QC | I11: Not Started | J11: =IF(ISBLANK($E11),0,IF($I11="Done",0,IF(AND($I11<>"Done",TODAY()>$D11),TODAY()-$D11,0))) | L11: 46293 | M11: USR-05
A12: SCH-000265 | B12: PRJ-2026-00125 | C12: Delivery | D12: 46371 | E12: 46374 | F12: =IF(ISBLANK($E12),0,$E12-$D12+1) | G12: USR-02 | H12: Packing | I12: Not Started | J12: =IF(ISBLANK($E12),0,IF($I12="Done",0,IF(AND($I12<>"Done",TODAY()>$D12),TODAY()-$D12,0))) | L12: 46293 | M12: USR-05
A13: SCH-000266 | B13: PRJ-2026-00126 | C13: Engineering | D13: 46266 | E13: 46280 | F13: =IF(ISBLANK($E13),0,$E13-$D13+1) | G13: USR-04 | I13: In Progress | J13: =IF(ISBLANK($E13),0,IF($I13="Done",0,IF(AND($I13<>"Done",TODAY()>$D13),TODAY()-$D13,0))) | K13: در انتظار تأیید نقشه | L13: 46266 | M13: USR-04

Sheet Cost_Lines
A1: Cost_Lines | B1: ریز اجزای قیمت تمام‌شده (Drill-down). Direct Material = اقلام Make، Purchased Parts = اقلام Buy (غیر بسته‌بندی)، Packaging = بسته‌بندی.
A2: System_ID | B2: Costing_ID | C2: Project_ID | D2: Category | E2: Material_ID | F2: Supplier_ID | G2: Qty | H2: UoM | I2: Unit_Cost | J2: Amount | K2: Source_Ref | L2: Memo | M2: Create_Date | N2: Created_By
A3: CLI-000001 | B3: CST-000321 | C3: PRJ-2026-00125 | D3: Direct Material | E3: MAT-001542 | G3: 378 | H3: kg | I3: =Purchase_Prices!$O$3 | J3: =ROUND($G3*$I3,0) | K3: PPR-MAT-001542 | L3: از قیمت خرید فعال (Landed) | M3: 46300 | N3: USR-07
A4: CLI-000002 | B4: CST-000321 | C4: PRJ-2026-00125 | D4: Direct Material | E4: MAT-001543 | G4: 115.5 | H4: kg | I4: =Purchase_Prices!$O$4 | J4: =ROUND($G4*$I4,0) | K4: PPR-MAT-001543 | L4: از قیمت خرید فعال (Landed) | M4: 46300 | N4: USR-07
A5: CLI-000003 | B5: CST-000321 | C5: PRJ-2026-00125 | D5: Direct Material | E5: MAT-001547 | G5: 46.2 | H5: kg | I5: =Purchase_Prices!$O$9 | J5: =ROUND($G5*$I5,0) | K5: PPR-MAT-001547 | L5: از قیمت خرید فعال (Landed) | M5: 46300 | N5: USR-07
A6: CLI-000004 | B6: CST-000321 | C6: PRJ-2026-00125 | D6: Purchased Parts | E6: MAT-001544 | F6: SUP-000089 | G6: 2 | H6: pcs | I6: =Purchase_Prices!$O$5 | J6: =ROUND($G6*$I6,0) | K6: PPR-MAT-001544 | L6: از قیمت خرید فعال (Landed) | M6: 46300 | N6: USR-07
A7: CLI-000005 | B7: CST-000321 | C7: PRJ-2026-00125 | D7: Purchased Parts | E7: MAT-001545 | F7: SUP-000088 | G7: 2 | H7: pcs | I7: =Purchase_Prices!$O$6 | J7: =ROUND($G7*$I7,0) | K7: PPR-MAT-001545 | L7: از قیمت خرید فعال (Landed) | M7: 46300 | N7: USR-07
A8: CLI-000006 | B8: CST-000321 | C8: PRJ-2026-00125 | D8: Purchased Parts | E8: MAT-001546 | F8: SUP-000087 | G8: 2 | H8: pcs | I8: =Purchase_Prices!$O$7 | J8: =ROUND($G8*$I8,0) | K8: PPR-MAT-001546 | L8: از قیمت خرید فعال (Landed) | M8: 46300 | N8: USR-07
A9: CLI-000007 | B9: CST-000321 | C9: PRJ-2026-00125 | D9: Direct Material | E9: MAT-001542 | G9: 99.75 | H9: kg | I9: =Purchase_Prices!$O$3 | J9: =ROUND($G9*$I9,0) | K9: PPR-MAT-001542 | L9: از قیمت خرید فعال (Landed) | M9: 46300 | N9: USR-07
A10: CLI-000008 | B10: CST-000321 | C10: PRJ-2026-00125 | D10: Direct Material | E10: MAT-001547 | G10: 14.7 | H10: kg | I10: =Purchase_Prices!$O$9 | J10: =ROUND($G10*$I10,0) | K10: PPR-MAT-001547 | L10: از قیمت خرید فعال (Landed) | M10: 46300 | N10: USR-07
A11: CLI-000009 | B11: CST-000321 | C11: PRJ-2026-00125 | D11: Purchased Parts | E11: MAT-001544 | F11: SUP-000089 | G11: 1 | H11: pcs | I11: =Purchase_Prices!$O$5 | J11: =ROUND($G11*$I11,0) | K11: PPR-MAT-001544 | L11: از قیمت خرید فعال (Landed) | M11: 46300 | N11: USR-07
A12: CLI-000010 | B12: CST-000321 | C12: PRJ-2026-00125 | D12: Purchased Parts | E12: MAT-001545 | F12: SUP-000088 | G12: 1 | H12: pcs | I12: =Purchase_Prices!$O$6 | J12: =ROUND($G12*$I12,0) | K12: PPR-MAT-001545 | L12: از قیمت خرید فعال (Landed) | M12: 46300 | N12: USR-07
A13: CLI-000011 | B13: CST-000321 | C13: PRJ-2026-00125 | D13: Purchased Parts | E13: MAT-001546 | F13: SUP-000087 | G13: 1 | H13: pcs | I13: =Purchase_Prices!$O$7 | J13: =ROUND($G13*$I13,0) | K13: PPR-MAT-001546 | L13: از قیمت خرید فعال (Landed) | M13: 46300 | N13: USR-07
A14: CLI-000012 | B14: CST-000321 | C14: PRJ-2026-00125 | D14: Direct Labor | G14: 400 | H14: hr | I14: =Settings!$B$3 | J14: =ROUND($G14*$I14,0) | K14: Settings | L14: ASSUMPTION: 400 ساعت نفر | M14: 46300 | N14: USR-07
A15: CLI-000013 | B15: CST-000321 | C15: PRJ-2026-00125 | D15: Manufacturing Overhead | G15: 1 | H15: lot | I15: =Settings!$B$4 | J15: =ROUND($J$14*$I15,0) | K15: Settings | L15: ASSUMPTION: نرخ سربار × دستمزد مستقیم (جذب بر پایه کار) | M15: 46300 | N15: USR-07
A16: CLI-000014 | B16: CST-000321 | C16: PRJ-2026-00125 | D16: Scrap | G16: 1 | H16: lot | I16: =Settings!$B$5 | J16: =ROUND(($J$3+$J$4+$J$5+$J$9+$J$10+$J$6+$J$7+$J$8+$J$11+$J$12+$J$13)*$I16,0) | K16: Settings | L16: ASSUMPTION: ضریب ضایعات فرآیند | M16: 46300 | N16: USR-07
A17: CLI-000015 | B17: CST-000321 | C17: PRJ-2026-00125 | D17: Packaging | E17: MAT-001548 | G17: 2 | H17: pcs | I17: =Settings!$B$11 | J17: =ROUND($G17*$I17,0) | K17: Settings | L17: بسته‌بندی از Settings/تأمین‌کننده | M17: 46300 | N17: USR-07
A18: CLI-000016 | B18: CST-000321 | C18: PRJ-2026-00125 | D18: Logistics | G18: 1 | H18: lot | I18: =Settings!$B$10 | J18: =ROUND($G18*$I18,0) | K18: Settings | L18: ASSUMPTION: لجستیک پایه پروژه | M18: 46300 | N18: USR-07
A19: CLI-000017 | B19: CST-000321 | C19: PRJ-2026-00125 | D19: Tooling | G19: 1 | H19: lot | I19: =Settings!$B$9 | J19: =ROUND($G19*$I19,0) | K19: Settings | L19: ASSUMPTION: استهلاک قالب (تسهیم خطی) | M19: 46300 | N19: USR-07
A20: CLI-000018 | B20: CST-000321 | C20: PRJ-2026-00125 | D20: SG&A | G20: 1 | H20: lot | I20: =Settings!$B$7 | J20: =ROUND(IF(Settings!$B$8=1,($J$3+$J$4+$J$5+$J$9+$J$10+$J$6+$J$7+$J$8+$J$11+$J$12+$J$13+$J$17+$J$14+$J$15)*$I20,0),0) | K20: Settings | L20: ASSUMPTION: نرخ اداری/فروش (در صورت سیاست سازمان) | M20: 46300 | N20: USR-07

Sheet Costing
A1: Costing | B1: قیمت تمام‌شده = SUMIFS روی Cost_Lines به تفکیک Category. Cost_Per_Unit = Total_Cost / Qty_Basis.
A2: System_ID | B2: Project_ID | C2: Revision | D2: Status_ID | E2: Cost_Basis | F2: Qty_Basis | G2: Direct_Material | H2: Purchased_Parts | I2: Direct_Labor | J2: Mfg_Overhead | K2: Scrap | L2: Packaging | M2: Logistics | N2: Tooling | O2: SG&A | P2: Other_Allocated | Q2: Total_Cost | R2: Cost_Per_Unit | S2: Approved_By | T2: Create_Date | U2: Created_By
A3: CST-000321 | B3: PRJ-2026-00125 | C3: R01 | D3: Approved | E3: 46300 | F3: 2 | G3: =SUMIFS(Cost_Lines!$J$3:$J$21,Cost_Lines!$B$3:$B$21,$A3,Cost_Lines!$D$3:$D$21,"Direct Material") | H3: =SUMIFS(Cost_Lines!$J$3:$J$21,Cost_Lines!$B$3:$B$21,$A3,Cost_Lines!$D$3:$D$21,"Purchased Parts") | I3: =SUMIFS(Cost_Lines!$J$3:$J$21,Cost_Lines!$B$3:$B$21,$A3,Cost_Lines!$D$3:$D$21,"Direct Labor") | J3: =SUMIFS(Cost_Lines!$J$3:$J$21,Cost_Lines!$B$3:$B$21,$A3,Cost_Lines!$D$3:$D$21,"Manufacturing Overhead") | K3: =SUMIFS(Cost_Lines!$J$3:$J$21,Cost_Lines!$B$3:$B$21,$A3,Cost_Lines!$D$3:$D$21,"Scrap") | L3: =SUMIFS(Cost_Lines!$J$3:$J$21,Cost_Lines!$B$3:$B$21,$A3,Cost_Lines!$D$3:$D$21,"Packaging") | M3: =SUMIFS(Cost_Lines!$J$3:$J$21,Cost_Lines!$B$3:$B$21,$A3,Cost_Lines!$D$3:$D$21,"Logistics") | N3: =SUMIFS(Cost_Lines!$J$3:$J$21,Cost_Lines!$B$3:$B$21,$A3,Cost_Lines!$D$3:$D$21,"Tooling") | O3: =SUMIFS(Cost_Lines!$J$3:$J$21,Cost_Lines!$B$3:$B$21,$A3,Cost_Lines!$D$3:$D$21,"SG&A") | P3: 0 | Q3: =SUM($G3:$P3) | R3: =IF($F3=0,0,ROUND($Q3/$F3,0)) | S3: USR-07 | T3: 46300 | U3: USR-07

Sheet Budget
A1: Budget | B1: بودجه اولیه در برابر عملکرد (Actual از Costing). Variance و Budget_vs_Actual زنده محاسبه می‌شوند.
A2: System_ID | B2: Project_ID | C2: Revision | D2: Period | E2: Budget_Material | F2: Budget_Labor | G2: Budget_Overhead | H2: Budget_Procurement | I2: Budget_Logistics | J2: Budget_Tooling | K2: Budget_Other | L2: Total_Budget | M2: Actual_Material | N2: Actual_Labor | O2: Actual_Overhead | P2: Actual_Logistics | Q2: Actual_Other | R2: Actual_Total | S2: Variance_Total | T2: Budget_vs_Actual | U2: Create_Date | V2: Created_By
A3: BDG-000245 | B3: PRJ-2026-00125 | C3: R01 | D3: 2026-Q4 | E3: 4000000000 | F3: 350000000 | G3: 700000000 | H3: 200000000 | I3: 150000000 | J3: 100000000 | K3: 50000000 | L3: =SUM($E3:$K3) | M3: =Costing!$G$3+Costing!$H$3 | N3: =Costing!$I$3 | O3: =Costing!$J$3 | P3: =Costing!$L$3+Costing!$M$3 | Q3: =Costing!$N$3+Costing!$O$3 | R3: =Costing!$Q$3 | S3: =$R3-$L3 | T3: =IF($L3=0,"",ROUND(($R3/$L3)-1,4)) | U3: 46290 | V3: USR-07

Sheet Payment_Terms
A1: Payment_Terms | B1: شرایط پرداخت؛ هزینه مالی اعتبار = بخش اعتباری × نرخ سالانه × مدت/360 (در Sales_Quotation لحاظ می‌شود).
A2: System_ID | B2: Quotation_ID | C2: Advance_Payment_% | D2: Payment_On_Delivery_% | E2: Credit_Days | F2: Installment_Terms | G2: Bank_Guarantee | H2: Currency | I2: Payment_Risk_Level | J2: Fin_Cost_Rate_Annual | K2: Fin_Cost_Amount | L2: Is_Active_FLAG | M2: Create_Date | N2: Created_By
A3: PT-0001 | B3: QUO-001 | C3: 0.3 | D3: 0.1 | E3: 60 | G3: SBLC 10% | H3: IRR | I3: Medium | J3: =Settings!$B$6 | K3: =IF(Sales_Quotation!$K$4=0,0,Sales_Quotation!$K$4) | L3: 1 | M3: 46301 | N3: USR-01

Sheet Sales_Quotation
A1: Sales_Quotation | B1: سناریوهای A/B/C. Proposed = Cost + Margin + Commercial + Risk + Financial (هزینه مالی اعتبار). هیچ سناریو بدون Basis_Memo معتبر نیست.
A2: System_ID | B2: Project_ID | C2: Quotation_Code | D2: Scenario | E2: Costing_ID | F2: Total_Cost | G2: Desired_Margin_% | H2: Margin_Amount | I2: Commercial_Adjustment | J2: Risk_Adjustment | K2: Financial_Adjustment | L2: Proposed_Selling_Price | M2: Currency | N2: Basis_Memo | O2: Status_ID | P2: Create_Date | Q2: Created_By
A3: QUO-2026-00125 | B3: PRJ-2026-00125 | C3: QUO-001 | D3: Scenario A | E3: CST-000321 | F3: =IF($D3<>"",XLOOKUP($E3,Costing!$A$3:$A$10,Costing!$Q$3:$Q$10,0),0) | G3: 0.12 | H3: =ROUND($F3*$G3,0) | I3: 20000000 | J3: 0 | K3: =ROUND((1-Payment_Terms!$C$3-Payment_Terms!$D$3)*$F3*Settings!$B$6*(Payment_Terms!$E$3/360),0) | L3: =ROUND($F3+$H3+$I3+$J3+$K3,0) | M3: IRR | N3: Margin 12% روی کل هزینه به علاوه پوشش هزینه بازرگانی؛ بدون تعدیل ریسک | O3: Submitted | P3: 46301 | Q3: USR-01
A4: QUO-2026-00125 | B4: PRJ-2026-00125 | C4: QUO-001 | D4: Scenario B | E4: CST-000321 | F4: =IF($D4<>"",XLOOKUP($E4,Costing!$A$3:$A$10,Costing!$Q$3:$Q$10,0),0) | G4: 0.1 | H4: =ROUND($F4*$G4,0) | I4: 10000000 | J4: 15000000 | K4: =ROUND((1-Payment_Terms!$C$3-Payment_Terms!$D$3)*$F4*Settings!$B$6*(Payment_Terms!$E$3/360),0) | L4: =ROUND($F4+$H4+$I4+$J4+$K4,0) | M4: IRR | N4: Margin 10% + پوشش ریسک ارزی/زنجیره 15M؛ گزینه باثبات‌تر | O4: Submitted | P4: 46301 | Q4: USR-01
A5: QUO-2026-00125 | B5: PRJ-2026-00125 | C5: QUO-001 | D5: Scenario C | E5: CST-000321 | F5: =IF($D5<>"",XLOOKUP($E5,Costing!$A$3:$A$10,Costing!$Q$3:$Q$10,0),0) | G5: 0.15 | H5: =ROUND($F5*$G5,0) | I5: 0 | J5: 30000000 | K5: =ROUND((1-Payment_Terms!$C$3-Payment_Terms!$D$3)*$F5*Settings!$B$6*(Payment_Terms!$E$3/360),0) | L5: =ROUND($F5+$H5+$I5+$J5+$K5,0) | M5: IRR | N5: Margin تهاجمی 15% + تعدیل ریسک بالاتر برای تأخیر تأمین | O5: Draft | P5: 46301 | Q5: USR-01

Sheet Quotation_Versions
A1: Quotation_Versions | B1: نسخه‌های پیشنهاد؛ نسخه قبلی هرگز Overwrite نمی‌شود. (نمونه: نسخه V01 از سناریو B)
A2: System_ID | B2: Quotation_ID | C2: Version_No | D2: Costing_Revision_ID | E2: Total_Cost | F2: Margin_Amount | G2: Proposed_Selling_Price | H2: Change_Summary | I2: Approved_Step | J2: Status_ID | K2: Create_Date | L2: Created_By
A3: QUO-00125-V01 | B3: QUO-001 | C3: V01 | D3: CST-000321 | E3: =Sales_Quotation!$F$4 | F3: =Sales_Quotation!$H$4 | G3: =Sales_Quotation!$L$4 | J3: Approved | K3: 46301 | L3: USR-01

Sheet Management_Approval
A1: Management_Approval | B1: تصمیم مدیریت ارشد: APPROVED / APPROVED WITH CONDITION / RETURN FOR REVISION / REJECTED.
A2: System_ID | B2: Quotation_Version_ID | C2: Project_ID | D2: Decision | E2: Decision_Maker | F2: Decision_Date | G2: Comment | H2: Version_Ref | I2: Status_ID | J2: Create_Date | K2: Created_By
A3: APR-000547 | B3: QUO-00125-V01 | C3: PRJ-2026-00125 | D3: APPROVED WITH CONDITION | E3: USR-08 | F3: 46302 | G3: مشروط به تأمین مکانیکال سیل قبل از ۱۵ آبان و تعهد کتبی بلبرینگ | H3: QUO-00125-V01 | I3: Approved | J3: 46302 | K3: USR-08

Sheet Workflow_History
A1: Workflow_History | B1: لاگ انتقال وضعیت — پایه Audit (چه کسی / چه زمانی / از چه وضعیتی / به چه وضعیتی).
A2: Workflow_History_ID | B2: Project_ID | C2: Entity_Type | D2: Entity_ID | E2: From_Status | F2: To_Status | G2: Action_Date | H2: User_ID | I2: Comment
A3: WFH-000001 | B3: PRJ-2026-00125 | C3: Order | D3: ORD-2026-00321 | E3: Draft | F3: In Review | G3: 46285 | H3: USR-02 | I3: ثبت سفارش
A4: WFH-000002 | B4: PRJ-2026-00125 | C4: Order | D4: ORD-2026-00321 | E4: In Review | F4: Approved | G4: 46286 | H4: USR-01 | I4: کنترل اولیه تأیید شد
A5: WFH-000003 | B5: PRJ-2026-00125 | C5: Project | D5: PRJ-2026-00125 | E5: Draft | F5: Approved | G5: 46286 | H5: USR-03 | I5: تأسیس پروژه
A6: WFH-000004 | B6: PRJ-2026-00125 | C6: BOM | D6: BOM-000215-R05 | E6: Waiting Approval | F6: Approved | G6: 46295 | H6: USR-04 | I6: تأیید BOM R05
A7: WFH-000005 | B7: PRJ-2026-00125 | C7: Quotation | D7: QUO-2026-00125 | E7: Draft | F7: Submitted | G7: 46300 | H7: USR-01 | I7: ارسال به مدیریت
A8: WFH-000006 | B8: PRJ-2026-00125 | C8: Approval | D8: APR-000547 | E8: Waiting Approval | F8: Approved | G8: 46302 | H8: USR-08 | I8: تصویب مشروط

Sheet Change_Log
A1: Change_Log | B1: کنترل تغییرات — هر تغییر پس از تأیید Revision جدید می‌سازد؛ مقدار قبلی ثبت می‌ماند.
A2: Change_Log_ID | B2: Project_ID | C2: Entity_Type | D2: Entity_ID | E2: Field_Changed | F2: Old_Value | G2: New_Value | H2: Change_Reason | I2: Changed_By | J2: Change_Date | K2: Revision_After | L2: Create_Date | M2: Created_By
A3: CHG-001245 | B3: PRJ-2026-00125 | C3: BOM | D3: BOM-000216 | E3: Material | F3: MAT-001545 | G3: MAT-001545 | H3: تایید تامین‌کننده جدید مکانیکال سیل | I3: USR-04 | J3: 46293 | K3: R05 | L3: 46293 | M3: USR-04

Sheet Issues
A1: Issues | B1: ثبت ریسک/خطا با مالک و اقدام لازم.
A2: Issue_ID | B2: Project_ID | C2: Error_Code | D2: Error_Description | E2: Owner | F2: Required_Action | G2: Status | H2: Severity | I2: Raised_Date | J2: Create_Date | K2: Created_By
A3: ISS-000215 | B3: PRJ-2026-00125 | C3: IG-02 | D3: قیمت شفت (MAT-001547) در تاریخ ۱۵ اکتبر منقضی می‌شود؛ نیاز به تمدید | E3: USR-06 | F3: استعلام مجدد قبل از ۱۰ اکتبر | G3: Open | H3: Medium | I3: 46287 | J3: 46287 | K3: USR-03
A4: ISS-000216 | C4: E-001 | D4: سفارش ORD-2026-00323 ناقص است (تاریخ تحویل و شرایط پرداخت ندارد) | E4: USR-02 | F4: تکمیل اطلاعات سفارش قبل از ورود به مهندسی | G4: Open | H4: High | I4: 46287 | J4: 46287 | K4: USR-03

Sheet Error_Checks
A1: Error_Checks | B1: کنترل‌های خودکار (Error/Exception Handling). Formula_Result زنده محاسبه می‌شود.
A2: Rule_Key | B2: Error_Code | C2: Check_Description | D2: Severity | E2: Owner | F2: Formula_Result | G2: Message | H2: Required_Action | I2: Status | J2: Create_Date | K2: Created_By
A3: DK-01 | B3: E-018 | C3: Duplicate Order_ID | D3: Error | E3: Sales | F3: =IF(COUNTIF(Orders!$S$3:$S$1000,"DUP")>0,"ERROR","OK") | G3: شناسه سفارش تکراری است | H3: بررسی و اصلاح | I3: Open | J3: 46287 | K3: USR-09
A4: G1 | B4: E-001 | C4: سفارش ناقص (Ready_Flag) | D4: Block | E4: Sales | F4: =IF(COUNTIF(Orders!$R$3:$R$5,"INCOMPLETE")>0,"BLOCKED","OK") | G4: هر سفارش باید Ready_Flag=READY باشد تا وارد مهندسی شود | H4: تکمیل اطلاعات | I4: Open | J4: 46287 | K4: USR-09
A5: DK-02 | B5: E-019 | C5: Duplicate BOM_ID+Revision | D5: Error | E5: Engineering | F5: =IF(MAX(COUNTIFS(BOM_Header!$B$3:$B$5,BOM_Header!$B$3:$B$5,BOM_Header!$D$3:$D$5,BOM_Header!$D$3:$D$5))>1,"ERROR","OK") | G5: ترکیب BOM_ID+Revision تکراری است | H5: صدور Revision جدید | I5: Open | J5: 46287 | K5: USR-09
A6: G2 | B6: E-002 | C6: BOM بدون Revision فعال | D6: Block | E6: Engineering | F6: =IF(COUNTIF(BOM_Header!$I$3:$I$5,"Approved")>0,"OK","BLOCKED") | G6: بدون BOM Revision تأییدشده نمی‌توان وارد Planning شد | H6: تأیید BOM | I6: Open | J6: 46287 | K6: USR-09
A7: PX-01 | B7: E-003 | C7: قیمت خرید بدون تاریخ | D7: Error | E7: Procurement | F7: =IF(COUNTIF(Purchase_Prices!$E$3:$E$10,"")>0,"ERROR","OK") | G7: قیمتی بدون تاریخ وجود دارد | H7: ثبت Price_Date | I7: Open | J7: 46287 | K7: USR-09
A8: PX-02 | B8: E-004 | C8: قیمت بدون منبع | D8: Error | E8: Procurement | F8: =IF(COUNTIF(Purchase_Prices!$F$3:$F$10,"")>0,"ERROR","OK") | G8: قیمتی بدون منبع وجود دارد | H8: ثبت Price_Source | I8: Open | J8: 46287 | K8: USR-09
