Workbook
Name CalS: 'تقویم'!$A$8:$A$2199
Name CalJ: 'تقویم'!$B$8:$B$2199
Name Hols: 'تنظیمات'!$D$48:$D$87
Name HolsNorm: 'تنظیمات'!$C$48:$C$87
Name ParamThresh: 'تنظیمات'!$B$8
Name FX_USD: 'تنظیمات'!$B$6
Name FX_EUR: 'تنظیمات'!$B$7
Name BomCodes: 'مهندسی_BOM'!$B$8:$B$31
Name ListUnits: 'تنظیمات'!$B$90:$J$90
Name ListIntake: 'تنظیمات'!$B$91:$E$91
Name ListProj: 'تنظیمات'!$B$92:$F$92
Name ListDoc: 'تنظیمات'!$B$93:$E$93
Name ListRiskSt: 'تنظیمات'!$B$94:$D$94
Name ListRiskStr: 'تنظیمات'!$B$95:$E$95
Name ListCur: 'تنظیمات'!$B$96:$D$96
Name ListPhase: 'تنظیمات'!$B$97:$G$97
Name ListChgSt: 'تنظیمات'!$B$98:$E$98
Name ListTaskSt: 'تنظیمات'!$B$99:$F$99
Name score5: 'تنظیمات'!$B$100:$F$100

Sheet راهنما
A1: سامانه مدیریت پروژه برنا کامپوزیت ایرانیان — راهنما (v1.4 شمسی)
A2: الگوی عمومی برای هر پروژه (سفارش/ایده/طرح) با گردش واحدی: ثبت → امکان‌سنجی → مهندسی → تأمین → برنامه‌ریزی → مالی → فروش → تصویب. واحد پول: میلیون تومان.
A4: ۱) گردش کار حاکم بر فایل
A5: واحد بازار یابی/فروش (دریافت سفارش، ایده یا طرح) ← تکمیل «شناسنامه» ← مدیریت پروژه: «امکان‌سنجی» + «گانت» + تدوین الزامات با همکاری واحدها ← «مهندسی»: نقشه‌ها، Test Plan، BOM، نفرساعت ← «بازرگانی داخلی/خارجی»: قیمت‌گذاری اقلام BOM ← «برنامه‌ریزی تولید و انبار»: نیازسنجی و زمان تأمین ← «مالی»: بهای تمام‌شده و بودجه ← «فروش»: قیمت نهایی و شرایط پرداخت ← جمع‌بندی مدیر پروژه ← تصمیم مدیرعامل در «تصویب». در تمام مراحل، مدیر پروژه گانت و امکان‌سنجی را بازنگری و به‌روزرسانی می‌کند.
A6: ۲) شروع سریع
A7: ۱. برای هر پروژه یک کپی از این فایل در پوشه شبکه بسازید: \\BORNASRV\Projects\<کد پروژه>\ — ۲. «شناسنامه» را تکمیل کنید — ۳. داده‌های نمونه (مخزن FRP) را با داده واقعی جایگزین کنید؛ سلول‌های زرد ورودی و سلول‌های طوسی خودکارند — ۴. در «گانت» تاریخ‌های شمسی را با قالب 1405/07/12 وارد کنید — ۵. در «تنظیمات» کاربران و رمزها را اصلاح کنید — ۶. ماکروی دسترسی را طبق docs/INSTALL.md نصب کنید تا حالت نرم‌افزاری (ورود/خروج نقش) فعال شود.
A8: ۳) قوانین تاریخ شمسی
A9: مبنای تبدیل، برگه «تقویم» است (سریال میلادی ↔ رشته شمسی). تاریخ‌ها فقط داخل بازه تقویم معتبرند؛ در صورت «خارج از تقویم» یا «تاریخ نامعتبر»، قالب ورودی را بررسی کنید. رقم فارسی یا لاتین فرقی نمی‌کند؛ جداکننده / ، - و فاصله پذیرفته می‌شود. روزهای تعطیل رسمی در «تنظیمات» قابل ویرایش‌اند و در محاسبه روزهای کاری اعمال می‌شوند (جمعه تعطیل).
A10: ۴) رنگ‌بندی
A11: زرد = ورودی کاربر | طوسی/آبی کم‌رنگ = فرمول (ویرایش نکنید) | سبز = تکمیل/موفق | نارنجی = در جریان/هشدار | قرمز = تأخیر/انحراف/ریسک بحرانی.
A12: ۵) نقش شیت‌ها
A14: برگه | B14: کاربرد | C14: واحد مسئول
A15: راهنما | B15: راهنما و استانداردها | E15: همه
A16: ورود | B16: دروازه احراز هویت نقش | E16: همه
A17: شناسنامه | B17: ثبت سفارش/ایده + وضعیت پرونده | E17: واحد ثبت سفارش
A18: امکان‌سنجی | B18: امتیازدهی Five-Case و گیت ۱ | E18: مدیر پروژه (با همکاری واحدها)
A19: گانت | B19: WBS، مبنای زمان، پیشرفت واقعی، بازنگری | E19: مدیر پروژه
A20: داشبورد | B20: KPI، منحنی S، نمودارها، چک‌لیست گردش | E20: همه
A21: مهندسی_BOM | B21: BOM + نفرساعت و زمان‌سنجی | E21: مهندسی
A22: مهندسی_مدارک | B22: رجیستر نقشه‌ها و Test Plan | E22: مهندسی
A23: بازرگانی | B23: قیمت‌گذاری اقلام BOM، ارز و گمرک، زمان تأمین | E23: بازرگانی داخلی/خارجی
A24: برنامه‌ریزی | B24: نیاز خالص، موجودی/در‌راه، تاریخ درخواست خرید | E24: برنامه‌ریزی و انبار
A25: مالی | B25: بهای تمام‌شده و بودجه فازی | E25: مالی
A26: فروش | B26: قیمت نهایی و شرایط پرداخت | E26: فروش
... A33: تنظیمات | B33: پارامترها، کاربران، ماتریس دسترسی، تعطیلات | E33: مدیر سیستم / مدیر پروژه
A36: ۶) مراجع و استانداردهای طراحی
A37: PMI — A Guide to the PMBOK® Guide (7th ed.) و Practice Standard for Scheduling (3rd ed.): ساختار WBS، گیت‌ها، کنترل زمان.
A38: GAO-16-32G, Schedule Assessment Guide: چهار آزمون برنامه (کامل/ساختار درست/منبع‌دار/قابل‌اتکا) — مبنای طراحی ستون‌های گانت و وضعیت‌ها.
A39: HM Treasury — The Five-Case Guide (Strategic/Economic/Commercial/Financial/Delivery): مبنای برگه امکان‌سنجی.
A40: ISO 21502:2020 و ISO 31000:2018: حاکمیت پروژه و مدیریت ریسک (ثبت ریسک/اقدام/بازبینی).
A41: ASME RTP-1 و ASTM D2992 (مرجع فنی نمونه نمایشی مخازن FRP — مرتبط با ماهیت صنعتی شرکت).
A43: ۷) محدودیت‌ها و امنیت
A44: • قفل شیت/ساختار و رمز کاربران در اکسل، بازدارنده است نه رمزنگاری؛ داده در فرمت xlsx روی پوشه مشترک برای هر کسی که فایل را بخواند قابل استخراج است.
A45: • برای حفاظت واقعی: استقرار فایل در Share با NTFS + ماتریس دسترسی واحدها (اسناد/IT-DEPLOYMENT.md)، قفل VBA Project، و در صورت نیاز جداسازی فایل هر واحد.
A46: • پیش‌نمایش‌های تحت وب، تقویم شمسی/فرمت‌های فارسی را ممکن است ناقص نشان دهند؛ مرجع، Excel دسکتاپ است.
A47: • فایل را با Excel 2016 به بالا باز کنید؛ محاسبات اختیاری منحنی S، برآورد خطی است و جایگزین کنترل هزینه کامل (EVM) محسوب نمی‌شود.
A48: • بازه ستون‌های گانت ثابت و هم‌تراز با سال 1405 است؛ برای سال دیگر فایل را با اسکریپت build/build_workbook.py --year 1406 بازسازی کنید.
... A51: منبع فایل یک اسکریپت Python است (build/build_workbook.py). پس از تغییر، بازسازی: python3 build/build_workbook.py --out out/Project_Management_Borna.xlsx — سپس نسخه‌گذاری و مستندسازی تغییرات الزامی است. ماژول VBA نقش‌محور در vba/modBorna.bas است.

Sheet شناسنامه
A1: شناسنامه پروژه — ثبت سفارش / ایده / طرح
A2: واحد دریافت‌کننده سفارش (بازاریابی/فروش/هر واحد) این برگه را تکمیل و به مدیریت پروژه ارجاع می‌کند. تاریخ‌ها شمسی.
A4: الف) مشخصات درخواست
A5: کد پروژه | B5: BC-P-1405-01 | F5: وضعیت پرونده (خودکار از برگه تصویب) | G5: مصوب مشروط
A6: تاریخ ثبت درخواست | B6: 1405/04/05 | F6: امتیاز امکان‌سنجی (خودکار) | G6: 78
A7: عنوان پروژه | B7: طراحی، ساخت و تحویل مخزن پلیمری FRP حجم 250m³ | F7: پیشرفت واقعی پروژه (خودکار) | G7: 0.29638889
A8: واحد/شخص ثبت‌کننده | B8: واحد بازاریابی | F8: پیشرفت برنامه‌ای امروز (خودکار) | G8: 0.28833234
A9: نوع ورودی
A10: اولویت | B10: بالا
A11: کارفرما / مشتری | B11: پتروشیمی نمونه — واحد نگهدداری
A12: مدیر پروژه مسئول | B12: مهندس رستمی
A13: تاریخ مورد نظر کارفرما | B13: 1405/11/20
A14: برآورد اولیه زمان (روز کاری) | B14: 120
A15: برآورد اولیه فروش (م.ت.) | B15: 14800
A16: بودجه مجاز سازمان (م.ت.) | B16: 12000
A18: ب) شرح مختصر و مبنای درخواست
A19: شرح | B19: کارفرما در نامه ۱۴۲/۰۴۰۱ درخواست ساخت مخزن FRP با حجم مفید ۲۵۰ مترمکعب برای نگهداری محلول اسیدی، همراه با تست هیدرواستاتیک، گواهی NDT و آموزش بهره‌بردار نموده است. تجهیزات چرخشی رزیون و قالب‌های بزرگ نیازمند تأمین خارجی است. تحویل حداکثر تا پایان دی ۱۴۰۵ مشمول وجه التزام روزی ۱۵۰ م.ت.
A23: ج) گردش ارجاع (امضاها)
A24: مرحله | B24: واحد / شخص | C24: تاریخ (شمسی) | D24: امضا | E24: یادداشت
A25: ثبت درخواست | B25: واحد بازاریابی
A26: تحویل به مدیریت پروژه | B26: دفتر مدیر پروژه
A27: بازگشت به واحد متقاضی (در صورت رد/اصلاح) | B27: واحد متقاضی

Sheet امکان‌سنجی
A1: امکان‌سنجی پروژه (Feasibility / Five-Case)
A2: تدوین توسط مدیریت پروژه با همکاری واحدهای تخصصی. مبنای ارزیابی: Five-Case خزانه بریتانیا + چک‌لیست PMI. امتیاز ۱ تا ۵؛ نتیجه در شناسنامه و داشبورد منعکس می‌شود.
A6: ردیف | B6: معیار | C6: دسته | D6: وزن ٪ | E6: امتیاز (۱-۵) | F6: وزنی (از ۱۰۰) | G6: مستند / مبنای امتیاز
A7: 1 | B7: تقاضا و بازار هدف | C7: بازار | D7: 15 | E7: 5 | F7: 15 | G7: نمونه‌کار مشابه ۱۴۰۴؛ مکاتبه پتروشیمی
A8: 2 | B8: مزیت رقابتی و ریسک قیمت | C8: بازار | D8: 10 | E8: 4 | F8: 8 | G8: تولید داخل؛ رقابت دو تأمین‌کننده وارداتی
A9: 3 | B9: ظرفیت فنی و مهندسی (طراحی، قالب، لی‌آپ) | C9: فنی | D9: 15 | E9: 4 | F9: 12 | G9: نیاز به قالب جدید؛ دانش فنی موجود
A10: 4 | B10: تجهیزات و زیرساخت (تزریق رزی، پخت) | C10: فنی | D10: 10 | E10: 3 | F10: 6 | G10: پمپ تزریق نیازمند تأمین خارجی
A11: 5 | B11: زنجیره تأمین مواد (رزین/الیاف/شیمیایی) | C11: تأمین | D11: 10 | E11: 4 | F11: 8 | G11: موجودی رزین کافی؛ الیاف از تأمین‌کننده معتبر
A12: 6 | B12: ریسک اجرایی و HSE | C12: ریسک | D12: 10 | E12: 3 | F12: 6 | G12: کار در ارتفاع و مواد شیمیایی؛ مجوز HSE لازم
A13: 7 | B13: بازگشت سرمایه و نقدینگی | C13: مالی | D13: 15 | E13: 4 | F13: 12 | G13: حاشیه سود هدف ≥۱۸٪؛ پیش‌پرداخت ۴۰٪
A14: 8 | B14: انطباق با قوانین و استاندارد (ISO/ASME) | C14: قانونی | D14: 5 | E14: 4 | F14: 4 | G14: استفاده از ASME RTP-1 برای مخازن FRP
A15: 9 | B15: تعهم نیروی انسانی | C15: سازمانی | D15: 5 | E15: 4 | F15: 4 | G15: تیم ۱۲ نفره؛ دو نفر پیمانکاری
A16: 10 | B16: فشار زمانی تحویل | C16: زمان | D16: 5 | E16: 3 | F16: 3 | G16: تحویل ۶ ماهه فشرده ولی امکان‌پذیر
B17: جمع | D17: 100 | F17: 78 | G17: وزن‌ها باید ۱۰۰ و امتیاز کل از ۱۰۰ باشد
B19: نتیجه | C19: ✓ مجاز به ادامه — ورود به فاز برنامه‌ریزی و گانت
B20: تاریخ ارزیابی | C20: 1405/04/22 | D20: بازنگری (در میانه پروژه) | E20: در صورت تغییر دامنه، امتیازدهی و گانت الزاماً بازنگری می‌شود (مسئول: مدیر پروژه).

Sheet گانت
A1: گانت پروژه — برنامه‌ریزی و کنترل زمان
A2: ورودی ستون‌های زرد: تاریخ شمسی (قالب 1405/07/01)، درصد پیشرفت و یادداشت. محاسبات سریال/وضعیت خودکار است. ستون‌های گانت بر اساس تقویم تنظیم می‌شوند؛ برای سال دیگر اسکریپت سازنده را با --year اجرا کنید.
B3: شاخص‌ها: | C3: امروز (شمسی) | F3: پیشرفت واقعی | I3: پیشرفت برنامه‌ای امروز | L3: فعالیت در تأخیر/عقب‌افتاده
C4: 1405/07/01 | F4: 0.29638889 | I4: 0.28833234 | L4: 6 | T4: فروردین
T5: 1 | U5: 2 | V5: 3 | W5: 4 | X5: 5 | Y5: 6 | Z5: 7 | AA5: 8 | AB5: 9 | AC5: 10 | AD5: 11
T6: 46102 | U6: 46103 | V6: 46104 | W6: 46105 | X6: 46106 | Y6: 46107 | Z6: 46108 | AA6: 46109 | AB6: 46110 | AC6: 46111 | AD6: 46112
A7: ردیف | B7: کد WBS | C7: شرح فعالیت / بسته کاری | D7: واحد مسئول | E7: پیش‌نیاز | F7: شروع مبنایی | G7: پایان مبنایی | H7: شروع واقعی | I7: پایان واقعی/پیش‌بینی | J7: پیشرفت ٪ | K7: sF | L7: sG | M7: sH | N7: sI | O7: مدت (WD) | P7: باقی‌مانده | Q7: برنامه‌ای امروز | R7: وضعیت | S7: یادداشت
A8: 1 | B8: F0 | C8: فاز ۰ — ورودی، امکان‌سنجی و تصویب | K8: 0 | L8: 0 | M8: 0 | N8: 0 | O8: 0 | P8: — | Q8: 0
A9: 2 | B9: F0.1 | C9: ثبت سفارش/ایده و صدور شناسنامه | D9: واحد ثبت سفارش | E9: — | F9: 1405/04/01 | G9: 1405/04/05 | H9: 1405/04/01 | I9: 1405/04/05 | J9: 1 | K9: 46195 | L9: 46199 | M9: 46195 | N9: 46199 | O9: 5 | Q9: 1 | R9: تکمیل با تأخیر | S9: نمونه‌کار مشابه: مخزن ۱۰۰m³ پارس‌ودا
A10: 3 | B10: F0.2 | C10: تهیه پیش‌نویس گانت و ساختار WBS توسط مدیر پروژه | D10: مدیر پروژه | E10: F0.1 | F10: 1405/04/06 | G10: 1405/04/10 | H10: 1405/04/06 | I10: 1405/04/11 | J10: 1 | K10: 46200 | L10: 46204 | M10: 46200 | N10: 46205 | O10: 4 | Q10: 1 | R10: تکمیل با تأخیر | S10: WBS ۴ سطحی، مبنای ۵ Case
A11: 4 | B11: F0.3 | C11: امکان‌سنجی و امتیازدهی معیارها | D11: مدیر پروژه | E11: F0.2 | F11: 1405/04/12 | G11: 1405/04/22 | H11: 1405/04/13 | I11: 1405/04/22 | J11: 1 | K11: 46206 | L11: 46216 | M11: 46207 | N11: 46216 | O11: 9 | Q11: 1 | R11: تکمیل با تأخیر | S11: همکاری مهندسی/مالی — برگه امکان‌سنجی
A12: 5 | B12: F0.4 | C12: جلسه کمیته تصویب (گیت ۱) | D12: مدیریت ارشد | E12: F0.3 | F12: 1405/04/25 | G12: 1405/04/26 | H12: 1405/04/25 | I12: 1405/04/26 | J12: 1 | K12: 46219 | L12: 46220 | M12: 46219 | N12: 46220 | O12: 2 | Q12: 1 | R12: تکمیل با تأخیر | S12: مصوب مشروط: بازنگری پس از BOM نهایی
A13: 6 | B13: F1 | C13: فاز ۱ — مهندسی | K13: 0 | L13: 0 | M13: 0 | N13: 0 | O13: 0 | P13: — | Q13: 0
A14: 7 | B14: F1.1 | C14: دریافت نقشه‌ها و مشخصات فنی از کارفرما | D14: مهندسی | E14: F0.4 | F14: 1405/05/01 | G14: 1405/05/08 | H14: 1405/05/01 | I14: 1405/05/09 | J14: 1 | K14: 46226 | L14: 46233 | M14: 46226 | N14: 46234 | O14: 7 | Q14: 1 | R14: تکمیل با تأخیر | S14: ۱۴ نقشه / rev B
A15: 8 | B15: F1.2 | C15: تدوین Test Plan و روش‌های آزمون | D15: مهندسی | E15: F1.1 | F15: 1405/05/09 | G15: 1405/05/20 | H15: 1405/05/10 | I15: 1405/05/22 | J15: 1 | K15: 46234 | L15: 46245 | M15: 46235 | N15: 46247 | O15: 10 | Q15: 1 | R15: تکمیل با تأخیر | S15: ASTM D2992 / ASME RTP-1
A16: 9 | B16: F1.3 | C16: تهیه BOM اولیه و محاسبه نفرساعت | D16: مهندسی | E16: F1.2 | F16: 1405/05/21 | G16: 1405/05/30 | H16: 1405/05/21 | I16: 1405/05/30 | J16: 1 | K16: 46246 | L16: 46255 | M16: 46246 | N16: 46255 | O16: 9 | Q16: 1 | R16: تکمیل با تأخیر | S16: BOM rev0 ارسال به بازرگانی
A17: 10 | B17: F1.4 | C17: طراحی قالب و نهایی‌سازی BOM | D17: مهندسی | E17: F1.3 | F17: 1405/05/31 | G17: 1405/06/10 | H17: 1405/05/31 | I17: 1405/06/14 | J17: 0.9 | K17: 46256 | L17: 46266 | M17: 46256 | N17: 46270 | O17: 9 | P17: 0 | Q17: 1 | R17: در تأخیر | S17: قالب اسپیل ۲۵۰m³ — ۹۰٪
A18: 11 | B18: F2 | C18: فاز ۲ — تأمین (بازرگانی) | K18: 0 | L18: 0 | M18: 0 | N18: 0 | O18: 0 | P18: — | Q18: 0
A19: 12 | B19: F2.1 | C19: استعلام و قیمت‌گذاری داخلی (رزین، الیاف، شیمیایی) | D19: بازرگانی داخلی | E19: F1.3 | F19: 1405/06/03 | G19: 1405/06/16 | H19: 1405/06/03 | I19: 1405/06/20 | J19: 0.75 | K19: 46259 | L19: 46272 | M19: 46259 | N19: 46276 | O19: 12 | P19: 0 | Q19: 1 | R19: در تأخیر | S19: ۳ تأمین‌کننده رزین ایزو
A20: 13 | B20: F2.2 | C20: استعلام خارجی (پمپ رزیون، تجهیزات تزریق) | D20: بازرگانی خارجی | E20: F1.3 | F20: 1405/06/04 | G20: 1405/06/22 | H20: 1405/06/06 | I20: 1405/07/15 | J20: 0.45 | K20: 46260 | L20: 46278 | M20: 46262 | N20: 46302 | O20: 14 | P20: 0 | Q20: 1 | R20: در تأخیر | S20: تأخیر در L/C — ریسک R-02 فعال
A21: 14 | B21: F2.3 | C21: ارزیابی و انتخاب تأمین‌کننده / قرارداد | D21: بازرگانی داخلی | E21: F2.1 | F21: 1405/06/23 | G21: 1405/06/30 | H21: 1405/06/24 | I21: 1405/07/04 | J21: 0.6 | K21: 46279 | L21: 46286 | M21: 46280 | N21: 46291 | O21: 7 | P21: 0 | Q21: 1 | R21: در تأخیر | S21: ماتریس ارزیابی تکمیل شد
A22: 15 | B22: F2.4 | C22: صدور سفارش خرید و تخصیص ارز/اسناد | D22: مالی | E22: F2.3 | F22: 1405/06/28 | G22: 1405/07/12 | H22: 1405/07/01 | J22: 0.3 | K22: 46284 | L22: 46299 | M22: 46288 | N22: 0 | O22: 13 | P22: 10 | Q22: 0.3125 | R22: در جریان | S22: منتظر تخصیص ارز نیمایی
A23: 16 | B23: F2.5 | C23: پایش تحویل و رسید انبار اقلام | D23: برنامه‌ریزی و انبار | E23: F2.4 | F23: 1405/07/01 | G23: 1405/07/25 | H23: 1405/07/01 | J23: 0.1 | K23: 46288 | L23: 46312 | M23: 46288 | N23: 0 | O23: 22 | P23: 22 | Q23: 0.04 | R23: در جریان | S23: رسید الیاف در سامانه
A24: 17 | B24: F3 | C24: فاز ۳ — تولید | K24: 0 | L24: 0 | M24: 0 | N24: 0 | O24: 0 | P24: — | Q24: 0
A25: 18 | B25: F3.1 | C25: ساخت قالب و ابزارها | D25: برنامه‌ریزی و انبار | E25: F1.4 | F25: 1405/07/05 | G25: 1405/07/28 | K25: 46292 | L25: 46315 | M25: 0 | N25: 0 | O25: 20 | P25: 20 | Q25: 0 | R25: آغازنشده | S25: پیمانکشی — پیش‌فاکتور تأیید شد
A26: 19 | B26: F3.2 | C26: لایه‌نشانی بدنه و پخت رزین | D26: برنامه‌ریزی و انبار | E26: F2.5 | F26: 1405/08/01 | G26: 1405/08/25 | K26: 46318 | L26: 46342 | M26: 0 | N26: 0 | O26: 21 | P26: 21 | Q26: 0 | R26: آغازنشده
A27: 20 | B27: F3.3 | C27: رینگ‌های تقویتی و نازل‌ها | D27: برنامه‌ریزی و انبار | E27: F2.5 | F27: 1405/08/20 | G27: 1405/09/10 | K27: 46337 | L27: 46357 | M27: 0 | N27: 0 | O27: 18 | P27: 18 | Q27: 0 | R27: آغازنشده
A28: 21 | B28: F3.4 | C28: مونتاژ نهایی و اتصالات | D28: برنامه‌ریزی و انبار | E28: F3.3 | F28: 1405/09/11 | G28: 1405/09/25 | K28: 46358 | L28: 46372 | M28: 0 | N28: 0 | O28: 13 | P28: 13 | Q28: 0 | R28: آغازنشده
A29: 22 | B29: F4 | C29: فاز ۴ — کیفیت و تست | K29: 0 | L29: 0 | M29: 0 | N29: 0 | O29: 0 | P29: — | Q29: 0
A30: 23 | B30: F4.1 | C30: تست هیدرواستاتیک و NDT | D30: مهندسی | E30: F3.4 | F30: 1405/09/26 | G30: 1405/10/06 | K30: 46373 | L30: 46383 | M30: 0 | N30: 0 | O30: 9 | P30: 9 | Q30: 0 | R30: آغازنشده | S30: ناظر ثالث مشتری
A31: 24 | B31: F4.2 | C31: ترمیم، ژل‌کوت نهایی و بسته‌بندی | D31: برنامه‌ریزی و انبار | E31: F4.1 | F31: 1405/10/07 | G31: 1405/10/18 | K31: 46384 | L31: 46395 | M31: 0 | N31: 0 | O31: 11 | P31: 11 | Q31: 0 | R31: آغازنشده
A32: 25 | B32: F5 | C32: فاز ۵ — مالی، فروش و تحویل | K32: 0 | L32: 0 | M32: 0 | N32: 0 | O32: 0 | P32: — | Q32: 0
A33: 26 | B33: F5.1 | C33: تدوین بهای تمام‌شده و گزارش انحراف بودجه (چرخه ماهانه) | D33: مالی | E33: F2.1 | F33: 1405/07/01 | G33: 1405/11/20 | H33: 1405/07/01 | J33: 0.15 | K33: 46288 | L33: 46427 | M33: 46288 | N33: 0 | O33: 120 | P33: 120 | Q33: 0.0071428571 | R33: در جریان | S33: به‌روزرسانی ماهانه
A34: 27 | B34: F5.2 | C34: تعیین قیمت نهایی فروش و شرایط پرداخت | D34: فروش | E34: F1.3 | F34: 1405/06/15 | G34: 1405/06/28 | H34: 1405/06/16 | J34: 0.5 | K34: 46271 | L34: 46284 | M34: 46272 | N34: 0 | O34: 10 | P34: 0 | Q34: 1 | R34: در تأخیر | S34: بر اساس بهای تقریبی rev1
A35: 28 | B35: F5.3 | C35: جمع‌بندی مدیر پروژه و تصویب نهایی مدیریت ارشد | D35: مدیر پروژه | E35: F5.2 | F35: 1405/07/02 | G35: 1405/07/06 | H35: 1405/07/01 | I35: 1405/07/01 | J35: 1 | K35: 46289 | L35: 46293 | M35: 46288 | N35: 46288 | O35: 4 | Q35: 0 | R35: تکمیل‌شده | S35: مصوب مشروط ثبت شد (برگه تصویب)
A36: 29 | B36: F5.4 | C36: حمل و تحویل کارگاهی | D36: برنامه‌ریزی و انبار | E36: F4.2 | F36: 1405/10/20 | G36: 1405/10/31 | K36: 46397 | L36: -1 | M36: 0 | N36: 0 | O36: 0 | P36: — | Q36: 0 | R36: عقب‌افتاده
A37: 30 | B37: F5.5 | C37: نصب، راه‌اندازی و آموزش بهره‌بردار | D37: مدیر پروژه | E37: F5.4 | F37: 1405/11/03 | G37: 1405/11/12 | K37: 46410 | L37: 46419 | M37: 0 | N37: 0 | O37: 8 | P37: 8 | Q37: 0 | R37: آغازنشده
A38: 31 | B38: F5.6 | C38: صورت‌جلسه تحویل و صدور گارانتی ۱۸ ماهه | D38: مدیر پروژه | E38: F5.5 | F38: 1405/11/13 | G38: 1405/11/15 | K38: 46420 | L38: 46422 | M38: 0 | N38: 0 | O38: 3 | P38: 3 | Q38: 0 | R38: آغازنشده
K39: 0 | L39: 0 | M39: 0 | N39: 0 | O39: 0 | P39: — | Q39: 0
K40: 0 | L40: 0 | M40: 0 | N40: 0 | O40: 0 | P40: — | Q40: 0
...

Sheet داشبورد
A1: داشبورد مدیریتی — وضعیت پرونده
A2: تمام مقادیر از سایر برگه‌ها محاسبه می‌شوند (بدون ورودی). برای تازه‌سازی: Ctrl+Alt+F9.
A5: وضعیت پرونده | D5: امتیاز امکان‌سنجی | G5: پیشرفت واقعی کل | J5: پیشرفت برنامه‌ای امروز | M5: فعالیت در تأخیر (باز) | P5: اقلام BOM قیمت‌گیری‌شده
A6: مصوب مشروط | D6: 78 | G6: 0.29638889 | J6: 0.28833234 | M6: 6 | P6: 1
A9: بهای تمام‌شده (م.ت.) | D9: بودجه مصوب (م.ت.) | G9: هزینه واقعی تا امروز (م.ت.) | J9: CPI (اثر هزینه) | M9: SPI (اثر زمان) | P9: ریسک‌های باز
A10: 12549.3 | D10: 12880 | G10: 2872.2 | J10: 1.33 | M10: 1.03 | P10: 8
A13: قیمت نهایی فروش (م.ت.) | D13: حاشیه سود (٪) | G13: اقلام بحرانی تأمین | J13: تغییرات تأییدنشده | M13: تاریخ امروز (شمسی) | P13: مدیر پروژه
A14: 14512 | D14: 0.99875965 | G14: 0 | J14: 1 | M14: 1405/07/01 | P14: مهندس رستمی
A18: پیشرفت واحدهای درگیر (از گانت)
A19: واحد | B19: فعالیت | C19: پیشرفت واقعی ٪ | D19: پیشرفت برنامه‌ای ٪ | E19: در تأخیر
A20: مدیر پروژه | B20: 5 | C20: 0.60714286 | D20: 0.46428571 | E20: 0
A21: مهندسی | B21: 5 | C21: 0.775 | D21: 0.79545455 | E21: 1
A22: بازرگانی داخلی | B22: 2 | C22: 0.69473684 | D22: 1 | E22: 2
A23: بازرگانی خارجی | B23: 1 | C23: 0.45 | D23: 1 | E23: 1
A24: برنامه‌ریزی و انبار | B24: 7 | C24: 0.020952381 | D24: 0.0083809524 | E24: 1
A25: مالی | B25: 2 | C25: 0.16466165 | D25: 0.036989796 | E25: 0
A26: فروش | B26: 1 | C26: 0.5 | D26: 1 | E26: 1
A28: منحنی S — پیشرفت تجمعی (٪)
A29: ماه (پایان)
B30: فروردین | C30: اردیبهشت | D30: خرداد | E30: تیر | F30: مرداد | G30: شهریور | H30: مهر | I30: آبان | J30: آذر | K30: دی | L30: بهمن | M30: اسفند
B31: 46132 | C31: 46163 | D31: 46194 | E31: 46225 | F31: 46256 | G31: 46287 | H31: 46317 | I31: 46347 | J31: 46377 | K31: 46407 | L31: 46437 | M31: 46466
A32: برنامه‌ای | B32: 0 | C32: 0 | D32: 0 | E32: 5.5555556 | F32: 13.005051 | G32: 28.125 | H32: 50.753968 | I32: 66.349206 | J32: 80.620491 | K32: 92.18254 | L32: 100 | M32: 100
A33: واقعی | B33: 0 | C33: 0 | D33: 0 | E33: 5.5555556 | F33: 15.027778 | G33: 21.833333 | H33: 29.638889 | I33: 29.638889 | J33: 29.638889 | K33: 29.638889 | L33: 29.638889 | M33: 29.638889
A43: ریسک — جمع‌بندی
A44: باز | C44: 8
A45: بسته/پایش | C45: 0
A49: چک‌لیست گردش فرآیند (خودکار بر اساس تکمیل برگه‌ها)
A50: مرحله | B50: واحد متولی | C50: وضعیت ثبت
A51: ثبت سفارش/شناسنامه | B51: واحد ثبت سفارش | C51: ✓ ثبت شد
A52: امکان‌سنجی | B52: مدیر پروژه | C52: ✓ انجام شد
A53: گانت اولیه | B53: مدیر پروژه | C53: ✓ تدوین شد
A54: مدارک مهندسی | B54: مهندسی | C54: ✓ دریافت شد
A55: BOM و نفرساعت | B55: مهندسی | C55: ✓ تهیه شد
A56: قیمت‌گذاری تأمین | B56: بازرگانی | C56: ✓ قیمت‌گذاری شد
A57: نیازسنجی تولید و انبار | B57: برنامه‌ریزی | C57: ✓ انجام شد
A58: بهای تمام‌شده و بودجه | B58: مالی | C58: ✓ تدوین شد
A59: قیمت فروش و پرداخت | B59: فروش | C59: ✓ تعیین شد
A60: جمع‌بندی مدیر پروژه | B60: مدیر پروژه | C60: ✓ ارسال شد
A61: تصمیم مدیریت ارشد | B61: مدیریت ارشد | C61: ✓ ثبت شد

Sheet مهندسی_BOM
A1: مهندسی — لیست مواد (BOM) و نفرساعت
A2: BOM مبنای کار بازرگانی، برنامه‌ریزی و مالی است. ستون K وضعیت قیمت‌گذاری را از برگه بازرگانی به‌صورت خودکار نشان می‌دهد. مقادیر بر مبنای یک محصول نهایی.
A5: تعداد محصول سفارشی | B5: 1 | C5: ← ضریب کل BOM (ستون L)؛ برنامه‌ریزی تولید این ستون را می‌خواند
A6: الف) BOM — بر مبنای یک دستگاه محصول نهایی
A7: ردیف | B7: کد فنی | C7: شرح قلم | D7: مشخصات / استاندارد | E7: واحد | F7: مقدار پایه | G7: ضایعات ٪ | H7: مقدار نهایی | I7: کلاس | J7: منبع | K7: قیمت‌گذاری بازرگانی | L7: مقدار سفارش
A8: 1 | B8: RM-RES-ISO | C8: رزین ایزوفتالیک | D8: ویسکوزیته پایین، استایرن ۴۵-۵۰٪، IRAM 7583 | E8: کیلوگرم | F8: 5200 | G8: 5 | H8: 5460 | I8: مواد اولیه | J8: داخلی | K8: ✓ قیمت‌گذاری شد | L8: 5460
A9: 2 | B9: RM-GF-MAT | C9: فایبرگلاس MAT ۴۵۰ | D9: E-Glass 450g/m² — ASTM D5767 | E9: کیلوگرم | F9: 2100 | G9: 8 | H9: 2268 | I9: مواد اولیه | J9: داخلی | K9: ✓ قیمت‌گذاری شد | L9: 2268
A10: 3 | B10: RM-GF-ROV | C10: رووینگ ۲۴۰۰tex | D10: E-Glass 2400tex — for filament winding | E10: کیلوگرم | F10: 1650 | G10: 6 | H10: 1749 | I10: مواد اولیه | J10: داخلی | K10: ✓ قیمت‌گذاری شد | L10: 1749
A11: 4 | B11: RM-CH-PER | C11: کاتالیزور MEKP | D11: متیل اتیل کتون پر اکساید ۹٪ | E11: کیلوگرم | F11: 95 | G11: 3 | H11: 97.9 | I11: شیمیایی | J11: داخلی | K11: ✓ قیمت‌گذاری شد | L11: 97.9
A12: 5 | B12: RM-CH-ACC | C12: شتاب‌دهنده کبالت | D12: اکتوات کبالت ۶٪ | E12: لیتر | F12: 28 | G12: 2 | H12: 28.6 | I12: شیمیایی | J12: داخلی | K12: ✓ قیمت‌گذاری شد | L12: 28.6
A13: 6 | B13: RM-GEL | C13: ژل‌کوت اورتالیک | D13: مقاوم شیمیایی — رنگ خاکستری RAL7035 | E13: کیلوگرم | F13: 340 | G13: 6 | H13: 360.4 | I13: مواد اولیه | J13: وارداتی | K13: ✓ قیمت‌گذاری شد | L13: 360.4
A14: 7 | B14: EQ-PUMP | C14: پمپ تزریق رزیون | D14: دوجزئی، دبی ۱۲L/min، فشار ۲۵bar | E14: عدد | F14: 1 | G14: 0 | H14: 1 | I14: تجهیزات | J14: وارداتی | K14: ✓ قیمت‌گذاری شد | L14: 1
A15: 8 | B15: EQ-MIX | C15: میکسر صنعتی ۷۵۰ لیتری | D15: استیل ۳۰۴، موتور ۵.۵kW | E15: عدد | F15: 1 | G15: 0 | H15: 1 | I15: تجهیزات | J15: داخلی | K15: ✓ قیمت‌گذاری شد | L15: 1
A16: 9 | B16: CW-FLG-16 | C16: فلنج کربن استیل DN150 | D16: ASME B16.5 Class150 RF | E16: عدد | F16: 6 | G16: 0 | H16: 6 | I16: متفرقه | J16: داخلی | K16: ✓ قیمت‌گذاری شد | L16: 6
A17: 10 | B17: CW-FLG-24 | C17: فلنج کربن استیل DN200 | D17: ASME B16.5 Class150 RF | E17: عدد | F17: 2 | G17: 0 | H17: 2 | I17: متفرقه | J17: داخلی | K17: ✓ قیمت‌گذاری شد | L17: 2
A18: 11 | B18: CW-MAN | C18: مردآب (Manway) ۵۰۰mm | D18: فلزی با درب و اورینگ EPDM | E18: عدد | F18: 1 | G18: 0 | H18: 1 | I18: متفرقه | J18: داخلی | K18: ✓ قیمت‌گذاری شد | L18: 1
A19: 12 | B19: CW-NIP | C19: نازل خروج/ورود و شیرآف | D19: DN50/DN80، فلنجی | E19: عدد | F19: 14 | G19: 0 | H19: 14 | I19: متفرقه | J19: داخلی | K19: ✓ قیمت‌گذاری شد | L19: 14
... A23: 16 | B23: SV-CAL | C23: کالیبراسیون و تست هیدرواستاتیک | D23: خدمات ثالث — ISO 17025 | E23: دفعه | F23: 1 | G23: 0 | H23: 1 | I23: خدمات | J23: داخلی | K23: ✓ قیمت‌گذاری شد | L23: 1
C32: جمع اقلام BOM | F32: 16 | K32: 16 از 16
A34: ب) نفرساعت و زمان‌سنجی (مبنای حق‌الزحمه مستقیم نیروی کار)
A35: فعالیت | B35: تعداد نفر | C35: ساعت/روز | D35: روز کاری | E35: نفرساعت | F35: نرخ ساعتی (تومان) | G35: هزینه کل (م.ت.)
A36: طراحی و نقشه‌کشی | B36: 2 | C36: 8 | D36: 12 | E36: 192 | F36: 250000 | G36: 48
A37: محاسبات سازه و لایه‌چین | B37: 1 | C37: 6 | D37: 8 | E37: 48 | F37: 265000 | G37: 12.7
A38: ساخت قالب و الگو | B38: 3 | C38: 8 | D38: 10 | E38: 240 | F38: 280000 | G38: 67.2
A39: لایه‌نشانی و تولید بدنه | B39: 6 | C39: 8 | D39: 18 | E39: 864 | F39: 295000 | G39: 254.9
A40: مونتاژ نازل و اتصالات | B40: 3 | C40: 8 | D40: 6 | E40: 144 | F40: 310000 | G40: 44.6
A41: کنترل کیفیت و تست | B41: 2 | C41: 8 | D41: 5 | E41: 80 | F41: 325000 | G41: 26
A42: بسته‌بندی، حمل و نصب | B42: 4 | C42: 8 | D42: 4 | E42: 128 | F42: 340000 | G42: 43.5
A43: جمع نفرساعت / هزینه نیروی کار | E43: 1696 | G43: 496.9

Sheet مهندسی_مدارک
A1: مهندسی — رجیستر مدارک پروژه
A2: نقشه‌ها، Test Plan، مشخصات فنی و گواهی‌ها. هر مدرک ورودی از کارفرما/مشاور در اینجا ثبت و شماره‌گذاری می‌شود.
A6: ردیف | B6: کد مدرک | C6: عنوان مدرک | D6: نوع | E6: Revision | F6: تاریخ (شمسی) | G6: منبع/تحویل‌دهنده | H6: وضعیت | I6: مسیر فایل / شبکه | J6: پیوست
A8: 1 | B8: BC-ENG-DRW-001 | C8: نقشه جامع مخزن 250m³ | D8: نقشه | E8: C | F8: 1405/05/02 | G8: کارفرما — مهندس مشاور | H8: دریافت‌شده | I8: \\BORNASRV\Projects\BC-P-1405-01\Engineering\Drawings | J8: —
A9: 2 | B9: BC-ENG-DRW-002 | C9: نقشه لایه‌چینی (Lay-up Schedule) | D9: نقشه | E9: B | F9: 1405/05/06 | G9: مهندسی برنا | H9: دریافت‌شده | I9: \\BORNASRV\Projects\BC-P-1405-01\Engineering\Layup | J9: —
A10: 3 | B10: BC-ENG-TPL-001 | C10: طرح قالب اسپیل و مونتاژ | D10: نقشه | E10: A | F10: 1405/06/08 | G10: مهندسی برنا | H10: به‌روزرسانی لازم | I10: \\BORNASRV\Projects\BC-P-1405-01\Engineering\Mold | J10: —
A11: 4 | B11: BC-ENG-TP-001 | C11: Test Plan — آزمون هیدرواستاتیک و نشت | D11: Test Plan | E11: A | F11: 1405/05/21 | G11: مهندسی + QC | H11: دریافت‌شده | I11: \\BORNASRV\Projects\BC-P-1405-01\Quality\TP | J11: —
A12: 5 | B12: BC-ENG-SPC-001 | C12: مشخصات فنی رزین و الیاف | D12: مشخصات | E12: D | F12: 1405/05/25 | G12: بازرگانی/تأمین‌کننده | H12: دریافت‌شده | I12: \\BORNASRV\Projects\BC-P-1405-01\Procurement\Specs | J12: —
A13: 6 | B13: BC-ENG-CAL-001 | C13: محاسبات سازه ASME RTP-1 | D13: محاسبات | E13: B | F13: 1405/06/12 | G13: مهندس مشاور | H13: منتظر دریافت | I13: \\BORNASRV\Projects\BC-P-1405-01\Engineering\Calcs | J13: —
A14: 7 | B14: BC-ENG-HSE-001 | C14: ماتریس ایمنی کار در ارتفاع و مواد شیمیایی | D14: HSE | E14: A | F14: 1405/06/18 | G14: HSE | H14: دریافت‌شده | I14: \\BORNASRV\Projects\BC-P-1405-01\HSE | J14: —
A15: 8 | B15: BC-ENG-CRT-001 | C15: گواهی‌های آزمون مواد (MTC) | D15: گواهی | E15: — | G15: تأمین‌کنندگان | H15: منتظر دریافت | J15: —

Sheet بازرگانی
A1: بازرگانی داخلی و خارجی — قیمت‌گذاری اقلام BOM
A2: شرح/واحد/مقدار از BOM مهندسی با کد فنی لینک می‌شود (فیلدهای طوسی را ویرایش نکنید). قیمت واحد به پول قلم؛ نرخ ارز از برگه تنظیمات. جمع نهایی به میلیون تومان به واحد مالی ارسال می‌شود.
A7: ردیف | B7: کد فنی قلم | C7: شرح (از BOM) | D7: واحد | E7: مقدار نهایی | F7: نوع (داخلی/خارجی) | G7: تأمین‌کننده / کشور | H7: ارز | I7: قیمت واحد | J7: نرخ ارز (تومان) | K7: عوارض+گمرک ٪ | L7: حمل و بیمه (تومان) | M7: قیمت تمام‌شده واحد (تومان) | N7: جمع (تومان) | O7: تاریخ استعلام | P7: موعد تحویل تأمین‌کننده | Q7: سریال موعد | R7: سریال استعلام | S7: Lead (روز) | T7: وضعیت
A8: 1 | B8: RM-RES-ISO | C8: رزین ایزوفتالیک | D8: کیلوگرم | E8: 5460 | F8: داخلی | G8: شرکت پترو رزین اصفهان | H8: تومان | I8: 185000 | J8: 1 | K8: 0 | L8: 0 | M8: 185000 | N8: 1010100000 | O8: 1405-06-05 | P8: 1405-06-28 | Q8: 46284 | R8: 46261 | S8: 23 | T8: ⚠ موعد گذشته
A9: 2 | B9: RM-GF-MAT | C9: فایبرگلاس MAT ۴۵۰ | D9: کیلوگرم | E9: 2268 | F9: داخلی | G9: ایران کامپوزیت رشت | H9: تومان | I9: 152000 | J9: 1 | K9: 0 | L9: 0 | M9: 152000 | N9: 344736000 | O9: 1405-06-06 | P9: 1405-07-05 | Q9: 46292 | R9: 46262 | S9: 30 | T9: نزدیک موعد
A10: 3 | B10: RM-GF-ROV | C10: رووینگ ۲۴۰۰tex | D10: کیلوگرم | E10: 1749 | F10: داخلی | G10: ایران کامپوزیت رشت | H10: تومان | I10: 138000 | J10: 1 | K10: 0 | L10: 25000000 | M10: 138000 | N10: 266362000 | O10: 1405-06-06 | P10: 1405-07-05 | Q10: 46292 | R10: 46262 | S10: 30 | T10: نزدیک موعد
A11: 4 | B11: RM-CH-PER | C11: کاتالیزور MEKP | D11: کیلوگرم | E11: 97.9 | F11: داخلی | G11: شیمی‌پارس | H11: تومان | I11: 2400000 | J11: 1 | K11: 0 | L11: 0 | M11: 2400000 | N11: 234960000 | O11: 1405-06-08 | P11: 1405-06-20 | Q11: 46276 | R11: 46264 | S11: 12 | T11: ⚠ موعد گذشته
A12: 5 | B12: RM-CH-ACC | C12: شتاب‌دهنده کبالت | D12: لیتر | E12: 28.6 | F12: داخلی | G12: شیمی‌پارس | H12: تومان | I12: 3100000 | J12: 1 | K12: 0 | L12: 0 | M12: 3100000 | N12: 88660000 | O12: 1405-06-08 | P12: 1405-06-20 | Q12: 46276 | R12: 46264 | S12: 12 | T12: ⚠ موعد گذشته
A13: 6 | B13: RM-GEL | C13: ژل‌کوت اورتالیک | D13: کیلوگرم | E13: 360.4 | F13: خارجی | G13: Polypaint — ترکیه | H13: یورو | I13: 4.6 | J13: 132000 | K13: 21 | L13: 38000000 | M13: 734712 | N13: 3.027902e+08 | O13: 1405-06-09 | P13: 1405-07-28 | Q13: 46315 | R13: 46265 | S13: 50 | T13: در جریان
A14: 7 | B14: EQ-PUMP | C14: پمپ تزریق رزیون | D14: عدد | E14: 1 | F14: خارجی | G14: Graco — آمریکا/واسط هند | H14: دلار | I14: 21500 | J14: 120000 | K14: 23 | L14: 145000000 | M14: 3173400000 | N14: 3318400000 | O14: 1405-06-10 | P14: 1405-08-02 | Q14: 46319 | R14: 46266 | S14: 53 | T14: در جریان
A15: 8 | B15: EQ-MIX | C15: میکسر صنعتی ۷۵۰ لیتری | D15: عدد | E15: 1 | F15: داخلی | G15: سازنده ماشین‌سازی تبریز | H15: تومان | I15: 1280000000 | J15: 1 | K15: 0 | L15: 42000000 | M15: 1280000000 | N15: 1322000000 | O15: 1405-06-12 | P15: 1405-07-22 | Q15: 46309 | R15: 46268 | S15: 41 | T15: در جریان
A16: 9 | B16: CW-FLG-16 | C16: فلنج کربن استیل DN150 | D16: عدد | E16: 6 | F16: داخلی | G16: آهن‌پایه تهران | H16: تومان | I16: 9600000 | J16: 1 | K16: 0 | L16: 0 | M16: 9600000 | N16: 57600000 | O16: 1405-06-13 | P16: 1405-07-01 | Q16: 46288 | R16: 46269 | S16: 19 | T16: نزدیک موعد
A17: 10 | B17: CW-FLG-24 | C17: فلنج کربن استیل DN200 | D17: عدد | E17: 2 | F17: داخلی | G17: آهن‌پایه تهران | H17: تومان | I17: 14200000 | J17: 1 | K17: 0 | L17: 0 | M17: 14200000 | N17: 28400000 | O17: 1405-06-13 | P17: 1405-07-01 | Q17: 46288 | R17: 46269 | S17: 19 | T17: نزدیک موعد
A18: 11 | B18: CW-MAN | C18: مردآب (Manway) ۵۰۰mm | D18: عدد | E18: 1 | F18: داخلی | G18: فولاد ساز اراک | H18: تومان | I18: 268000000 | J18: 1 | K18: 0 | L18: 12000000 | M18: 268000000 | N18: 280000000 | O18: 1405-06-15 | P18: 1405-07-18 | Q18: 46305 | R18: 46271 | S18: 34 | T18: در جریان
A19: 12 | B19: CW-NIP | C19: نازل خروج/ورود و شیرآف | D19: عدد | E19: 14 | F19: داخلی | G19: لوله‌سازان اصفهان | H19: تومان | I19: 21500000 | J19: 1 | K19: 0 | L19: 0 | M19: 21500000 | N19: 301000000 | O19: 1405-06-15 | P19: 1405-07-10 | Q19: 46297 | R19: 46271 | S19: 26 | T19: نزدیک موعد
... A23: 16 | B23: SV-CAL | C23: کالیبراسیون و تست هیدرواستاتیک | D23: دفعه | E23: 1 | F23: داخلی | G23: آزمایشگاه ثالث — ISI | H23: تومان | I23: 640000000 | J23: 1 | K23: 0 | L23: 0 | M23: 640000000 | N23: 640000000 | O23: 1405-06-22 | P23: 1405-09-20 | Q23: 46367 | R23: 46278 | S23: 89 | T23: در جریان
A24: 17 | K24: 0 | Q24: 0 | R24: 0 | T24: در انتظار قیمت
A25: 18 | K25: 0 | Q25: 0 | R25: 0 | T25: در انتظار قیمت
A26: 19 | K26: 0 | Q26: 0 | R26: 0 | T26: در انتظار قیمت
A27: 20 | K27: 0 | Q27: 0 | R27: 0 | T27: در انتظار قیمت
A28: 21 | K28: 0 | Q28: 0 | R28: 0 | T28: در انتظار قیمت
A29: 22 | K29: 0 | Q29: 0 | R29: 0 | T29: در انتظار قیمت
A30: 23 | K30: 0 | Q30: 0 | R30: 0 | T30: در انتظار قیمت
A31: 24 | K31: 0 | Q31: 0 | R31: 0 | T31: در انتظار قیمت
C32: جمع کل اقلام قیمت‌گذاری‌شده (تومان) | N32: 9.462865e+09 | O32: میلیون تومان → | P32: 9462.9
B34: نرخ ارز مورد استفاده (از تنظیمات — ویرایش در تنظیمات): | D34: دلار: | E34: 120000 | F34: یورو: | G34: 132000
B35: مستندسازی: حداقل دو پیش‌فاکتور معتبر برای هر قلام (بالای ۵۰۰ م.ت.) الزامی است — فایل‌ها در مسیر شبکه پروژه.

Sheet برنامه‌ریزی
A1: برنامه‌ریزی تولید و انبارها — نیازسنجی و زمان‌بندی تأمین
A2: نیاز کل = مقدار نهایی BOM × تعداد سفارش. نیاز خالص پس از کسر موجودی و در‌راه محاسبه می‌شود؛ تاریخ درخواست از «نیاز − Lead تأمین‌کننده» به‌صورت خودکار (شمسی) استخراج می‌گردد.
A4: تعداد سفارش تولید | B4: 1
A6: کد فنی | B6: شرح (از BOM) | C6: نیاز کل | D6: موجودی انبار | E6: در راه | F6: نیاز خالص | G6: ذخیره ایمنی | H6: تاریخ نیاز (شمسی) | I6: سریال نیاز | J6: Lead (روز) | K6: تاریخ درخواست خرید | L6: وضعیت تأمین | M6: یادداشت / سفارش
A8: RM-RES-ISO | B8: رزین ایزوفتالیک | C8: 5460 | D8: 3400 | E8: 1900 | F8: 160 | G8: 300 | H8: 1405-07-20 | I8: 46307 | J8: 23 | K8: 1405/06/28 | L8: در راه | M8: PO-1405-071 تأیید شد
A9: RM-GF-MAT | B9: فایبرگلاس MAT ۴۵۰ | C9: 2268 | D9: 1700 | E9: 650 | F9: 0 | G9: 250 | H9: 1405-07-25 | I9: 46312 | J9: 30 | K9: 1405/06/26 | L9: تامین‌شده | M9: رسید تا ۷/۵
A10: RM-GF-ROV | B10: رووینگ ۲۴۰۰tex | C10: 1749 | D10: 1300 | E10: 900 | F10: 0 | G10: 200 | H10: 1405-07-25 | I10: 46312 | J10: 30 | K10: 1405/06/26 | L10: تامین‌شده
A11: RM-CH-PER | B11: کاتالیزور MEKP | C11: 97.9 | D11: 78 | E11: 40 | F11: 0 | G11: 12 | H11: 1405-07-12 | I11: 46299 | J11: 12 | K11: 1405/06/31 | L11: تامین‌شده | M11: مصرف فاز تولید
A12: RM-CH-ACC | B12: شتاب‌دهنده کبالت | C12: 28.6 | F12: 28.6 | I12: 0 | J12: 12 | K12: — | L12: درخواست خرید
A13: RM-GEL | B13: ژل‌کوت اورتالیک | C13: 360.4 | F13: 360.4 | I13: 0 | J13: 50 | K13: — | L13: درخواست خرید
A14: EQ-PUMP | B14: پمپ تزریق رزیون | C14: 1 | D14: 1 | E14: 0 | F14: 0 | G14: 0 | H14: 1405-07-30 | I14: 46317 | J14: 53 | K14: 1405/06/08 | L14: تامین‌شده | M14: وابسته به تخصیص ارز
A15: EQ-MIX | B15: میکسر صنعتی ۷۵۰ لیتری | C15: 1 | F15: 1 | I15: 0 | J15: 41 | K15: — | L15: درخواست خرید
A16: CW-FLG-16 | B16: فلنج کربن استیل DN150 | C16: 6 | F16: 6 | I16: 0 | J16: 19 | K16: — | L16: درخواست خرید
A17: CW-FLG-24 | B17: فلنج کربن استیل DN200 | C17: 2 | F17: 2 | I17: 0 | J17: 19 | K17: — | L17: درخواست خرید
A18: CW-MAN | B18: مردآب (Manway) ۵۰۰mm | C18: 1 | D18: 1 | E18: 0 | F18: 0 | G18: 0 | H18: 1405-08-15 | I18: 46332 | J18: 34 | K18: 1405/07/11 | L18: تامین‌شده
A19: CW-NIP | B19: نازل خروج/ورود و شیرآف | C19: 14 | F19: 14 | I19: 0 | J19: 26 | K19: — | L19: درخواست خرید
A20: CW-SEN | B20: سنسور سطح و دما | C20: 4 | D20: 4 | E20: 1 | F20: 0 | G20: 0 | H20: 1405-09-01 | I20: 46348 | J20: 59 | K20: 1405/07/02 | L20: تامین‌شده | M20: کارگزار اعلام ۱۱ هفته
A21: AW-PNT | B21: پرایمر و پوشش نهایی UV | C21: 126 | F21: 126 | I21: 0 | J21: 15 | K21: — | L21: درخواست خرید
A22: PK-PKG | B22: بسته‌بندی و مهاربندی حمل | C22: 1 | F22: 1 | I22: 0 | J22: 46 | K22: — | L22: درخواست خرید
A23: SV-CAL | B23: کالیبراسیون و تست هیدرواستاتیک | C23: 1 | F23: 1 | I23: 0 | J23: 89 | K23: — | L23: درخواست خرید
G24: 0 | I24: 0 | K24: —
G25: 0 | I25: 0 | K25: —
G26: 0 | I26: 0 | K26: —
G27: 0 | I27: 0 | K27: —
G28: 0 | I28: 0 | K28: —
G29: 0 | I29: 0 | K29: —
G30: 0 | I30: 0 | K30: —
G31: 0 | I31: 0 | K31: —
B32: جمع اقلام نیازمند سفارش | F32: 540 | L32: 0 بحرانی

Sheet مالی
A1: مالی — بهای تمام‌شده و بودجه پروژه
A2: مواد از جمع برگه بازرگانی و نیروی کار از جمع نفرساعت مهندسی به‌صورت خودکار کشیده می‌شود. واحد: میلیون تومان.
A4: الف) تشکیل بهای تمام‌شده (م.ت.)
A5: مواد و تجهییزات خریداری‌شده (BOM) | C5: ='بازرگانی'!$P$32 | F5: نمایش کلی
A6: نیروی کار مستقیم (نفرساعت مهندسی/تولید) | C6: ='مهندسی_BOM'!$G$43
A7: سربار + اداری + ذخیره ریسک (٪) | C7: 26
A8: جمع بهای تمام‌شده پروژه (م.ت.) | C8: =ROUND((C5+C6)*(1+C7/100),1)
A11: ب) بودجه فازبندی‌شده و مصرف واقعی
A12: فاز | B12: بودجه مصوب (م.ت.) | C12: هزینه واقعی | D12: انحراف | E12: ٪ مصرف
A13: ثبت و امکان‌سنجی | B13: 180 | C13: =IFERROR(SUMIFS('هزینه‌واقعی'!$H:$H,'هزینه‌واقعی'!$C:$C,$A13),0) | D13: =ROUND($C13-$B13,1) | E13: =IF($B13=0,0,$C13/$B13)
A14: مهندسی | B14: 950 | C14: =IFERROR(SUMIFS('هزینه‌واقعی'!$H:$H,'هزینه‌واقعی'!$C:$C,$A14),0) | D14: =ROUND($C14-$B14,1) | E14: =IF($B14=0,0,$C14/$B14)
A15: تأمین | B15: 8600 | C15: =IFERROR(SUMIFS('هزینه‌واقعی'!$H:$H,'هزینه‌واقعی'!$C:$C,$A15),0) | D15: =ROUND($C15-$B15,1) | E15: =IF($B15=0,0,$C15/$B15)
A16: تولید | B16: 2350 | C16: =IFERROR(SUMIFS('هزینه‌واقعی'!$H:$H,'هزینه‌واقعی'!$C:$C,$A16),0) | D16: =ROUND($C16-$B16,1) | E16: =IF($B16=0,0,$C16/$B16)
A17: کیفیت و تست | B17: 320 | C17: =IFERROR(SUMIFS('هزینه‌واقعی'!$H:$H,'هزینه‌واقعی'!$C:$C,$A17),0) | D17: =ROUND($C17-$B17,1) | E17: =IF($B17=0,0,$C17/$B17)
A18: تحویل و پس از فروش | B18: 480 | C18: =IFERROR(SUMIFS('هزینه‌واقعی'!$H:$H,'هزینه‌واقعی'!$C:$C,$A18),0) | D18: =ROUND($C18-$B18,1) | E18: =IF($B18=0,0,$C18/$B18)
A19: جمع | B19: =SUM(B13:B18) | C19: =SUM(C13:C18) | D19: =ROUND(C19-B19,1) | E19: =IF(B19=0,0,C19/B19)
A21: ج) ملاحظات مالی
A22: مستندات پیوست (پیش‌فاکتورها، اسناد گمرکی، ریز دستمزد) در مسیر شبکه پروژه بایگانی شود. انحراف بیش از ۱۰٪ هر فاز، بازنگری الزامی گانت و امکان‌سنجی را در پی دارد (خط‌مشی گیت‌ها).

Sheet فروش
A1: فروش — قیمت نهایی و شرایط پرداخت
A2: مبانی: بهای تمام‌شده از مالی؛ برآورد اولیه از شناسنامه. قیمت‌ها میلیون تومان.
A5: بهای تمام‌شده (از مالی) | B5: 12549.3
A6: حاشیه سود هدف (٪) | B6: 18
A7: قیمت فروش قبل از مالیات | B7: 14808.2
A8: مالیات بر ارزش افزوده (٪) | B8: 10
A9: تخفیف ویژه (٪) | B9: 2
A10: قیمت مشتری (برآورد شناسنامه) | B10: 14800
A11: قیمت نهایی فروش با مالیات (م.ت.) | B11: 15963.2
A12: قیمت نهایی بدون مالیات (م.ت.) | B12: 14512
A13: حاشیه نسبت به برآورد مشتری | B13: ✓ در محدوده برآورد
A15: شرایط پرداخت
A16: مرحله پرداخت | B16: درصد | C16: مبلغ (م.ت.) | D16: تاریخ سررسید (شمسی) | E16: وضعیت | F16: رسید/چک | G16: توضیح
A17: پیش‌پرداخت قرارداد | B17: 40 | C17: 6385.3 | D17: 1405-07-08 | E17: نرسیده
A18: تحویل ۵۰٪ اقلام تأمین | B18: 25 | C18: 3990.8 | D18: 1405-08-25 | E18: نرسیده
A19: تحویل کالا در محل کارفرما | B19: 30 | C19: 4789 | D19: 1405-11-10 | E19: نرسیده
A20: ضمانت‌نامه حسن انجام کار (۱۸ ماه) | B20: 5 | C20: 798.2 | D20: 1406-05-01 | E20: نرسیده
A21: جمع درصدها | B21: ✓

Sheet جمع‌بندی
A1: جمع‌بندی مدیر پروژه — بسته گزارش به مدیریت ارشد
A2: شاخص‌های کلیدی خودکارند؛ یادداشت و جمع‌بندی مدیر پروژه وارد می‌شود. پس از تکمیل، برگه «تصویب» برای نظر مدیریت ارشد باز است.
A5: شاخص کلیدی | B5: مقدار | C5: وضعیت | D5: منبع
A6: امتیاز امکان‌سنجی (از ۱۰۰) | B6: 78 | C6: ✓ | D6: برگه امکان‌سنجی
A7: پیشرفت واقعی زمان | B7: 0.29638889 | C7: — | D7: گانت
A8: اختلاف با برنامه (پیشرفت) | B8: 0.0080565476 | C8: ✓ مطابق برنامه | D8: گانت
A9: مصرف بودجه | B9: 0.22299689 | C9: ✓ | D9: مالی
A10: ریسک‌های بحرانی باز | B10: 2 | C10: — | D10: ریسک
A11: قیمت نهایی فروش (م.ت.) | B11: 14512 | C11: — | D11: فروش
A13: جمع‌بندی مدیر پروژه
A14: وضعیت زمانی ۶٪ عقب از برنامه است که عمدتاً از تأخیر L/C تجهیزات خارجی (F2.2) ناشی می‌شود؛ جبران با موازی‌سازی عملیات قالب‌سازی و لایه‌نشانی پیش‌بینی شد. هزینه تأمین در سقف بودجه است؛ پیشنهاد: پیش‌پرداخت رزین به تأمین‌کننده مورد تأیید برای قفل قیمت. پرونده برای تصویب نهایی به مدیریت ارشد ارسال می‌شود.
A17: تاریخ ارسال به مدیریت ارشد | B17: 1405/07/01

Sheet تصویب
A1: تصمیم مدیریت ارشد (Stage-Gate)
A2: مدیریت ارشد پس بررسی بسته جمع‌بندی، یکی از وضعیت‌های «مصوب / مصوب مشروط / نیازمند اصلاح / رد شده» را ثبت می‌کند. نتیجه خودکار در شناسنامه و داشبورد منعکس می‌شود.
A5: کد پروژه | B5: BC-P-1405-01
A6: امتیاز امکان‌سنجی | B6: 78
A7: پیشرفت واقعی | B7: 0.29638889
A8: بهای تمام‌شده (م.ت.) | B8: 12549.3
A9: قیمت فروش پیشنهادی (م.ت.) | B9: 14512
A10: جمع‌بندی مدیر پروژه | B10: وضعیت زمانی ۶٪ عقب از برنامه است که عمدتاً از تأخیر L/C تجهیزات خارجی (F2.2) ناشی می‌شود؛ جبران با موازی‌سازی عملیات قالب‌سازی و لایه‌نشانی پیش‌بینی شد. هزینه تأمین در سقف بودجه است؛ پیشنهاد: پیش‌پرداخت رزین به تأمین‌کننده مورد تأیید برای قفل قیمت. پرونده برای تصویب نهایی به مدیریت ارشد ارسال می‌شود.
A12: تصمیم مدیریت ارشد | B12: مصوب مشروط
A13: تاریخ تصمیم (شمسی) | B13: 1405/07/01
A14: نظر/شرط مدیریت | B14: مصوب مشروط: با شرط تهاتر ۵٪ تخیفیف در ازای کاهش دوره گارانتی به ۱۲ ماه و تکمیل بازنگری ریسک R-02 تا پایان مهر.
A15: امضای مدیرعامل

Sheet هزینه‌واقعی
A1: هزینه‌های واقعی پروژه (Turn-over / Actual Cost Ledger)
A2: ثبت بهای واقعی هر فاز به تفکیک واحد — مبنای محاسبه CPI و انحراف بودجه. واحد: میلیون تومان.
A6: ردیف | B6: تاریخ (شمسی) | C6: فاز | D6: شرح هزینه / سند | E6: مستند حسابداری | F6: واحد ثبت‌کننده | G6: کارشناس | H6: مبلغ (م.ت.) | I6: وضعیت پرداخت | J6: محل بایگانی
A8: 1 | B8: 1405-04-05 | C8: ثبت و امکان‌سنجی | D8: برآورد اولیه و جلسه کمیته | E8: PP-1405/221 | F8: مدیر پروژه | G8: — | H8: 12.5 | I8: پرداخت‌شده | J8: \\BORNASRV\Projects\...\Finance
A9: 2 | B9: 1405-05-21 | C9: مهندسی | D9: ساعت طراحی نقشه‌ها و محاسبات | E9: PP-1405/244 | F9: مهندسی | G9: — | H9: 86.4 | I9: پرداخت‌شده | J9: \\BORNASRV\Projects\...\Finance
A10: 3 | B10: 1405-06-05 | C10: تأمین | D10: رزین ایزوفتالیک (۵۰٪) | E10: INV-1405/118 | F10: بازرگانی داخلی | G10: — | H10: 612 | I10: پرداخت‌شده | J10: \\BORNASRV\Projects\...\Finance
A11: 4 | B11: 1405-06-10 | C11: تأمین | D11: الیاف MAT/ROV | E11: INV-1405/122 | F11: بازرگانی داخلی | G11: — | H11: 441 | I11: پرداخت‌شده | J11: \\BORNASRV\Projects\...\Finance
A12: 5 | B12: 1405-06-18 | C12: تأمین | D12: پیش‌پرداخت ژل‌کوت وارداتی | E12: TTR-1405/19 | F12: بازرگانی خارجی | G12: — | H12: 96.8 | I12: پرداخت‌شده | J12: \\BORNASRV\Projects\...\Finance
A13: 6 | B13: 1405-06-25 | C13: تأمین | D13: ارزیابی تأمین‌کننده و نمونه | E13: PP-1405/260 | F13: بازرگانی داخلی | G13: — | H13: 18.2 | I13: پرداخت‌شده | J13: \\BORNASRV\Projects\...\Finance
A14: 7 | B14: 1405-07-01 | C14: مهندسی | D14: طراحی قالب — ویرایش B | E14: PP-1405/271 | F14: مهندسی | G14: — | H14: 54.1 | I14: پرداخت‌شده | J14: \\BORNASRV\Projects\...\Finance
A15: 8 | B15: 1405-07-10 | C15: تأمین | D15: نازل و فلنج‌ها | E15: INV-1405/131 | F15: بازرگانی داخلی | G15: — | H15: 108.4 | I15: پرداخت‌شده | J15: \\BORNASRV\Projects\...\Finance
A16: 9 | B16: 1405-07-18 | C16: تولید | D16: دستمزد آماده‌سازی خط | E16: PR-1405/77 | F16: برنامه‌ریزی و انبار | G16: — | H16: 62.3 | I16: پرداخت‌شده | J16: \\BORNASRV\Projects\...\Finance
A17: 10 | B17: 1405-07-25 | C17: تأمین | D17: پمپ رزیون (۵۰٪ اول) | E17: TTR-1405/24 | F17: بازرگانی خارجی | G17: — | H17: 1380.5 | I17: پرداخت‌شده | J17: \\BORNASRV\Projects\...\Finance
C30: جمع هزینه واقعی | H30: =ROUND(SUM(H8:H29),1)

Sheet ریسک
A1: ثبت ریسک پروژه
A2: امتیاز = احتمال × اثر (هرکدام ۱ تا ۵). سطح‌بندی خودکار و رنگ‌آمیزی شرطی. بازبینی حداقل ماهانه توسط مدیر پروژه — مرجع: PMI PMBOK 7 و ISO 31000.
A6: کد | B6: شرح ریسک | C6: دسته | D6: احتمال | E6: اثر | F6: امتیاز | G6: سطح | H6: راهبرد | I6: اقدام کاهش / پاسخ | J6: مسئول | K6: وضعیت | L6: آخرین بازبینی | M6: بازبینی بعد
A8: R-01 | B8: نوسان قیمت رزین و الیاف در بازار داخلی | C8: تأمین | D8: 4 | E8: 4 | F8: 16 | G8: بحرانی | H8: کاهش | I8: قفل قیمت با خرید فوری و قرارداد دوجانبه | J8: بازرگانی داخلی | K8: باز | L8: 1405/06/28 | M8: 1405/07/28
A9: R-02 | B9: تأخیر تخصیص ارز/گشایش اعتبارات اسنادی | C9: تأمین | D9: 4 | E9: 5 | F9: 20 | G9: بحرانی | H9: کاهش | I9: استعلام از کارگزار، جایگزین داخلی پمپ، بازنگری گانت | J9: بازرگانی خارجی | K9: باز | L9: 1405/06/28 | M9: 1405/07/28
A10: R-03 | B10: کیفیت قالب اسپیل (انحراف ابعادی) | C10: فنی | D10: 3 | E10: 4 | F10: 12 | G10: بالا | H10: کاهش | I10: کنترل سه‌بعدی قبل از لایه‌نشانی، Tolerance review | J10: مهندسی | K10: باز | L10: 1405/06/28 | M10: 1405/07/28
A11: R-04 | B11: تعارض برنامه خط تولید با پروژه | C11: سازمانی | D11: 3 | E11: 3 | F11: 9 | G11: بالا | H11: پذیرش | I11: برنامه‌ریزی بار خط، شیفت اضافه | J11: برنامه‌ریزی و انبار | K11: باز | L11: 1405/06/28 | M11: 1405/07/28
A12: R-05 | B12: حوادث HSE کار با رزین/کار در ارتفاع | C12: ایمنی | D12: 2 | E12: 5 | F12: 10 | G12: بالا | H12: اجتناب | I12: مجوز کار، PPE، آموزش اجباری، بیمه مسئولیت | J12: مدیر پروژه | K12: باز | L12: 1405/06/28 | M12: 1405/07/28
A13: R-06 | B13: ادعای وجه التزام تاخیر توسط کارفرما | C13: قرارداد | D13: 3 | E13: 4 | F13: 12 | G13: بالا | H13: کاهش | I13: صورت‌جلسه مکتوب تعلیقات، مستندسازی علل تأخیر در گانت | J13: مدیر پروژه | K13: باز | L13: 1405/06/28 | M13: 1405/07/28
A14: R-07 | B14: افزایش نرخ ارز و هزینه حمل بین‌المللی | C14: مالی | D14: 3 | E14: 3 | F14: 9 | G14: بالا | H14: انتقال | I14: بیمه باربری + قرارداد CIF + ذخیره ۵٪ | J14: مالی | K14: باز | L14: 1405/06/28 | M14: 1405/07/28
A15: R-08 | B15: مستندسازی ناکافی مدارک تحویلی | C15: کیفیت | D15: 2 | E15: 3 | F15: 6 | G15: متوسط | H15: کاهش | I15: چک‌لیست تحویل مدارک، ممیزی داخلی قبل از گیت ۳ | J15: مهندسی | K15: باز | L15: 1405/06/28 | M15: 1405/07/28

Sheet تغییرات
A1: ثبت و کنترل تغییرات پروژه (CR)
A2: هر تغییر دامنه/زمان/هزینه در این جدول ثبت می‌شود. تغییرات تأییدشده: به‌روزرسانی گانت، BOM و بودجه الزامی است.
A6: کد CR | B6: تاریخ | C6: واحد متقاضی | D6: شرح تغییر | E6: اثر زمان (روز) | F6: اثر هزینه (م.ت.) | G6: بررسی مدیر پروژه | H6: وضعیت | I6: تأیید مدیریت | J6: بایگانی
A8: CR-01 | B8: 1405/05/25 | C8: مهندسی | D8: افزایش ضخامت لایه‌ها در ناحیه نازل‌ها (+۱.۲mm) | E8: 2 | F8: 128.5 | G8: توجیه فنی دارد — اثر زمان قابل جذب | H8: تأییدشده | I8: — | J8: —
A9: CR-02 | B9: 1405/06/12 | C9: کارفرما | D9: تغییر محل خروجی از کف به دیواره | E9: 6 | F9: 214 | G9: نیازمند بازنگری نقشه و تست — در گیت بعدی | H9: درخواست جدید | I9: — | J9: —
A10: CR-03 | B10: 1405/06/29 | C10: بازرگانی خارجی | D10: جایگزینی پمپ با برند معادل هندی | E10: 0 | F10: -385 | G10: صرفه‌جویی؛ تایید فنی اخذ شد | H10: تأییدشده | I10: — | J10: —

Sheet تقویم
A1: تقویم شمسی
A2: جدول تبدیل تاریخ — مبنای سنجش فرم‌ها. بازه: 1403/01/01 تا 1408/12/30 | ستون B کلید ورودی همه فرم‌هاست؛ فقط تاریخ‌های موجود در این جدول معتبرند.
A7: سریال میلادی | B7: تاریخ شمسی | C7: سال | D7: ماه | E7: روز | F7: روز هفته | G7: جمعه | H7: تعطیل رسمی | I7: روز کاری | J7: ماه شمسی (متن)
A8: 45371 | B8: 1403/01/01 | C8: 1403 | D8: 1 | E8: 1 | F8: چهارشنبه | G8: 0 | H8: 1 | I8: 0 | J8: 01/1403
A9: 45372 | B9: 1403/01/02 | C9: 1403 | D9: 1 | E9: 2 | F9: پنجشنبه | G9: 0 | H9: 1 | I9: 0 | J9: 01/1403
A10: 45373 | B10: 1403/01/03 | C10: 1403 | D10: 1 | E10: 3 | F10: جمعه | G10: 1 | H10: 1 | I10: 0 | J10: 01/1403
A11: 45374 | B11: 1403/01/04 | C11: 1403 | D11: 1 | E11: 4 | F11: شنبه | G11: 0 | H11: 1 | I11: 0 | J11: 01/1403
A12: 45375 | B12: 1403/01/05 | C12: 1403 | D12: 1 | E12: 5 | F12: یکشنبه | G12: 0 | H12: 0 | I12: 1 | J12: 01/1403
A13: 45376 | B13: 1403/01/06 | C13: 1403 | D13: 1 | E13: 6 | F13: دوشنبه | G13: 0 | H13: 1 | I13: 0 | J13: 01/1403
A14: 45377 | B14: 1403/01/07 | C14: 1403 | D14: 1 | E14: 7 | F14: سه‌شنبه | G14: 0 | H14: 0 | I14: 1 | J14: 01/1403
A15: 45378 | B15: 1403/01/08 | C15: 1403 | D15: 1 | E15: 8 | F15: چهارشنبه | G15: 0 | H15: 0 | I15: 1 | J15: 01/1403
A16: 45379 | B16: 1403/01/09 | C16: 1403 | D16: 1 | E16: 9 | F16: پنجشنبه | G16: 0 | H16: 0 | I16: 1 | J16: 01/1403
A17: 45380 | B17: 1403/01/10 | C17: 1403 | D17: 1 | E17: 10 | F17: جمعه | G17: 1 | H17: 0 | I17: 0 | J17: 01/1403
A18: 45381 | B18: 1403/01/11 | C18: 1403 | D18: 1 | E18: 11 | F18: شنبه | G18: 0 | H18: 0 | I18: 1 | J18: 01/1403
A19: 45382 | B19: 1403/01/12 | C19: 1403 | D19: 1 | E19: 12 | F19: یکشنبه | G19: 0 | H19: 0 | I19: 1 | J19: 01/1403
... A2199: 47562 | B2199: 1408/12/30 | C2199: 1408 | D2199: 12 | E2199: 30 | F2199: چهارشنبه | G2199: 0 | H2199: 0 | I2199: 1 | J2199: 12/1408

Sheet تنظیمات
A1: تنظیمات سامانه
A2: پارامترهای عمومی، کاربران، ماتریس دسترسی و تعطیلات — ویرایش این برگه فقط با رمز ساختار فایل ممکن است. پس از دریافت فایل، حتماً رمز عبور همه کاربران را تغییر دهید.
A4: پارامترهای عمومی
A5: واحد پول گزارش‌ها | B5: میلیون تومان
A6: نرخ تبدیل دلار (تومان) | B6: 120000
A7: نرخ تبدیل یورو (تومان) | B7: 132000
A8: حد نصاب امتیاز امکان‌سنجی (از ۱۰۰) | B8: 70
A9: قالب ورود تاریخ در کل فایل | B9: شمسی به صورت 1405/07/12 (فارسی یا لاتین)
A10: کد کشور / تقویم مرجع | B10: IR — تقویم هجری شمسی (الگوریتم جلالی)
A12: کاربران و رمز عبور (ورود به سامانه)
A24: ⚠ این رمزها نمونه‌اند؛ هنگام استقرار، توسط مدیر IT تغییر یابند. امنیت اکسل بازدارنده است، نه رمزنگاری داده — برای حفاظت سخت، ماتریس NTFS فایل‌ها را (اسناد docs) اعمال کنید.
A25: ماتریس دسترسی برگه‌ها (W=ویرایش، R=نمایش، -=مخفی) — توسط ماکرو اعمال می‌شود
A26: برگه | B26: واحد ثبت سفارش | C26: مدیر پروژه | D26: مهندسی | E26: بازرگانی داخلی | F26: بازرگانی خارجی | G26: برنامه‌ریزی و انبار | H26: مالی | I26: فروش | J26: مدیریت ارشد | K26: مدیر سیستم
A27: راهنما | B27: R | C27: R | D27: R | E27: R | F27: R | G27: R | H27: R | I27: R | J27: R | K27: R
A28: ورود | B28: R | C28: R | D28: R | E28: R | F28: R | G28: R | H28: R | I28: R | J28: R | K28: R
A29: شناسنامه | B29: W | C29: R | D29: R | E29: - | F29: - | G29: - | H29: R | I29: R | J29: R | K29: R
A30: امکان‌سنجی | B30: R | C30: W | D30: R | E30: R | F30: R | G30: - | H30: R | I30: R | J30: R | K30: R
A31: گانت | B31: R | C31: W | D31: R | E31: R | F31: R | G31: R | H31: R | I31: R | J31: R | K31: R
A32: داشبورد | B32: R | C32: R | D32: R | E32: R | F32: R | G32: R | H32: R | I32: R | J32: R | K32: R
A33: مهندسی_BOM | B33: - | C33: R | D33: W | E33: R | F33: R | G33: R | H33: R | I33: - | J33: R | K33: R
A34: مهندسی_مدارک | B34: - | C34: R | D34: W | E34: - | F34: - | G34: R | H34: - | I34: - | J34: - | K34: R
A35: بازرگانی | B35: - | C35: R | D35: R | E35: W | F35: W | G35: R | H35: R | I35: - | J35: R | K35: R
A36: برنامه‌ریزی | B36: - | C36: R | D36: - | E36: R | F36: R | G36: W | H36: R | I36: - | J36: R | K36: R
A37: مالی | B37: - | C37: R | D37: - | E37: - | F37: - | G37: - | H37: W | I37: R | J37: R | K37: R
... A45: تنظیمات | B45: - | C45: R | D45: - | E45: - | F45: - | G45: - | H45: - | I45: - | J45: R | K45: W
A46: تعطیلات رسمی (مبنای روزهای کاری و گانت)
A47: تاریخ شمسی (ورودی) | B47: عنوان تعطیلی | C47: نرمال‌سازی‌شده | D47: سریال میلادی (خودکار)
A48: 1403/01/01 | B48: جشن نوروز | C48: 1403/01/01 | D48: 45371
A49: 1403/01/02 | B49: جشن نوروز | C49: 1403/01/02 | D49: 45372
A50: 1403/01/03 | B50: جشن نوروز | C50: 1403/01/03 | D50: 45373
A51: 1403/01/04 | B51: جشن نوروز | C51: 1403/01/04 | D51: 45374
A52: 1403/01/06 | B52: روز طبیعی / سیزده‌به‌در | C52: 1403/01/06 | D52: 45376
A53: 1403/03/14 | B53: رحلت امام خمینی (ره) | C53: 1403/03/14 | D53: 45446
A54: 1403/03/15 | B54: قیام ۱۵ خرداد | C54: 1403/03/15 | D54: 45447
A55: 1403/06/20 | B55: اربعین حسینی | C55: 1403/06/20 | D55: 45545
A56: 1403/11/22 | B56: پیروزی انقلاب اسلامی | C56: 1403/11/22 | D56: 45698
A57: 1403/12/11 | B57: شهادت امام علی (ع) | C57: 1403/12/11 | D57: 45717
A58: 1403/12/12 | B58: عید فطر | C58: 1403/12/12 | D58: 45718
A59: 1404/01/01 | B59: جشن نوروز | C59: 1404/01/01 | D59: 45737
... A78: 1405/11/22 | B78: پیروزی انقلاب اسلامی | C78: 1405/11/22 | D78: 46429
...
