Workbook

Sheet Dashboard
A1: Dashboard — داشبورد مدیریت فرآیند «سفارش تا تصویب» (KPI + ماتریس گردش کار + گیت‌ها) | Z1: CHART1_ROWS=38:46
A3: پروژه‌های فعال | B3: =COUNTIF(Projects!$K$3:$K$4,"Approved")
A4: سفارش‌های جدید | B4: =COUNTA(Orders!$A$3:$A$5)
A5: در انتظار بررسی فروش | B5: =COUNTIF(Orders!$M$3:$M$5,"Draft")
A6: پروژه‌های تأخیرخورده | B6: =SUM(Projects!$N$3:$N$4)
A7: امکان‌سنجی‌های کامل | B7: =COUNTIF(Feasibility!$M$3:$M$20,"COMPLETE")
A8: امکان‌سنجی‌های ناقص (قفل مهندسی) | B8: =COUNTIF(Feasibility!$M$3:$M$20,"INCOMPLETE")
A9: تجهیزات قیمت‌دهی‌شده | B9: =COUNTIF(Project_Equipment!$N$3:$N$20,"PRICED")
A10: تجهیزات در انتظار قیمت‌دهی | B10: =COUNTIF(Project_Equipment!$N$3:$N$20,"PENDING")
A11: اقلام دریافت‌شده در انبار (تعداد) | B11: =SUM(Receipts!$F$3:$F$20)
A12: BOMهای در انتظار تأیید | B12: =COUNTIF(BOM_Header!$I$3:$I$5,"Waiting Approval")
A13: قیمت‌های منقضی | B13: =COUNTIF(Purchase_Prices!$R$3:$R$10,1)
A14: پیشنهاد در انتظار مدیریت | B14: =COUNTIF(Sales_Quotation!$O$3:$O$5,"Submitted")
A15: تصمیم تأیید (مطلق) | B15: =COUNTIF(Management_Approval!$D$3:$D$10,"APPROVED")
A16: تصمیم تأیید مشروط | B16: =COUNTIF(Management_Approval!$D$3:$D$10,"APPROVED WITH CONDITION")
A17: تصمیم برگشت برای اصلاح | B17: =COUNTIF(Management_Approval!$D$3:$D$10,"RETURN FOR REVISION")
A18: تصمیم رد | B18: =COUNTIF(Management_Approval!$D$3:$D$10,"REJECTED")
A19: Total Sales Value (پیشنهاد جاری) | B19: =Quotation_Versions!$G$3
A20: Total Cost | B20: =SUM(Costing!$Q$3:$Q$3)
A21: اختلاف بودجه و هزینه واقعی | B21: =Budget!$S$3
A23: Funnel (تعداد)
A24: Leads / سفارش‌ها | B24: =COUNTA(Orders!$A$3:$A$5)
A25: Orders → READY | B25: =COUNTIF(Orders!$R$3:$R$5,"READY")
A26: امکان‌سنجی کامل | B26: =COUNTIF(Feasibility!$M$3:$M$20,"COMPLETE")
A27: مهندسی تأییدشده | B27: =COUNTIF(Engineering!$H$3:$H$4,"Approved")
A28: Costing تأییدشده | B28: =COUNTIF(Costing!$D$3:$D$3,"Approved")
A29: پیشنهاد Submitted | B29: =COUNTIF(Sales_Quotation!$O$3:$O$5,"Submitted")
A30: تصمیم مدیریت (کل) | B30: =COUNTA(Management_Approval!$D$3:$D$10)
A32: ماتریس گردش کار پروژه‌ها — ✅ تکمیل / 🔵 در جریان / 🔒 قفل (گیت بسته)
A33: پروژه | B33: بررسی سفارش (فروش) | C33: امکان‌سنجی (مدیر پروژه) | D33: مهندسی (اقلام/تجهیزات/زمان‌سنجی) | E33: بازرگانی (قیمت‌دهی اقلام) | F33: برنامه‌ریزی تولید و انبارها | G33: مالی (قیمت تمام‌شده و بودجه) | H33: قیمت‌گذاری فروش و نحوه پرداخت | I33: جمع‌بندی مدیریت پروژه | J33: تصمیم مدیریت ارشد | K33: مراحل تکمیل‌شده | L33: درصد پیشروی
A34: PRJ-2026-00125 | B34: =IFERROR(IF(INDEX(Gate_Status!$D$3:$D$20,MATCH($A34,Gate_Status!$B$3:$B$20,0))=1,"✅ تکمیل","🔵 در جریان"),"—") | C34: =IFERROR(IF(INDEX(Gate_Status!$E$3:$E$20,MATCH($A34,Gate_Status!$B$3:$B$20,0))=1,"✅ تکمیل",IF(INDEX(Gate_Status!$N$3:$N$20,MATCH($A34,Gate_Status!$B$3:$B$20,0))=1,"🔵 در جریان","🔒 قفل")),"—") | D34: =IFERROR(IF(INDEX(Gate_Status!$F$3:$F$20,MATCH($A34,Gate_Status!$B$3:$B$20,0))=1,"✅ تکمیل",IF(INDEX(Gate_Status!$O$3:$O$20,MATCH($A34,Gate_Status!$B$3:$B$20,0))=1,"🔵 در جریان","🔒 قفل")),"—") | E34: =IFERROR(IF(INDEX(Gate_Status!$G$3:$G$20,MATCH($A34,Gate_Status!$B$3:$B$20,0))=1,"✅ تکمیل",IF(INDEX(Gate_Status!$P$3:$P$20,MATCH($A34,Gate_Status!$B$3:$B$20,0))=1,"🔵 در جریان","🔒 قفل")),"—") | F34: =IFERROR(IF(INDEX(Gate_Status!$H$3:$H$20,MATCH($A34,Gate_Status!$B$3:$B$20,0))=1,"✅ تکمیل",IF(INDEX(Gate_Status!$Q$3:$Q$20,MATCH($A34,Gate_Status!$B$3:$B$20,0))=1,"🔵 در جریان","🔒 قفل")),"—") | G34: =IFERROR(IF(INDEX(Gate_Status!$I$3:$I$20,MATCH($A34,Gate_Status!$B$3:$B$20,0))=1,"✅ تکمیل",IF(INDEX(Gate_Status!$R$3:$R$20,MATCH($A34,Gate_Status!$B$3:$B$20,0))=1,"🔵 در جریان","🔒 قفل")),"—") | H34: =IFERROR(IF(INDEX(Gate_Status!$J$3:$J$20,MATCH($A34,Gate_Status!$B$3:$B$20,0))=1,"✅ تکمیل",IF(INDEX(Gate_Status!$S$3:$S$20,MATCH($A34,Gate_Status!$B$3:$B$20,0))=1,"🔵 در جریان","🔒 قفل")),"—") | I34: =IFERROR(IF(INDEX(Gate_Status!$K$3:$K$20,MATCH($A34,Gate_Status!$B$3:$B$20,0))=1,"✅ تکمیل",IF(INDEX(Gate_Status!$T$3:$T$20,MATCH($A34,Gate_Status!$B$3:$B$20,0))=1,"🔵 در جریان","🔒 قفل")),"—") | J34: =IFERROR(IF(INDEX(Gate_Status!$L$3:$L$20,MATCH($A34,Gate_Status!$B$3:$B$20,0))=1,"✅ تکمیل",IF(INDEX(Gate_Status!$U$3:$U$20,MATCH($A34,Gate_Status!$B$3:$B$20,0))=1,"🔵 در جریان","🔒 قفل")),"—") | K34: =IFERROR(INDEX(Gate_Status!$V$3:$V$20,MATCH($A34,Gate_Status!$B$3:$B$20,0)),"") | L34: =IFERROR(ROUND(INDEX(Gate_Status!$W$3:$W$20,MATCH($A34,Gate_Status!$B$3:$B$20,0)),3),"")
A35: PRJ-2026-00126 | B35: =IFERROR(IF(INDEX(Gate_Status!$D$3:$D$20,MATCH($A35,Gate_Status!$B$3:$B$20,0))=1,"✅ تکمیل","🔵 در جریان"),"—") | C35: =IFERROR(IF(INDEX(Gate_Status!$E$3:$E$20,MATCH($A35,Gate_Status!$B$3:$B$20,0))=1,"✅ تکمیل",IF(INDEX(Gate_Status!$N$3:$N$20,MATCH($A35,Gate_Status!$B$3:$B$20,0))=1,"🔵 در جریان","🔒 قفل")),"—") | D35: =IFERROR(IF(INDEX(Gate_Status!$F$3:$F$20,MATCH($A35,Gate_Status!$B$3:$B$20,0))=1,"✅ تکمیل",IF(INDEX(Gate_Status!$O$3:$O$20,MATCH($A35,Gate_Status!$B$3:$B$20,0))=1,"🔵 در جریان","🔒 قفل")),"—") | E35: =IFERROR(IF(INDEX(Gate_Status!$G$3:$G$20,MATCH($A35,Gate_Status!$B$3:$B$20,0))=1,"✅ تکمیل",IF(INDEX(Gate_Status!$P$3:$P$20,MATCH($A35,Gate_Status!$B$3:$B$20,0))=1,"🔵 در جریان","🔒 قفل")),"—") | F35: =IFERROR(IF(INDEX(Gate_Status!$H$3:$H$20,MATCH($A35,Gate_Status!$B$3:$B$20,0))=1,"✅ تکمیل",IF(INDEX(Gate_Status!$Q$3:$Q$20,MATCH($A35,Gate_Status!$B$3:$B$20,0))=1,"🔵 در جریان","🔒 قفل")),"—") | G35: =IFERROR(IF(INDEX(Gate_Status!$I$3:$I$20,MATCH($A35,Gate_Status!$B$3:$B$20,0))=1,"✅ تکمیل",IF(INDEX(Gate_Status!$R$3:$R$20,MATCH($A35,Gate_Status!$B$3:$B$20,0))=1,"🔵 در جریان","🔒 قفل")),"—") | H35: =IFERROR(IF(INDEX(Gate_Status!$J$3:$J$20,MATCH($A35,Gate_Status!$B$3:$B$20,0))=1,"✅ تکمیل",IF(INDEX(Gate_Status!$S$3:$S$20,MATCH($A35,Gate_Status!$B$3:$B$20,0))=1,"🔵 در جریان","🔒 قفل")),"—") | I35: =IFERROR(IF(INDEX(Gate_Status!$K$3:$K$20,MATCH($A35,Gate_Status!$B$3:$B$20,0))=1,"✅ تکمیل",IF(INDEX(Gate_Status!$T$3:$T$20,MATCH($A35,Gate_Status!$B$3:$B$20,0))=1,"🔵 در جریان","🔒 قفل")),"—") | J35: =IFERROR(IF(INDEX(Gate_Status!$L$3:$L$20,MATCH($A35,Gate_Status!$B$3:$B$20,0))=1,"✅ تکمیل",IF(INDEX(Gate_Status!$U$3:$U$20,MATCH($A35,Gate_Status!$B$3:$B$20,0))=1,"🔵 در جریان","🔒 قفل")),"—") | K35: =IFERROR(INDEX(Gate_Status!$V$3:$V$20,MATCH($A35,Gate_Status!$B$3:$B$20,0)),"") | L35: =IFERROR(ROUND(INDEX(Gate_Status!$W$3:$W$20,MATCH($A35,Gate_Status!$B$3:$B$20,0)),3),"")
A37: داده نمودار — تعداد پروژه‌های تکمیل‌کننده هر مرحله
A38: بررسی سفارش (فروش) | B38: =SUM(Gate_Status!$D$3:$D$20)
A39: امکان‌سنجی (مدیر پروژه) | B39: =SUM(Gate_Status!$E$3:$E$20)
A40: مهندسی (اقلام/تجهیزات/زمان‌سنجی) | B40: =SUM(Gate_Status!$F$3:$F$20)
A41: بازرگانی (قیمت‌دهی اقلام) | B41: =SUM(Gate_Status!$G$3:$G$20)
A42: برنامه‌ریزی تولید و انبارها | B42: =SUM(Gate_Status!$H$3:$H$20)
A43: مالی (قیمت تمام‌شده و بودجه) | B43: =SUM(Gate_Status!$I$3:$I$20)
A44: قیمت‌گذاری فروش و نحوه پرداخت | B44: =SUM(Gate_Status!$J$3:$J$20)
...

Sheet Workflow
A1: Workflow — گردش کار ۹ مرحله‌ای «سفارش تا تصویب مدیریت ارشد» + گیت‌ها و مالکان
A2: № | B2: مرحله | C2: مالک (واحد) | D2: گیت ورود (پیش‌نیاز) | E2: شرط عبور به مرحله بعد
A3: ۱ | B3: دریافت و بررسی سفارش | C3: فروش | D3: — | E3: سفارش کامل و تأیید اولیه (Ready_Flag=READY) | F3: ↓
A4: ۲ | B4: تعریف پروژه + تهیه گانت + تکمیل امکان‌سنجی | C4: مدیر پروژه | D4: گیت ۱ (سفارش آماده) | E4: امکان‌سنجی کامل (امتیازها + نتیجه + توصیه) | F4: ↓
A5: ۳ | B5: تهیه اقلام (BOM)، تجهیزات، زمان‌سنجی و نفرساعت | C5: مهندسی | D5: گیت ۲ (امکان‌سنجی کامل) | E5: مهندسی تأییدشده + BOM تأییدشده + زمان‌سنجی ثبت‌شده | F5: ↓
A6: ۴ | B6: تعیین قیمت اقلام و تجهیزات فهرست مهندسی (با نرخ ارز وارداتی) | C6: بازرگانی | D6: گیت ۳ (مهندسی کامل) | E6: همه اقلام/تجهیزات پروژه قیمت‌گذاری‌شده و معتبر | F6: ↓
A7: ۵ | B7: مقدار مورد نیاز اقلام برای تولید + زمان‌بندی نیاز + ثبت رسید انبار | C7: برنامه‌ریزی تولید و انبارها | D7: گیت ۴ (بازرگانی کامل) | E7: تاریخ نیاز و وضعیت تأمین همه ردیف‌های نیاز ثبت‌شده | F7: ↓
A8: ۶ | B8: قیمت تمام‌شده محصول + تدوین بودجه راه‌اندازی | C8: مالی | D8: گیت ۵ (برنامه‌ریزی کامل) | E8: Costing تأییدشده + بودجه ثبت‌شده | F8: ↓
A9: ۷ | B9: تعیین قیمت نهایی فروش و نحوه پرداخت | C9: فروش | D9: گیت ۶ (مالی کامل) | E9: پیشنهاد قیمت Submitted با سناریو و شرایط پرداخت | F9: ↓
A10: ۸ | B10: جمع‌بندی عملکرد واحدها + به‌روزرسانی گانت/امکان‌سنجی + اعلام به ارشد | C10: مدیریت پروژه (PMO) | D10: گیت ۷ (قیمت‌گذاری کامل) | E10: گزارش جمع‌بندی ارسال‌شده (Report_Date) | F10: ↓
A11: ۹ | B11: تأیید / رد / برگشت برای اصلاح | C11: مدیریت ارشد | D11: گیت ۸ (گزارش کامل) | E11: ثبت تصمیم چهارگانه: APPROVED / مشروط / برگشت / رد
A13: برگشت برای اصلاح: تصمیم RETURN FOR REVISION پروژه را به مرحله مربوط بازمی‌گرداند؛ تغییر هر ورودیِ تصویب‌شده فقط با Revision جدید.
A14: اجرای گیت‌ها: ستون‌های G در شیت Gate_Status + Data Validation روی سلول‌های ورودی + محدوده‌های ویرایش رمزدار (شیت Access_Control).

Sheet Gate_Status
A1: Gate_Status | B1: هر ستون S پرچم تکمیل یک مرحله (فرمول زنده)؛ ستون‌های G گیت تجمعی هستند: تا مرحله قبل تکمیل نشود، ورود اطلاعات در مرحله بعد توسط Data Validation مسدود است. Any_G_* ها در ردیف ۱ برای گیت شیت‌های غیرپروژه‌محور. | Z1: Any_G_Eng | AA1: =MAX($O$3:$O$20) | AB1: Any_G_Com | AC1: =MAX($P$3:$P$20) | AD1: Any_G_Pln | AE1: =MAX($Q$3:$Q$20)
A2: System_ID | B2: Project_ID | C2: Order_ID | D2: S1_Sales_Ready | E2: S2_PM_Feasibility | F2: S3_Engineering | G2: S4_Commercial | H2: S5_Planning_Warehouse | I2: S6_Finance | J2: S7_Sales_Pricing | K2: S8_PMO_Summary | L2: Decision_Recorded | M2: Decision_Text | N2: G_PM | O2: G_Eng | P2: G_Com | Q2: G_Pln | R2: G_Fin | S2: G_Price | T2: G_PMO | U2: G_Senior | V2: Stages_Completed | W2: Completion_Percent | X2: Current_Stage
A3: GST-000001 | B3: =Projects!$A$3 | C3: =Projects!$C$3 | D3: =IF(COUNTIFS(Orders!$A$3:$A$20,$C3,Orders!$R$3:$R$20,"READY")>0,1,0) | E3: =IF(COUNTIFS(Feasibility!$B$3:$B$20,$B3,Feasibility!$M$3:$M$20,"COMPLETE")>0,1,0) | F3: =IF(AND(COUNTIFS(Engineering!$B$3:$B$20,$B3,Engineering!$H$3:$H$20,"Approved")>0,COUNTIFS(Time_Study!$B$3:$B$20,$B3)>0,COUNTIFS(BOM_Header!$C$3:$C$20,XLOOKUP(XLOOKUP($B3,Projects!$A$3:$A$20,Projects!$E$3:$E$20,""),Product_Revisions!$B$3:$B$20,Product_Revisions!$A$3:$A$20,""),BOM_Header!$I$3:$I$20,"Approved")>0),1,0) | G3: =IF(AND(COUNTIFS(Project_Equipment!$B$3:$B$20,$B3)>0,COUNTIFS(Project_Equipment!$B$3:$B$20,$B3,Project_Equipment!$N$3:$N$20,"PRICED")=COUNTIFS(Project_Equipment!$B$3:$B$20,$B3),COUNTIFS(Purchase_Prices!$S$3:$S$20,"Approved",Purchase_Prices!$R$3:$R$20,0)>0),1,0) | H3: =IF(AND(COUNTIFS(Planning!$B$3:$B$30,$B3)>0,COUNTIFS(Planning!$B$3:$B$30,$B3,Planning!$R$3:$R$30,"Approved")=COUNTIFS(Planning!$B$3:$B$30,$B3)),1,0) | I3: =IF(COUNTIFS(Costing!$B$3:$B$10,$B3,Costing!$D$3:$D$10,"Approved")>0,1,0) | J3: =IF(COUNTIFS(Sales_Quotation!$B$3:$B$10,$B3,Sales_Quotation!$O$3:$O$10,"Submitted")>0,1,0) | K3: =IF(COUNTIFS(PMO_Summary!$B$3:$B$10,$B3,PMO_Summary!$J$3:$J$10,"REPORTED")>0,1,0) | L3: =IF($M3<>"",1,0) | M3: =IFERROR(XLOOKUP($B3,Management_Approval!$C$3:$C$10,Management_Approval!$D$3:$D$10,""),"") | N3: =$D3 | O3: =$D3*$E3 | P3: =$O3*$F3 | Q3: =$P3*$G3 | R3: =$Q3*$H3 | S3: =$R3*$I3 | T3: =$S3*$J3 | U3: =$T3*$K3 | V3: =SUM($D3:$K3) | W3: =ROUND($V3/8,3) | X3: =IF($L3=1,"چرخه کامل — تصمیم ثبت شده",IF($D3=0,"بررسی سفارش (فروش)",IF($E3=0,"تعریف پروژه و امکان‌سنجی (مدیر پروژه)",IF($F3=0,"مهندسی (اقلام/تجهیزات/زمان‌سنجی)",IF($G3=0,"بازرگانی (قیمت‌دهی اقلام)",IF($H3=0,"برنامه‌ریزی تولید و انبارها",IF($I3=0,"مالی (قیمت تمام‌شده و بودجه)",IF($J3=0,"فروش (قیمت نهایی و نحوه پرداخت)",IF($K3=0,"جمع‌بندی و اعلام به مدیریت ارشد","در انتظار تصمیم مدیریت ارشد")))))))))
A4: GST-000002 | B4: =Projects!$A$4 | C4: =Projects!$C$4 | D4: =IF(COUNTIFS(Orders!$A$3:$A$20,$C4,Orders!$R$3:$R$20,"READY")>0,1,0) | E4: =IF(COUNTIFS(Feasibility!$B$3:$B$20,$B4,Feasibility!$M$3:$M$20,"COMPLETE")>0,1,0) | F4: =IF(AND(COUNTIFS(Engineering!$B$3:$B$20,$B4,Engineering!$H$3:$H$20,"Approved")>0,COUNTIFS(Time_Study!$B$3:$B$20,$B4)>0,COUNTIFS(BOM_Header!$C$3:$C$20,XLOOKUP(XLOOKUP($B4,Projects!$A$3:$A$20,Projects!$E$3:$E$20,""),Product_Revisions!$B$3:$B$20,Product_Revisions!$A$3:$A$20,""),BOM_Header!$I$3:$I$20,"Approved")>0),1,0) | G4: =IF(AND(COUNTIFS(Project_Equipment!$B$3:$B$20,$B4)>0,COUNTIFS(Project_Equipment!$B$3:$B$20,$B4,Project_Equipment!$N$3:$N$20,"PRICED")=COUNTIFS(Project_Equipment!$B$3:$B$20,$B4),COUNTIFS(Purchase_Prices!$S$3:$S$20,"Approved",Purchase_Prices!$R$3:$R$20,0)>0),1,0) | H4: =IF(AND(COUNTIFS(Planning!$B$3:$B$30,$B4)>0,COUNTIFS(Planning!$B$3:$B$30,$B4,Planning!$R$3:$R$30,"Approved")=COUNTIFS(Planning!$B$3:$B$30,$B4)),1,0) | I4: =IF(COUNTIFS(Costing!$B$3:$B$10,$B4,Costing!$D$3:$D$10,"Approved")>0,1,0) | J4: =IF(COUNTIFS(Sales_Quotation!$B$3:$B$10,$B4,Sales_Quotation!$O$3:$O$10,"Submitted")>0,1,0) | K4: =IF(COUNTIFS(PMO_Summary!$B$3:$B$10,$B4,PMO_Summary!$J$3:$J$10,"REPORTED")>0,1,0) | L4: =IF($M4<>"",1,0) | M4: =IFERROR(XLOOKUP($B4,Management_Approval!$C$3:$C$10,Management_Approval!$D$3:$D$10,""),"") | N4: =$D4 | O4: =$D4*$E4 | P4: =$O4*$F4 | Q4: =$P4*$G4 | R4: =$Q4*$H4 | S4: =$R4*$I4 | T4: =$S4*$J4 | U4: =$T4*$K4 | V4: =SUM($D4:$K4) | W4: =ROUND($V4/8,3) | X4: =IF($L4=1,"چرخه کامل — تصمیم ثبت شده",IF($D4=0,"بررسی سفارش (فروش)",IF($E4=0,"تعریف پروژه و امکان‌سنجی (مدیر پروژه)",IF($F4=0,"مهندسی (اقلام/تجهیزات/زمان‌سنجی)",IF($G4=0,"بازرگانی (قیمت‌دهی اقلام)",IF($H4=0,"برنامه‌ریزی تولید و انبارها",IF($I4=0,"مالی (قیمت تمام‌شده و بودجه)",IF($J4=0,"فروش (قیمت نهایی و نحوه پرداخت)",IF($K4=0,"جمع‌بندی و اعلام به مدیریت ارشد","در انتظار تصمیم مدیریت ارشد")))))))))

Sheet Access_Control
A1: Access_Control | B1: هر نقش فقط محدوده‌های خودش را (با گذرواژه خود) می‌تواند ویرایش کند؛ مشاهده همه شیت‌ها آزاد است. اعمال فنی: Sheet Protection + Protected Ranges. برای تغییر گذرواژه‌ها، اسکریپت ساخت را ویرایش و بازتولید کنید.
A2: Role_ID | B2: Role_Name | C2: Department_ID | D2: Edit_Password | E2: Scope | F2: Notes
A3: ROL-02 | B3: Sales (فروش) | C3: DEP-01 | D3: فروش1404 | E3: Orders (ثبت و بررسی سفارش) | Sales_Quotation (قیمت نهایی/حاشیه) | Payment_Terms (نحوه پرداخت) | F3: فقط ورودی‌های واحد فروش؛ مشاهده همه شیت‌ها آزاد است
A4: ROL-03 | B4: Project Manager (مدیر پروژه) | C4: DEP-06 | D4: مدیر1404 | E4: Projects | Feasibility | Schedule | Gantt | PMO_Summary | F4: مشاهده همه بخش‌ها آزاد؛ ویرایش فقط در بخش‌های خود (تعریف پروژه، امکان‌سنجی، گانت، جمع‌بندی)
A5: ROL-04 | B5: Engineering (مهندسی) | C5: DEP-02 | D5: مهندسی1404 | E5: Engineering | BOM_Header | BOM_Detail | Materials | Equipment | Project_Equipment (بخش مهندسی) | Time_Study | F5: تهیه لیست اقلام/تجهیزات، زمان‌سنجی و نفرساعت؛ نگهداری لیست‌های مرجع
A6: ROL-06 | B6: Commercial (بازرگانی) | C6: DEP-04 | D6: بازرگانی1404 | E6: Supplier_Quotes | Supplier_Quote_Lines | Procurement | Purchase_Prices | Project_Equipment (بخش قیمت‌دهی) | F6: قیمت‌دهی اقلامِ فهرست مهندسی + نرخ ارز برای اقلام وارداتی
A7: ROL-05 | B7: Planning (برنامه‌ریزی تولید و انبارها) | C7: DEP-03 | D7: برنامه1404 | E7: Planning (تاریخ نیاز/وضعیت تأمین) | Inventory | F7: مقدار مورد نیاز از مهندسی (BOM) محاسبه می‌شود؛ برنامه‌ریزی زمان‌بندی نیاز را ثبت می‌کند
A8: ROL-10 | B8: Warehouse (انبار) | C8: DEP-03 | D8: انبار1404 | E8: Receipts (رسیدهای انبار) | Inventory (موجودی) | F8: ثبت رسید اقلام و نگهداری موجودی
A9: ROL-07 | B9: Finance (مالی) | C9: DEP-05 | D9: مالی1404 | E9: Cost_Lines | Costing | Budget | F9: قیمت تمام‌شده محصول + تدوین بودجه راه‌اندازی
A10: ROL-08 | B10: Senior Management (مدیریت ارشد) | C10: DEP-07 | D10: ارشد1404 | E10: Management_Approval (تصمیم نهایی: تأیید / رد / برگشت برای اصلاح) | F10: فقط ثبت تصمیم؛ سایر بخش‌ها صرفاً قابل مشاهده
A11: ROL-09 | B11: Admin (راهبر) | C11: — | D11: راهبر1404 | E11: باز/بستن محافظت شیت‌ها و تغییر گذرواژه‌ها | F11: گذرواژه محافظت شیت‌ها؛ در اختیار مدیر سیستم

Sheet Orders
A1: Orders | B1: کنترل اولیه سفارش (CO_01..CO_04)؛ تا Ready_Flag=READY نباشد ورود به مهندسی مجاز نیست.
A2: System_ID | B2: Customer_ID | C2: Order_Date | D2: Requested_Delivery_Date | E2: Request_Type | F2: Total_Qty | G2: Delivery_Terms | H2: Payment_Terms | I2: Validity_Days | J2: Confidentiality_Level | K2: Sales_Responsible | L2: Doc_Ref | M2: Status_ID | N2: CO_01_Customer_Valid | O2: CO_02_Qty_Defined | P2: CO_03_Delivery_Defined | Q2: CO_04_Payment_Defined | R2: Ready_Flag | S2: Duplicate_Flag | T2: Create_Date | U2: Created_By
A3: ORD-2026-00321 | B3: CUS-000001 | C3: 46285 | D3: 46376 | E3: New | F3: =SUMIF(Order_Lines!$B$3:$B$20,$A3,Order_Lines!$E$3:$E$20) | G3: CPT سایت عسلویه | H3: 30% پیش‌پرداخت + 70% اعتبار 60 روزه | I3: 30 | J3: Confidential | K3: USR-02 | L3: RFQ-SABA-2026-09-001 | M3: Approved | N3: =IF(TRIM($B3)<>"","OK","MISSING") | O3: =IF(SUMIF(Order_Lines!$B$3:$B$20,$A3,Order_Lines!$E$3:$E$20)>0,"OK","MISSING") | P3: =IF(TRIM($D3)<>"","OK","MISSING") | Q3: =IF(TRIM($H3)<>"","OK","MISSING") | R3: =IF(AND($N3="OK",$O3="OK",$P3="OK",$Q3="OK"),"READY","INCOMPLETE") | S3: =IF(COUNTIF($A$3:$A$1000,$A3)>1,"DUP","OK") | T3: 46285 | U3: USR-02
A4: ORD-2026-00322 | B4: CUS-000002 | C4: 46286 | D4: 46402 | E4: New | F4: =SUMIF(Order_Lines!$B$3:$B$20,$A4,Order_Lines!$E$3:$E$20) | G4: CPT بندرعباس | H4: LC | I4: 45 | J4: Internal | K4: USR-02 | L4: RFQ-STAREH-2026-09-002 | M4: Draft | N4: =IF(TRIM($B4)<>"","OK","MISSING") | O4: =IF(SUMIF(Order_Lines!$B$3:$B$20,$A4,Order_Lines!$E$3:$E$20)>0,"OK","MISSING") | P4: =IF(TRIM($D4)<>"","OK","MISSING") | Q4: =IF(TRIM($H4)<>"","OK","MISSING") | R4: =IF(AND($N4="OK",$O4="OK",$P4="OK",$Q4="OK"),"READY","INCOMPLETE") | S4: =IF(COUNTIF($A$3:$A$1000,$A4)>1,"DUP","OK") | T4: 46285 | U4: USR-02
A5: ORD-2026-00323 | B5: CUS-000001 | C5: 46286 | E5: New | F5: =SUMIF(Order_Lines!$B$3:$B$20,$A5,Order_Lines!$E$3:$E$20) | I5: 30 | J5: Internal | K5: USR-02 | L5: RFQ-SABA-2026-09-009 | M5: Draft | N5: =IF(TRIM($B5)<>"","OK","MISSING") | O5: =IF(SUMIF(Order_Lines!$B$3:$B$20,$A5,Order_Lines!$E$3:$E$20)>0,"OK","MISSING") | P5: =IF(TRIM($D5)<>"","OK","MISSING") | Q5: =IF(TRIM($H5)<>"","OK","MISSING") | R5: =IF(AND($N5="OK",$O5="OK",$P5="OK",$Q5="OK"),"READY","INCOMPLETE") | S5: =IF(COUNTIF($A$3:$A$1000,$A5)>1,"DUP","OK") | T5: 46285 | U5: USR-02

Sheet Order_Lines
A1: Order_Lines | B1: هر سفارش می‌تواند چند ردیف محصول داشته باشد (Order → Order_Line → Product).
A2: System_ID | B2: Order_ID | C2: Line_No | D2: Product_ID | E2: Quantity | F2: UoM | G2: Latest_FLAG | H2: Create_Date | I2: Created_By
A3: OLN-000456 | B3: ORD-2026-00321 | C3: 1 | D3: PRD-000125 | E3: 2 | F3: pcs | G3: 1 | H3: 46285 | I3: USR-02
A4: OLN-000457 | B4: ORD-2026-00321 | C4: 2 | D4: PRD-000126 | E4: 1 | F4: pcs | G4: 1 | H4: 46285 | I4: USR-02
A5: OLN-000458 | B5: ORD-2026-00322 | C5: 1 | D5: PRD-000125 | E5: 1 | F5: pcs | G5: 1 | H5: 46285 | I5: USR-02

Sheet Projects
A1: Projects
A2: System_ID | B2: Project_Code | C2: Order_ID | D2: Customer_ID | E2: Product_ID | F2: Project_Name | G2: Project_Manager | H2: Start_Date | I2: Due_Date | J2: Priority | K2: Status_ID | L2: Progress_% | M2: Sponsor | N2: Team_List | O2: Overdue_Flag | P2: Create_Date | Q2: Created_By
A3: PRJ-2026-00125 | B3: PRJ-001 | C3: ORD-2026-00321 | D3: CUS-000001 | E3: PRD-000125 | F3: پمپ PMP-250 صبا | G3: USR-03 | H3: 46286 | I3: 46376 | J3: High | K3: Approved | L3: 0.45 | M3: USR-08 | N3: Neda E, Kaveh P, Mina T, Ali F | O3: =IF(ISBLANK($I3),0,IF(AND($I3<TODAY(),$K3<>"Closed"),1,0)) | P3: 46286 | Q3: USR-03
A4: PRJ-2026-00126 | B4: PRJ-002 | C4: ORD-2026-00322 | D4: CUS-000002 | E4: PRD-000125 | F4: پمپ PMP-250 ستاره | G4: USR-03 | H4: 46287 | I4: 46402 | J4: Medium | K4: Draft | L4: 0.05 | M4: USR-08 | N4: TBD | O4: =IF(ISBLANK($I4),0,IF(AND($I4<TODAY(),$K4<>"Closed"),1,0)) | P4: 46286 | Q4: USR-03

Sheet Feasibility
A1: Feasibility | B1: امکان‌سنجی توسط مدیر پروژه تکمیل می‌شود؛ بدون Completed_Flag=COMPLETE گیت مهندسی باز نمی‌شود. وزن‌ها و کف امتیاز از Settings خوانده می‌شود.
A2: System_ID | B2: Project_ID | C2: Version | D2: Market_Score | E2: Technical_Score | F2: Economic_Score | G2: Schedule_Score | H2: Risk_Score | I2: Weighted_Score | J2: Risk_Level | K2: Feasibility_Result | L2: Go_NoGo_Recommendation | M2: Completed_Flag | N2: Status_ID | O2: Create_Date | P2: Created_By
A3: FEA-000125 | B3: PRJ-2026-00125 | C3: R01 | D3: 85 | E3: 90 | F3: 78 | G3: 80 | H3: 30 | I3: =IF(AND(ISNUMBER($D3),ISNUMBER($E3),ISNUMBER($F3),ISNUMBER($G3)),ROUND(Settings!$B$17*$D3+Settings!$B$18*$E3+Settings!$B$19*$F3+Settings!$B$20*$G3,2),"") | J3: =IF(ISNUMBER($H3),IF($H3>=67,"High",IF($H3>=34,"Medium","Low")),"") | K3: =IF($I3="","",IF(AND($I3>=Settings!$B$21,$J3<>"High"),"Feasible",IF($I3>=50,"Conditional","Not Feasible"))) | L3: اجرا شود؛ ریسک تأمین مکانیکال سیل با پیش‌خرید و تعهد کتبی تأمین‌کننده مدیریت شود | M3: =IF(AND(ISNUMBER($D3),ISNUMBER($E3),ISNUMBER($F3),ISNUMBER($G3),ISNUMBER($H3),$L3<>""),"COMPLETE","INCOMPLETE") | N3: Approved | O3: 46287 | P3: USR-03
A4: FEA-000126 | B4: PRJ-2026-00126 | C4: R01 | D4: 70 | G4: 65 | I4: =IF(AND(ISNUMBER($D4),ISNUMBER($E4),ISNUMBER($F4),ISNUMBER($G4)),ROUND(Settings!$B$17*$D4+Settings!$B$18*$E4+Settings!$B$19*$F4+Settings!$B$20*$G4,2),"") | J4: =IF(ISNUMBER($H4),IF($H4>=67,"High",IF($H4>=34,"Medium","Low")),"") | K4: =IF($I4="","",IF(AND($I4>=Settings!$B$21,$J4<>"High"),"Feasible",IF($I4>=50,"Conditional","Not Feasible"))) | M4: =IF(AND(ISNUMBER($D4),ISNUMBER($E4),ISNUMBER($F4),ISNUMBER($G4),ISNUMBER($H4),$L4<>""),"COMPLETE","INCOMPLETE") | N4: Draft | O4: 46287 | P4: USR-03

Sheet Gantt
A1: Gantt — نمودار گانت برنامه/عملکرد (منبع: Schedule؛ به‌روزرسانی توسط مدیر پروژه) | B1: هر ستون یک هفته؛ میله = بازه شروع تا پایان فعالیت. رنگ‌ها: سبز=انجام‌شده، آبی=در جریان، قرمز=معوق، خاکستری=برنامه‌ریزی‌شده.
A2: System_ID | B2: Project_ID | C2: Activity | D2: Responsible | E2: Status_ID | F2: Start_Date | G2: End_Date | H2: Duration | I2: Display_Status | J2: 46286 | K2: 46293 | L2: 46300 | M2: 46307 | N2: 46314 | O2: 46321 | P2: 46328 | Q2: 46335 | R2: 46342 | S2: 46349 | T2: 46356 | U2: 46363 | V2: 46370 | W2: 46377 | X2: 46384 | Y2: 46391 | Z2: 46398 | AA2: 46405 | AB2: 46412 | AC2: 46419 | AD2: 46426 | AE2: 46433 | AF2: 46440 | AG2: 46447 | AH2: 46454 | AI2: 46461
A3: =Schedule!$A$3 | B3: =Schedule!$B$3 | C3: =Schedule!$C$3 | D3: =Schedule!$G$3 | E3: =Schedule!$I$3 | F3: =Schedule!$D$3 | G3: =Schedule!$E$3 | H3: =IF(OR($F3="",$G3=""),0,$G3-$F3+1) | I3: =IF($F3="","",IF($E3="Done","Done",IF($G3<TODAY(),"Late",IF($E3="Not Started","Planned","In Progress")))) | J3: =IF(AND($F3<>"",J$2>=$F3,J$2<=$G3),1,0) | K3: =IF(AND($F3<>"",K$2>=$F3,K$2<=$G3),1,0) | L3: =IF(AND($F3<>"",L$2>=$F3,L$2<=$G3),1,0) | M3: =IF(AND($F3<>"",M$2>=$F3,M$2<=$G3),1,0) | N3: =IF(AND($F3<>"",N$2>=$F3,N$2<=$G3),1,0) | O3: =IF(AND($F3<>"",O$2>=$F3,O$2<=$G3),1,0) | P3: =IF(AND($F3<>"",P$2>=$F3,P$2<=$G3),1,0) | Q3: =IF(AND($F3<>"",Q$2>=$F3,Q$2<=$G3),1,0) | ... AI3: =IF(AND($F3<>"",AI$2>=$F3,AI$2<=$G3),1,0)
A4: =Schedule!$A$4 | B4: =Schedule!$B$4 | C4: =Schedule!$C$4 | D4: =Schedule!$G$4 | E4: =Schedule!$I$4 | F4: =Schedule!$D$4 | G4: =Schedule!$E$4 | H4: =IF(OR($F4="",$G4=""),0,$G4-$F4+1) | I4: =IF($F4="","",IF($E4="Done","Done",IF($G4<TODAY(),"Late",IF($E4="Not Started","Planned","In Progress")))) | J4: =IF(AND($F4<>"",J$2>=$F4,J$2<=$G4),1,0) | K4: =IF(AND($F4<>"",K$2>=$F4,K$2<=$G4),1,0) | L4: =IF(AND($F4<>"",L$2>=$F4,L$2<=$G4),1,0) | M4: =IF(AND($F4<>"",M$2>=$F4,M$2<=$G4),1,0) | N4: =IF(AND($F4<>"",N$2>=$F4,N$2<=$G4),1,0) | O4: =IF(AND($F4<>"",O$2>=$F4,O$2<=$G4),1,0) | P4: =IF(AND($F4<>"",P$2>=$F4,P$2<=$G4),1,0) | Q4: =IF(AND($F4<>"",Q$2>=$F4,Q$2<=$G4),1,0) | ... AI4: =IF(AND($F4<>"",AI$2>=$F4,AI$2<=$G4),1,0)
A5: =Schedule!$A$5 | B5: =Schedule!$B$5 | C5: =Schedule!$C$5 | D5: =Schedule!$G$5 | E5: =Schedule!$I$5 | F5: =Schedule!$D$5 | G5: =Schedule!$E$5 | H5: =IF(OR($F5="",$G5=""),0,$G5-$F5+1) | I5: =IF($F5="","",IF($E5="Done","Done",IF($G5<TODAY(),"Late",IF($E5="Not Started","Planned","In Progress")))) | J5: =IF(AND($F5<>"",J$2>=$F5,J$2<=$G5),1,0) | K5: =IF(AND($F5<>"",K$2>=$F5,K$2<=$G5),1,0) | L5: =IF(AND($F5<>"",L$2>=$F5,L$2<=$G5),1,0) | M5: =IF(AND($F5<>"",M$2>=$F5,M$2<=$G5),1,0) | N5: =IF(AND($F5<>"",N$2>=$F5,N$2<=$G5),1,0) | O5: =IF(AND($F5<>"",O$2>=$F5,O$2<=$G5),1,0) | P5: =IF(AND($F5<>"",P$2>=$F5,P$2<=$G5),1,0) | Q5: =IF(AND($F5<>"",Q$2>=$F5,Q$2<=$G5),1,0) | ... AI5: =IF(AND($F5<>"",AI$2>=$F5,AI$2<=$G5),1,0)
A6: =Schedule!$A$6 | B6: =Schedule!$B$6 | C6: =Schedule!$C$6 | D6: =Schedule!$G$6 | E6: =Schedule!$I$6 | F6: =Schedule!$D$6 | G6: =Schedule!$E$6 | H6: =IF(OR($F6="",$G6=""),0,$G6-$F6+1) | I6: =IF($F6="","",IF($E6="Done","Done",IF($G6<TODAY(),"Late",IF($E6="Not Started","Planned","In Progress")))) | J6: =IF(AND($F6<>"",J$2>=$F6,J$2<=$G6),1,0) | K6: =IF(AND($F6<>"",K$2>=$F6,K$2<=$G6),1,0) | L6: =IF(AND($F6<>"",L$2>=$F6,L$2<=$G6),1,0) | M6: =IF(AND($F6<>"",M$2>=$F6,M$2<=$G6),1,0) | N6: =IF(AND($F6<>"",N$2>=$F6,N$2<=$G6),1,0) | O6: =IF(AND($F6<>"",O$2>=$F6,O$2<=$G6),1,0) | P6: =IF(AND($F6<>"",P$2>=$F6,P$2<=$G6),1,0) | Q6: =IF(AND($F6<>"",Q$2>=$F6,Q$2<=$G6),1,0) | ... AI6: =IF(AND($F6<>"",AI$2>=$F6,AI$2<=$G6),1,0)
A7: =Schedule!$A$7 | B7: =Schedule!$B$7 | C7: =Schedule!$C$7 | D7: =Schedule!$G$7 | E7: =Schedule!$I$7 | F7: =Schedule!$D$7 | G7: =Schedule!$E$7 | H7: =IF(OR($F7="",$G7=""),0,$G7-$F7+1) | I7: =IF($F7="","",IF($E7="Done","Done",IF($G7<TODAY(),"Late",IF($E7="Not Started","Planned","In Progress")))) | J7: =IF(AND($F7<>"",J$2>=$F7,J$2<=$G7),1,0) | K7: =IF(AND($F7<>"",K$2>=$F7,K$2<=$G7),1,0) | L7: =IF(AND($F7<>"",L$2>=$F7,L$2<=$G7),1,0) | M7: =IF(AND($F7<>"",M$2>=$F7,M$2<=$G7),1,0) | N7: =IF(AND($F7<>"",N$2>=$F7,N$2<=$G7),1,0) | O7: =IF(AND($F7<>"",O$2>=$F7,O$2<=$G7),1,0) | P7: =IF(AND($F7<>"",P$2>=$F7,P$2<=$G7),1,0) | Q7: =IF(AND($F7<>"",Q$2>=$F7,Q$2<=$G7),1,0) | ... AI7: =IF(AND($F7<>"",AI$2>=$F7,AI$2<=$G7),1,0)
A8: =Schedule!$A$8 | B8: =Schedule!$B$8 | C8: =Schedule!$C$8 | D8: =Schedule!$G$8 | E8: =Schedule!$I$8 | F8: =Schedule!$D$8 | G8: =Schedule!$E$8 | H8: =IF(OR($F8="",$G8=""),0,$G8-$F8+1) | I8: =IF($F8="","",IF($E8="Done","Done",IF($G8<TODAY(),"Late",IF($E8="Not Started","Planned","In Progress")))) | J8: =IF(AND($F8<>"",J$2>=$F8,J$2<=$G8),1,0) | K8: =IF(AND($F8<>"",K$2>=$F8,K$2<=$G8),1,0) | L8: =IF(AND($F8<>"",L$2>=$F8,L$2<=$G8),1,0) | M8: =IF(AND($F8<>"",M$2>=$F8,M$2<=$G8),1,0) | N8: =IF(AND($F8<>"",N$2>=$F8,N$2<=$G8),1,0) | O8: =IF(AND($F8<>"",O$2>=$F8,O$2<=$G8),1,0) | P8: =IF(AND($F8<>"",P$2>=$F8,P$2<=$G8),1,0) | Q8: =IF(AND($F8<>"",Q$2>=$F8,Q$2<=$G8),1,0) | ... AI8: =IF(AND($F8<>"",AI$2>=$F8,AI$2<=$G8),1,0)
A9: =Schedule!$A$9 | B9: =Schedule!$B$9 | C9: =Schedule!$C$9 | D9: =Schedule!$G$9 | E9: =Schedule!$I$9 | F9: =Schedule!$D$9 | G9: =Schedule!$E$9 | H9: =IF(OR($F9="",$G9=""),0,$G9-$F9+1) | I9: =IF($F9="","",IF($E9="Done","Done",IF($G9<TODAY(),"Late",IF($E9="Not Started","Planned","In Progress")))) | J9: =IF(AND($F9<>"",J$2>=$F9,J$2<=$G9),1,0) | K9: =IF(AND($F9<>"",K$2>=$F9,K$2<=$G9),1,0) | L9: =IF(AND($F9<>"",L$2>=$F9,L$2<=$G9),1,0) | M9: =IF(AND($F9<>"",M$2>=$F9,M$2<=$G9),1,0) | N9: =IF(AND($F9<>"",N$2>=$F9,N$2<=$G9),1,0) | O9: =IF(AND($F9<>"",O$2>=$F9,O$2<=$G9),1,0) | P9: =IF(AND($F9<>"",P$2>=$F9,P$2<=$G9),1,0) | Q9: =IF(AND($F9<>"",Q$2>=$F9,Q$2<=$G9),1,0) | ... AI9: =IF(AND($F9<>"",AI$2>=$F9,AI$2<=$G9),1,0)
A10: =Schedule!$A$10 | B10: =Schedule!$B$10 | C10: =Schedule!$C$10 | D10: =Schedule!$G$10 | E10: =Schedule!$I$10 | F10: =Schedule!$D$10 | G10: =Schedule!$E$10 | H10: =IF(OR($F10="",$G10=""),0,$G10-$F10+1) | I10: =IF($F10="","",IF($E10="Done","Done",IF($G10<TODAY(),"Late",IF($E10="Not Started","Planned","In Progress")))) | J10: =IF(AND($F10<>"",J$2>=$F10,J$2<=$G10),1,0) | K10: =IF(AND($F10<>"",K$2>=$F10,K$2<=$G10),1,0) | L10: =IF(AND($F10<>"",L$2>=$F10,L$2<=$G10),1,0) | M10: =IF(AND($F10<>"",M$2>=$F10,M$2<=$G10),1,0) | N10: =IF(AND($F10<>"",N$2>=$F10,N$2<=$G10),1,0) | O10: =IF(AND($F10<>"",O$2>=$F10,O$2<=$G10),1,0) | P10: =IF(AND($F10<>"",P$2>=$F10,P$2<=$G10),1,0) | Q10: =IF(AND($F10<>"",Q$2>=$F10,Q$2<=$G10),1,0) | ... AI10: =IF(AND($F10<>"",AI$2>=$F10,AI$2<=$G10),1,0)
A11: =Schedule!$A$11 | B11: =Schedule!$B$11 | C11: =Schedule!$C$11 | D11: =Schedule!$G$11 | E11: =Schedule!$I$11 | F11: =Schedule!$D$11 | G11: =Schedule!$E$11 | H11: =IF(OR($F11="",$G11=""),0,$G11-$F11+1) | I11: =IF($F11="","",IF($E11="Done","Done",IF($G11<TODAY(),"Late",IF($E11="Not Started","Planned","In Progress")))) | J11: =IF(AND($F11<>"",J$2>=$F11,J$2<=$G11),1,0) | K11: =IF(AND($F11<>"",K$2>=$F11,K$2<=$G11),1,0) | L11: =IF(AND($F11<>"",L$2>=$F11,L$2<=$G11),1,0) | M11: =IF(AND($F11<>"",M$2>=$F11,M$2<=$G11),1,0) | N11: =IF(AND($F11<>"",N$2>=$F11,N$2<=$G11),1,0) | O11: =IF(AND($F11<>"",O$2>=$F11,O$2<=$G11),1,0) | P11: =IF(AND($F11<>"",P$2>=$F11,P$2<=$G11),1,0) | Q11: =IF(AND($F11<>"",Q$2>=$F11,Q$2<=$G11),1,0) | ... AI11: =IF(AND($F11<>"",AI$2>=$F11,AI$2<=$G11),1,0)
A12: =Schedule!$A$12 | B12: =Schedule!$B$12 | C12: =Schedule!$C$12 | D12: =Schedule!$G$12 | E12: =Schedule!$I$12 | F12: =Schedule!$D$12 | G12: =Schedule!$E$12 | H12: =IF(OR($F12="",$G12=""),0,$G12-$F12+1) | I12: =IF($F12="","",IF($E12="Done","Done",IF($G12<TODAY(),"Late",IF($E12="Not Started","Planned","In Progress")))) | J12: =IF(AND($F12<>"",J$2>=$F12,J$2<=$G12),1,0) | K12: =IF(AND($F12<>"",K$2>=$F12,K$2<=$G12),1,0) | L12: =IF(AND($F12<>"",L$2>=$F12,L$2<=$G12),1,0) | M12: =IF(AND($F12<>"",M$2>=$F12,M$2<=$G12),1,0) | N12: =IF(AND($F12<>"",N$2>=$F12,N$2<=$G12),1,0) | O12: =IF(AND($F12<>"",O$2>=$F12,O$2<=$G12),1,0) | P12: =IF(AND($F12<>"",P$2>=$F12,P$2<=$G12),1,0) | Q12: =IF(AND($F12<>"",Q$2>=$F12,Q$2<=$G12),1,0) | ... AI12: =IF(AND($F12<>"",AI$2>=$F12,AI$2<=$G12),1,0)
A13: =Schedule!$A$13 | B13: =Schedule!$B$13 | C13: =Schedule!$C$13 | D13: =Schedule!$G$13 | E13: =Schedule!$I$13 | F13: =Schedule!$D$13 | G13: =Schedule!$E$13 | H13: =IF(OR($F13="",$G13=""),0,$G13-$F13+1) | I13: =IF($F13="","",IF($E13="Done","Done",IF($G13<TODAY(),"Late",IF($E13="Not Started","Planned","In Progress")))) | J13: =IF(AND($F13<>"",J$2>=$F13,J$2<=$G13),1,0) | K13: =IF(AND($F13<>"",K$2>=$F13,K$2<=$G13),1,0) | L13: =IF(AND($F13<>"",L$2>=$F13,L$2<=$G13),1,0) | M13: =IF(AND($F13<>"",M$2>=$F13,M$2<=$G13),1,0) | N13: =IF(AND($F13<>"",N$2>=$F13,N$2<=$G13),1,0) | O13: =IF(AND($F13<>"",O$2>=$F13,O$2<=$G13),1,0) | P13: =IF(AND($F13<>"",P$2>=$F13,P$2<=$G13),1,0) | Q13: =IF(AND($F13<>"",Q$2>=$F13,Q$2<=$G13),1,0) | ... AI13: =IF(AND($F13<>"",AI$2>=$F13,AI$2<=$G13),1,0)

Sheet Schedule
A1: Schedule | B1: زمان‌بندی فعالیت‌ها؛ Duration = End - Start + 1 و Delay برای فعالیت‌های معوق محاسبه می‌شود.
A2: System_ID | B2: Project_ID | C2: Activity | D2: Start_Date | E2: End_Date | F2: Duration | G2: Responsible | H2: Dependency | I2: Status_ID | J2: Delay_Days | K2: Delay_Reason | L2: Create_Date | M2: Created_By
A3: SCH-000256 | B3: PRJ-2026-00125 | C3: Engineering | D3: 46286 | E3: 46295 | F3: =IF(ISBLANK($E3),0,$E3-$D3+1) | G3: USR-04 | I3: Done | J3: =IF(ISBLANK($E3),0,IF($I3="Done",0,IF(AND($I3<>"Done",TODAY()>$D3),TODAY()-$D3,0))) | L3: 46293 | M3: USR-05
A4: SCH-000257 | B4: PRJ-2026-00125 | C4: BOM Release | D4: 46293 | E4: 46295 | F4: =IF(ISBLANK($E4),0,$E4-$D4+1) | G4: USR-04 | H4: Engineering | I4: Done | J4: =IF(ISBLANK($E4),0,IF($I4="Done",0,IF(AND($I4<>"Done",TODAY()>$D4),TODAY()-$D4,0))) | L4: 46293 | M4: USR-05
A5: SCH-000258 | B5: PRJ-2026-00125 | C5: Procurement | D5: 46296 | E5: 46315 | F5: =IF(ISBLANK($E5),0,$E5-$D5+1) | G5: USR-06 | H5: BOM Release | I5: In Progress | J5: =IF(ISBLANK($E5),0,IF($I5="Done",0,IF(AND($I5<>"Done",TODAY()>$D5),TODAY()-$D5,0))) | L5: 46293 | M5: USR-05
A6: SCH-000259 | B6: PRJ-2026-00125 | C6: Supplier Confirmation | D6: 46300 | E6: 46315 | F6: =IF(ISBLANK($E6),0,$E6-$D6+1) | G6: USR-06 | H6: Procurement | I6: In Progress | J6: =IF(ISBLANK($E6),0,IF($I6="Done",0,IF(AND($I6<>"Done",TODAY()>$D6),TODAY()-$D6,0))) | L6: 46293 | M6: USR-05
A7: SCH-000260 | B7: PRJ-2026-00125 | C7: Material Arrival | D7: 46327 | E7: 46341 | F7: =IF(ISBLANK($E7),0,$E7-$D7+1) | G7: USR-06 | H7: Supplier Confirmation | I7: Not Started | J7: =IF(ISBLANK($E7),0,IF($I7="Done",0,IF(AND($I7<>"Done",TODAY()>$D7),TODAY()-$D7,0))) | L7: 46293 | M7: USR-05
A8: SCH-000261 | B8: PRJ-2026-00125 | C8: Production Planning | D8: 46336 | E8: 46346 | F8: =IF(ISBLANK($E8),0,$E8-$D8+1) | G8: USR-05 | H8: Material Arrival | I8: Not Started | J8: =IF(ISBLANK($E8),0,IF($I8="Done",0,IF(AND($I8<>"Done",TODAY()>$D8),TODAY()-$D8,0))) | L8: 46293 | M8: USR-05
A9: SCH-000262 | B9: PRJ-2026-00125 | C9: Production | D9: 46346 | E9: 46361 | F9: =IF(ISBLANK($E9),0,$E9-$D9+1) | G9: USR-05 | H9: Production Planning | I9: Not Started | J9: =IF(ISBLANK($E9),0,IF($I9="Done",0,IF(AND($I9<>"Done",TODAY()>$D9),TODAY()-$D9,0))) | L9: 46293 | M9: USR-05
A10: SCH-000263 | B10: PRJ-2026-00125 | C10: QC | D10: 46362 | E10: 46366 | F10: =IF(ISBLANK($E10),0,$E10-$D10+1) | G10: USR-04 | H10: Production | I10: Not Started | J10: =IF(ISBLANK($E10),0,IF($I10="Done",0,IF(AND($I10<>"Done",TODAY()>$D10),TODAY()-$D10,0))) | L10: 46293 | M10: USR-05
A11: SCH-000264 | B11: PRJ-2026-00125 | C11: Packing | D11: 46367 | E11: 46370 | F11: =IF(ISBLANK($E11),0,$E11-$D11+1) | G11: USR-05 | H11: QC | I11: Not Started | J11: =IF(ISBLANK($E11),0,IF($I11="Done",0,IF(AND($I11<>"Done",TODAY()>$D11),TODAY()-$D11,0))) | L11: 46293 | M11: USR-05
A12: SCH-000265 | B12: PRJ-2026-00125 | C12: Delivery | D12: 46371 | E12: 46374 | F12: =IF(ISBLANK($E12),0,$E12-$D12+1) | G12: USR-02 | H12: Packing | I12: Not Started | J12: =IF(ISBLANK($E12),0,IF($I12="Done",0,IF(AND($I12<>"Done",TODAY()>$D12),TODAY()-$D12,0))) | L12: 46293 | M12: USR-05
A13: SCH-000266 | B13: PRJ-2026-00126 | C13: Engineering | D13: 46266 | E13: 46280 | F13: =IF(ISBLANK($E13),0,$E13-$D13+1) | G13: USR-04 | I13: In Progress | J13: =IF(ISBLANK($E13),0,IF($I13="Done",0,IF(AND($I13<>"Done",TODAY()>$D13),TODAY()-$D13,0))) | K13: در انتظار تأیید نقشه | L13: 46266 | M13: USR-04

Sheet Engineering
A1: Engineering
A2: System_ID | B2: Project_ID | C2: Product_ID | D2: Product_Revision_ID | E2: Drawing_No | F2: Drawing_Revision | G2: BOM_Revision_ID | H2: Status_ID | I2: Process | J2: Machine | K2: Tooling | L2: Packaging | M2: Engineering_Notes | N2: Submitted_By | O2: Approved_By | P2: Create_Date | Q2: Created_By
A3: ENG-000125 | B3: PRJ-2026-00125 | C3: PRD-000125 | D3: PRV-000125-R03 | E3: DRW-250-A | F3: Rev C | G3: BOM-000215-R05 | H3: Approved | I3: Machining + Assembly | J3: CNC-5Axis | K3: Fixture-250 | L3: ISPM-15 | M3: مطابق نقشه DRW | N3: USR-04 | O3: USR-04 | P3: 46290 | Q3: USR-04
A4: ENG-000126 | B4: PRJ-2026-00125 | C4: PRD-000126 | D4: PRV-000126-R02 | E4: DRW-150-B | F4: Rev B | G4: BOM-000216-R02 | H4: Approved | I4: Machining + Assembly | J4: CNC-5Axis | K4: Fixture-250 | L4: ISPM-15 | M4: مطابق نقشه DRW | N4: USR-04 | O4: USR-04 | P4: 46290 | Q4: USR-04

Sheet BOM_Header
A1: BOM_Header | B1: نسخه‌بندی BOM؛ نسخه قبلی هرگز Overwrite نمی‌شود (Is_Active=0 / Status=Superseded).
A2: System_ID | B2: BOM_ID | C2: Product_Revision_ID | D2: Revision_No | E2: Rev_Date | F2: Change_Reason | G2: Changed_By | H2: Approved_By | I2: Status_ID | J2: Is_Active | K2: Create_Date | L2: Created_By
A3: BOM-000215-R05 | B3: BOM-000215 | C3: PRV-000125-R03 | D3: R05 | E3: 46293 | F3: تغییر تأمین‌کننده مکانیکال سیل و افزودن شفت | G3: USR-04 | H3: USR-04 | I3: Approved | J3: 1 | K3: 46293 | L3: USR-04
A4: BOM-000215-R04 | B4: BOM-000215 | C4: PRV-000125-R03 | D4: R04 | E4: 46235 | F4: نسخه قبلی (نگهداری برای Audit — بدون Overwrite) | G4: USR-04 | H4: USR-04 | I4: Superseded | J4: 0 | K4: 46235 | L4: USR-04
A5: BOM-000216-R02 | B5: BOM-000216 | C5: PRV-000126-R02 | D5: R02 | E5: 46178 | F5: نسخه اولیه | G5: USR-04 | H5: USR-04 | I5: Approved | J5: 1 | K5: 46178 | L5: USR-04

Sheet BOM_Detail
A1: BOM_Detail | B1: BOM چندسطحی (Parent_BOM_Line_ID / Level_No / Sequence_No). Gross_Qty = Qty_Per × (1 + Scrap%).
A2: System_ID | B2: BOM_Revision_ID | C2: Parent_BOM_Line_ID | D2: Level_No | E2: Sequence_No | F2: Material_ID | G2: Qty_Per | H2: UoM | I2: Scrap_% | J2: Net_Qty | K2: Gross_Qty | L2: Make_Buy | M2: Approved_Supplier | N2: Create_Date | O2: Created_By
A3: BLI-000987 | B3: BOM-000215-R05 | D3: 0 | E3: 10 | F3: PRD-000125 | G3: 1 | H3: pcs | I3: 0 | J3: =$G3 | K3: =ROUND($G3*(1+$I3),3) | L3: Make | N3: 46293 | O3: USR-04
A4: BLI-000988 | B4: BOM-000215-R05 | C4: BLI-000987 | D4: 1 | E4: 20 | F4: MAT-001542 | G4: 180 | H4: kg | I4: 0.05 | J4: =$G4 | K4: =ROUND($G4*(1+$I4),3) | L4: Make | N4: 46293 | O4: USR-04
A5: BLI-000989 | B5: BOM-000215-R05 | C5: BLI-000987 | D5: 1 | E5: 30 | F5: MAT-001543 | G5: 55 | H5: kg | I5: 0.05 | J5: =$G5 | K5: =ROUND($G5*(1+$I5),3) | L5: Make | N5: 46293 | O5: USR-04
A6: BLI-000990 | B6: BOM-000215-R05 | C6: BLI-000987 | D6: 1 | E6: 40 | F6: MAT-001547 | G6: 22 | H6: kg | I6: 0.05 | J6: =$G6 | K6: =ROUND($G6*(1+$I6),3) | L6: Make | N6: 46293 | O6: USR-04
A7: BLI-000991 | B7: BOM-000215-R05 | C7: BLI-000987 | D7: 1 | E7: 50 | F7: MAT-001544 | G7: 1 | H7: pcs | I7: 0 | J7: =$G7 | K7: =ROUND($G7*(1+$I7),3) | L7: Buy | M7: SUP-000089 | N7: 46293 | O7: USR-04
A8: BLI-000992 | B8: BOM-000215-R05 | C8: BLI-000987 | D8: 1 | E8: 60 | F8: MAT-001545 | G8: 1 | H8: pcs | I8: 0 | J8: =$G8 | K8: =ROUND($G8*(1+$I8),3) | L8: Buy | M8: SUP-000088 | N8: 46293 | O8: USR-04
A9: BLI-000993 | B9: BOM-000215-R05 | C9: BLI-000987 | D9: 1 | E9: 70 | F9: MAT-001546 | G9: 1 | H9: pcs | I9: 0 | J9: =$G9 | K9: =ROUND($G9*(1+$I9),3) | L9: Buy | M9: SUP-000087 | N9: 46293 | O9: USR-04
A10: BLI-000994 | B10: BOM-000215-R05 | C10: BLI-000987 | D10: 1 | E10: 80 | F10: MAT-001548 | G10: 1 | H10: pcs | I10: 0 | J10: =$G10 | K10: =ROUND($G10*(1+$I10),3) | L10: Buy | M10: SUP-000086 | N10: 46293 | O10: USR-04
A11: BLI-000950 | B11: BOM-000215-R04 | D11: 0 | E11: 10 | F11: PRD-000125 | G11: 1 | H11: pcs | I11: 0 | J11: =$G11 | K11: =ROUND($G11*(1+$I11),3) | L11: Make | N11: 46293 | O11: USR-04
A12: BLI-000951 | B12: BOM-000215-R04 | C12: BLI-000950 | D12: 1 | E12: 20 | F12: MAT-001542 | G12: 180 | H12: kg | I12: 0.05 | J12: =$G12 | K12: =ROUND($G12*(1+$I12),3) | L12: Make | N12: 46293 | O12: USR-04
A13: BLI-000952 | B13: BOM-000215-R04 | C13: BLI-000950 | D13: 1 | E13: 30 | F13: MAT-001543 | G13: 55 | H13: kg | I13: 0.05 | J13: =$G13 | K13: =ROUND($G13*(1+$I13),3) | L13: Make | N13: 46293 | O13: USR-04
A14: BLI-000953 | B14: BOM-000215-R04 | C14: BLI-000950 | D14: 1 | E14: 40 | F14: MAT-001547 | G14: 22 | H14: kg | I14: 0.05 | J14: =$G14 | K14: =ROUND($G14*(1+$I14),3) | L14: Make | N14: 46293 | O14: USR-04
A15: BLI-000954 | B15: BOM-000215-R04 | C15: BLI-000950 | D15: 1 | E15: 50 | F15: MAT-001544 | G15: 1 | H15: pcs | I15: 0 | J15: =$G15 | K15: =ROUND($G15*(1+$I15),3) | L15: Buy | M15: SUP-000089 | N15: 46293 | O15: USR-04
A16: BLI-000955 | B16: BOM-000215-R04 | C16: BLI-000950 | D16: 1 | E16: 60 | F16: MAT-001545 | G16: 1 | H16: pcs | I16: 0 | J16: =$G16 | K16: =ROUND($G16*(1+$I16),3) | L16: Buy | M16: SUP-000088 | N16: 46293 | O16: USR-04
A17: BLI-000956 | B17: BOM-000215-R04 | C17: BLI-000950 | D17: 1 | E17: 70 | F17: MAT-001546 | G17: 1 | H17: pcs | I17: 0 | J17: =$G17 | K17: =ROUND($G17*(1+$I17),3) | L17: Buy | M17: SUP-000087 | N17: 46293 | O17: USR-04
A18: BLI-000957 | B18: BOM-000215-R04 | C18: BLI-000950 | D18: 1 | E18: 80 | F18: MAT-001548 | G18: 1 | H18: pcs | I18: 0 | J18: =$G18 | K18: =ROUND($G18*(1+$I18),3) | L18: Buy | M18: SUP-000086 | N18: 46293 | O18: USR-04
A19: BLI-000900 | B19: BOM-000216-R02 | D19: 0 | E19: 10 | F19: PRD-000126 | G19: 1 | H19: pcs | I19: 0 | J19: =$G19 | K19: =ROUND($G19*(1+$I19),3) | L19: Make | N19: 46293 | O19: USR-04
A20: BLI-000901 | B20: BOM-000216-R02 | C20: BLI-000900 | D20: 1 | E20: 20 | F20: MAT-001542 | G20: 95 | H20: kg | I20: 0.05 | J20: =$G20 | K20: =ROUND($G20*(1+$I20),3) | L20: Make | N20: 46293 | O20: USR-04
A21: BLI-000902 | B21: BOM-000216-R02 | C21: BLI-000900 | D21: 1 | E21: 30 | F21: MAT-001547 | G21: 14 | H21: kg | I21: 0.05 | J21: =$G21 | K21: =ROUND($G21*(1+$I21),3) | L21: Make | N21: 46293 | O21: USR-04
A22: BLI-000903 | B22: BOM-000216-R02 | C22: BLI-000900 | D22: 1 | E22: 40 | F22: MAT-001544 | G22: 1 | H22: pcs | I22: 0 | J22: =$G22 | K22: =ROUND($G22*(1+$I22),3) | L22: Buy | M22: SUP-000089 | N22: 46293 | O22: USR-04
A23: BLI-000904 | B23: BOM-000216-R02 | C23: BLI-000900 | D23: 1 | E23: 50 | F23: MAT-001545 | G23: 1 | H23: pcs | I23: 0 | J23: =$G23 | K23: =ROUND($G23*(1+$I23),3) | L23: Buy | M23: SUP-000088 | N23: 46293 | O23: USR-04
A24: BLI-000905 | B24: BOM-000216-R02 | C24: BLI-000900 | D24: 1 | E24: 60 | F24: MAT-001546 | G24: 1 | H24: pcs | I24: 0 | J24: =$G24 | K24: =ROUND($G24*(1+$I24),3) | L24: Buy | M24: SUP-000087 | N24: 46293 | O24: USR-04
A25: BLI-000906 | B25: BOM-000216-R02 | C25: BLI-000900 | D25: 1 | E25: 70 | F25: MAT-001548 | G25: 1 | H25: pcs | I25: 0 | J25: =$G25 | K25: =ROUND($G25*(1+$I25),3) | L25: Buy | M25: SUP-000086 | N25: 46293 | O25: USR-04

Sheet Time_Study
A1: Time_Study | B1: زمان‌سنجی عملیات توسط مهندسی؛ نفرساعت = (آماده‌سازی + زمان استاندارد×مقدار سفارش×(1+ضایعات))/60 × تعداد اپراتور. جمع نفرساعت مستقیماً وارد دستمزد مستقیم در Cost_Lines می‌شود.
A2: System_ID | B2: Project_ID | C2: Product_ID | D2: Operation | E2: Work_Center | F2: Setup_Min | G2: Std_Min_Per_Unit | H2: Operators | I2: Scrap_Allowance_% | J2: Order_Qty | K2: Man_Min_Total | L2: Man_Hours_Total | M2: Man_Hours_Per_Unit | N2: Status_ID | O2: Create_Date | P2: Created_By
A3: TST-000001 | B3: PRJ-2026-00125 | C3: PRD-000125 | D3: برش و آماده‌سازی مواد اولیه | E3: WC-CUT | F3: 240 | G3: 900 | H3: 2 | I3: 0.02 | J3: =SUMIFS(Order_Lines!$E$3:$E$20,Order_Lines!$B$3:$B$20,XLOOKUP($B3,Projects!$A$3:$A$20,Projects!$C$3:$C$20,""),Order_Lines!$D$3:$D$20,$C3) | K3: =IF($J3=0,0,$F3+$G3*$J3*(1+$I3)) | L3: =ROUND($K3/60*$H3,2) | M3: =IF($J3=0,0,ROUND($L3/$J3,2)) | N3: Approved | O3: 46292 | P3: USR-04
A4: TST-000002 | B4: PRJ-2026-00125 | C4: PRD-000125 | D4: ماشین‌کاری پوسته (CNC) | E4: WC-CNC | F4: 480 | G4: 2400 | H4: 1 | I4: 0.02 | J4: =SUMIFS(Order_Lines!$E$3:$E$20,Order_Lines!$B$3:$B$20,XLOOKUP($B4,Projects!$A$3:$A$20,Projects!$C$3:$C$20,""),Order_Lines!$D$3:$D$20,$C4) | K4: =IF($J4=0,0,$F4+$G4*$J4*(1+$I4)) | L4: =ROUND($K4/60*$H4,2) | M4: =IF($J4=0,0,ROUND($L4/$J4,2)) | N4: Approved | O4: 46292 | P4: USR-04
A5: TST-000003 | B5: PRJ-2026-00125 | C5: PRD-000125 | D5: ماشین‌کاری پروانه و بالانس استاتیک | E5: WC-CNC | F5: 240 | G5: 1200 | H5: 1 | I5: 0.02 | J5: =SUMIFS(Order_Lines!$E$3:$E$20,Order_Lines!$B$3:$B$20,XLOOKUP($B5,Projects!$A$3:$A$20,Projects!$C$3:$C$20,""),Order_Lines!$D$3:$D$20,$C5) | K5: =IF($J5=0,0,$F5+$G5*$J5*(1+$I5)) | L5: =ROUND($K5/60*$H5,2) | M5: =IF($J5=0,0,ROUND($L5/$J5,2)) | N5: Approved | O5: 46292 | P5: USR-04
A6: TST-000004 | B6: PRJ-2026-00125 | C6: PRD-000125 | D6: مونتاژ عمومی و بالانس دینامیک | E6: WC-ASM | F6: 360 | G6: 2700 | H6: 2 | I6: 0.02 | J6: =SUMIFS(Order_Lines!$E$3:$E$20,Order_Lines!$B$3:$B$20,XLOOKUP($B6,Projects!$A$3:$A$20,Projects!$C$3:$C$20,""),Order_Lines!$D$3:$D$20,$C6) | K6: =IF($J6=0,0,$F6+$G6*$J6*(1+$I6)) | L6: =ROUND($K6/60*$H6,2) | M6: =IF($J6=0,0,ROUND($L6/$J6,2)) | N6: Approved | O6: 46292 | P6: USR-04
A7: TST-000005 | B7: PRJ-2026-00125 | C7: PRD-000125 | D7: تست عملکردی نهایی و کنترل کیفیت | E7: WC-QC | F7: 60 | G7: 60 | H7: 1 | I7: 0.02 | J7: =SUMIFS(Order_Lines!$E$3:$E$20,Order_Lines!$B$3:$B$20,XLOOKUP($B7,Projects!$A$3:$A$20,Projects!$C$3:$C$20,""),Order_Lines!$D$3:$D$20,$C7) | K7: =IF($J7=0,0,$F7+$G7*$J7*(1+$I7)) | L7: =ROUND($K7/60*$H7,2) | M7: =IF($J7=0,0,ROUND($L7/$J7,2)) | N7: Approved | O7: 46292 | P7: USR-04

Sheet Materials
A1: Materials
A2: System_ID | B2: Material_Code | C2: Material_Description | D2: Material_Type | E2: Specification | F2: UoM | G2: Make_Buy_Default | H2: Preferred_Supplier | I2: Is_Active
A3: MAT-001542 | B3: MAT-01 | C3: پوسته چدنی (Cast Iron Casing) | D3: Raw Material | E3: GG-25 مطابق DIN 1691 | F3: kg | G3: Make | I3: 1
A4: MAT-001543 | B4: MAT-02 | C4: پروانه فولاد ضدزنگ (Impeller SS316) | D4: Raw Material | E4: AISI 316L | F4: kg | G4: Make | I4: 1
A5: MAT-001544 | B5: MAT-03 | C5: بلبرینگ کف‌گرد (Thrust Bearing) | D5: Purchased Part | E5: SKF 29420 E | F5: pcs | G5: Buy | H5: SUP-000089 | I5: 1
A6: MAT-001545 | B6: MAT-04 | C6: مکانیکال سیل (Mechanical Seal) | D6: Purchased Part | E6: EagleBurgmann H74 | F6: pcs | G6: Buy | H6: SUP-000088 | I6: 1
A7: MAT-001546 | B7: MAT-05 | C7: الکتروموتور 45kW | D7: Purchased Part | E7: IEC 400V 50Hz IM B3 | F7: pcs | G7: Buy | H7: SUP-000087 | I7: 1
A8: MAT-001547 | B8: MAT-06 | C8: شفت فولادی (Shaft CK45) | D8: Raw Material | E8: CK45 مطابق DIN 17200 | F8: kg | G8: Make | I8: 1
A9: MAT-001548 | B9: MAT-07 | C9: بسته‌بندی صادراتی چوبی | D9: Packaging | E9: ISPM-15 | F9: pcs | G9: Buy | H9: SUP-000086 | I9: 1

Sheet Equipment
A1: Equipment | B1: لیست مرجع تجهیزات؛ مهندسی از این فهرست در Project_Equipment انتخاب می‌کند و بازرگانی همان ردیف‌ها را قیمت می‌دهد. برای تجهیزات وارداتی نرخ ارز از Settings اعمال می‌شود.
A2: System_ID | B2: Equipment_Code | C2: Equipment_Name | D2: Specification | E2: UoM | F2: Origin | G2: Lead_Time_Days | H2: Estimated_Price | I2: Currency | J2: Is_Active
A3: EQP-000001 | B3: EQP-01 | C3: جرثقیل سقفی 5 تن | D3: DIN 15018 — دهانه 12 متر | E3: set | F3: Domestic | G3: 45 | H3: 8500000000 | I3: IRR | J3: 1
A4: EQP-000002 | B4: EQP-02 | C4: دستگاه جوشکاری صنعتی | D4: Fronius TPS 400i | E4: pcs | F4: Imported | G4: 60 | H4: 4200 | I4: USD | J4: 1
A5: EQP-000003 | B5: EQP-03 | C5: پرس هیدرولیک 100 تن | D5: قاب چهارستونه — 1000×1000 | E5: pcs | F5: Domestic | G5: 90 | H5: 3000000000 | I5: IRR | J5: 1
A6: EQP-000004 | B6: EQP-04 | C6: تست‌بنچ پمپ (ادوات دقیق) | D6: فلومتر تا 300 m3/h + درایو VFD | E6: set | F6: Imported | G6: 75 | H6: 12000 | I6: USD | J6: 1

Sheet Project_Equipment
A1: Project_Equipment | B1: ستون‌های آبی (B:F) ورودی مهندسی — انتخاب از لیست مرجع تجهیزات؛ ستون‌های قیمت (G:K) فقط ورودی بازرگانی پس از باز شدن گیت بازرگانی. قیمت وارداتی = نرخ ارزی × نرخ ارز (Settings)؛ قیمت نهایی شامل حمل و نصب.
A2: System_ID | B2: Project_ID | C2: Equipment_ID | D2: Qty | E2: Need_Date | F2: Engineering_Notes | G2: Unit_Price_Quote | H2: Currency | I2: Fx_Rate | J2: Unit_Price_IRR | K2: Transport_Cost | L2: Installation_Cost | M2: Total_Cost_IRR | N2: Priced_Flag | O2: Status_ID | P2: Create_Date | Q2: Created_By
A3: PEQ-000001 | B3: PRJ-2026-00125 | C3: EQP-000004 | D3: 1 | E3: 46351 | F3: تست عملکردی پمپ‌ها قبل از تحویل — شامل نصب در سایت تست | G3: 12500 | H3: USD | I3: =IF($H3="IRR",1,Settings!$B$13) | J3: =IF($G3="","",ROUND($G3*$I3,0)) | K3: 150000000 | L3: 80000000 | M3: =IF($G3="","",ROUND($G3*$I3*$D3+IF(ISNUMBER($K3),$K3,0)+IF(ISNUMBER($L3),$L3,0),0)) | N3: =IF($G3="","PENDING","PRICED") | O3: Priced | P3: 46297 | Q3: USR-06
A4: PEQ-000002 | B4: PRJ-2026-00125 | C4: EQP-000001 | D4: 1 | E4: 46346 | F4: جابجایی پوسته‌ها در سالن مونتاژ | G4: 8900000000 | H4: IRR | I4: =IF($H4="IRR",1,Settings!$B$13) | J4: =IF($G4="","",ROUND($G4*$I4,0)) | K4: 200000000 | L4: 120000000 | M4: =IF($G4="","",ROUND($G4*$I4*$D4+IF(ISNUMBER($K4),$K4,0)+IF(ISNUMBER($L4),$L4,0),0)) | N4: =IF($G4="","PENDING","PRICED") | O4: Priced | P4: 46297 | Q4: USR-06
A5: PEQ-000003 | B5: PRJ-2026-00126 | C5: EQP-000002 | D5: 2 | E5: 46397 | F5: جوشکاری بدنه — در انتظار تکمیل مهندسی | I5: =IF($H5="IRR",1,Settings!$B$13) | J5: =IF($G5="","",ROUND($G5*$I5,0)) | M5: =IF($G5="","",ROUND($G5*$I5*$D5+IF(ISNUMBER($K5),$K5,0)+IF(ISNUMBER($L5),$L5,0),0)) | N5: =IF($G5="","PENDING","PRICED") | O5: Pending | P5: 46288 | Q5: USR-04

Sheet Supplier_Quotes
A1: Supplier_Quotes | B1: استعلام به تفکیک ماده؛ انتخاب تأمین‌کننده در ردیف‌ها (نه فقط کمترین قیمت) توسط مسئول مجاز.
A2: System_ID | B2: Project_ID | C2: Material_ID | D2: Qty_Required | E2: Quoted_Date | F2: Valid_Until | G2: Status_ID | H2: Selected_Line_ID | I2: Create_Date | J2: Created_By
A3: SQT-2026-00545 | B3: PRJ-2026-00125 | C3: MAT-001545 | D3: 2 | E3: 46280 | F3: 46366 | G3: Closed | H3: SQL-002354 | I3: 46280 | J3: USR-06
A4: SQT-2026-00546 | B4: PRJ-2026-00125 | C4: MAT-001544 | D4: 2 | E4: 46280 | F4: 46346 | G4: Closed | H4: SQL-002360 | I4: 46280 | J4: USR-06
A5: SQT-2026-00547 | B5: PRJ-2026-00125 | C5: MAT-001546 | D5: 2 | E5: 46280 | F5: 46357 | G5: Closed | H5: SQL-002364 | I5: 46280 | J5: USR-06
A6: SQT-2026-00548 | B6: PRJ-2026-00125 | C6: MAT-001548 | D6: 2 | E6: 46280 | F6: 46376 | G6: Closed | H6: SQL-002368 | I6: 46280 | J6: USR-06

Sheet Supplier_Quote_Lines
A1: Supplier_Quote_Lines | B1: معیارهای قیمت/کیفیت/زمان/ریسک؛ Score_Total صرفاً جنبه مقایسه دارد و سیستم به‌طور خودکار «بهترین» را اعلام نمی‌کند.
A2: System_ID | B2: Supplier_Quote_ID | C2: Supplier_ID | D2: Unit_Price | E2: Currency | F2: MOQ | G2: Lead_Time_Days | H2: Payment_Terms | I2: Incoterm | J2: Freight | K2: Valid_To | L2: Price_Source | M2: Price_Confirm_Status | N2: Quality_Score | O2: OnTime_Score | P2: Capacity_Score | Q2: Risk_Score | R2: Longevity_Score | S2: Score_Total | T2: Selected | U2: Landed_Estimate | V2: Create_Date | W2: Created_By
A3: SQL-002354 | B3: SQT-2026-00545 | C3: SUP-000088 | D3: 185000000 | E3: IRR | F3: 1 | G3: 30 | H3: 30 days | I3: CPT | J3: 2000000 | K3: 46356 | L3: Email Quote 12-Sep | M3: Confirmed | N3: 5 | O3: 5 | P3: 4 | Q3: 2 | R3: 3 | S3: =SUM($N3:$R3) | T3: 1 | U3: =$D3+$J3 | V3: 46280 | W3: USR-06
A4: SQL-002355 | B4: SQT-2026-00545 | C4: SUP-000089 | D4: 172000000 | E4: IRR | F4: 2 | G4: 45 | H4: 60 days | I4: CPT | J4: 2500000 | K4: 46341 | L4: Portal RFQ | M4: Confirmed | N4: 4 | O4: 4 | P4: 3 | Q4: 3 | R4: 3 | S4: =SUM($N4:$R4) | T4: 0 | U4: =$D4+$J4 | V4: 46280 | W4: USR-06
A5: SQL-002356 | B5: SQT-2026-00545 | C5: SUP-000090 | D5: 190000000 | E5: IRR | F5: 1 | G5: 25 | H5: advance | I5: EXW | J5: 3000000 | K5: 46366 | L5: Phone + Email | M5: Confirmed | N5: 3 | O5: 3 | P5: 2 | Q5: 4 | R5: 2 | S5: =SUM($N5:$R5) | T5: 0 | U5: =$D5+$J5 | V5: 46280 | W5: USR-06
A6: SQL-002360 | B6: SQT-2026-00546 | C6: SUP-000089 | D6: 95000000 | E6: IRR | F6: 1 | G6: 25 | H6: 30 days | I6: CPT | J6: 1200000 | K6: 46346 | L6: Email Quote 14-Sep | M6: Confirmed | N6: 5 | O6: 4 | P6: 4 | Q6: 2 | R6: 4 | S6: =SUM($N6:$R6) | T6: 1 | U6: =$D6+$J6 | V6: 46280 | W6: USR-06
A7: SQL-002361 | B7: SQT-2026-00546 | C7: SUP-000090 | D7: 99000000 | E7: IRR | F7: 1 | G7: 30 | H7: 45 days | I7: EXW | J7: 1500000 | K7: 46336 | L7: Portal RFQ | M7: Confirmed | N7: 4 | O7: 3 | P7: 3 | Q7: 3 | R7: 3 | S7: =SUM($N7:$R7) | T7: 0 | U7: =$D7+$J7 | V7: 46280 | W7: USR-06
A8: SQL-002364 | B8: SQT-2026-00547 | C8: SUP-000087 | D8: 2500 | E8: USD | F8: 1 | G8: 45 | H8: 45 days | I8: CPT | J8: 30 | K8: 46357 | L8: Signed Quote | M8: Confirmed | N8: 5 | O8: 4 | P8: 5 | Q8: 2 | R8: 5 | S8: =SUM($N8:$R8) | T8: 1 | U8: =$D8+$J8 | V8: 46280 | W8: USR-06
A9: SQL-002365 | B9: SQT-2026-00547 | C9: SUP-000090 | D9: 1220000000 | E9: IRR | F9: 2 | G9: 60 | H9: 60 days | I9: EXW | J9: 18000000 | K9: 46351 | L9: Email Quote | M9: Confirmed | N9: 4 | O9: 3 | P9: 4 | Q9: 3 | R9: 4 | S9: =SUM($N9:$R9) | T9: 0 | U9: =$D9+$J9 | V9: 46280 | W9: USR-06
A10: SQL-002368 | B10: SQT-2026-00548 | C10: SUP-000086 | D10: 12000000 | E10: IRR | F10: 1 | G10: 10 | H10: cash | I10: EXW | J10: 0 | K10: 46376 | L10: Price list | M10: Confirmed | N10: 4 | O10: 5 | P10: 5 | Q10: 1 | R10: 5 | S10: =SUM($N10:$R10) | T10: 1 | U10: =$D10+$J10 | V10: 46280 | W10: USR-06

Sheet Procurement
A1: Procurement | B1: تصمیم خرید تأییدشده + Price Build-up: Unit + Freight + Insurance + Customs + Handling + Other = Landed (با تبدیل ارز).
A2: System_ID | B2: Project_ID | C2: Material_ID | D2: Supplier_ID | E2: Buyer | F2: Currency | G2: Fx_Rate | H2: Buy_Qty | I2: Unit_Purchase_Price | J2: MOQ_Applied | K2: Lead_Time_Days | L2: Payment_Terms | M2: Incoterm | N2: Freight_Per_Unit | O2: Insurance_Per_Unit | P2: Customs_Per_Unit | Q2: Handling_Per_Unit | R2: Other_Per_Unit | S2: Landed_Cost_Unit | T2: Price_Date | U2: Price_Source | V2: Price_Valid_To | W2: Price_Expired_Flag | X2: Status_ID | Y2: Create_Date | Z2: Created_By
A3: PRC-0001 | B3: PRJ-2026-00125 | C3: MAT-001545 | D3: SUP-000088 | E3: USR-06 | F3: IRR | G3: 1 | H3: 2 | I3: 185000000 | J3: 1 | K3: 30 | L3: 30 days | M3: CPT | N3: 2000000 | O3: 0 | P3: 0 | Q3: 0 | R3: 0 | S3: =ROUND(($I3+$N3+$O3+$P3+$Q3+$R3)*$G3,0) | T3: 46280 | U3: Email Quote 12-Sep | V3: 46356 | W3: =IF(ISBLANK($V3),"",IF($V3<TODAY(),1,0)) | X3: Approved | Y3: 46293 | Z3: USR-06
A4: PRC-0002 | B4: PRJ-2026-00125 | C4: MAT-001544 | D4: SUP-000089 | E4: USR-06 | F4: IRR | G4: 1 | H4: 2 | I4: 95000000 | J4: 1 | K4: 25 | L4: 30 days | M4: CPT | N4: 1200000 | O4: 0 | P4: 0 | Q4: 0 | R4: 0 | S4: =ROUND(($I4+$N4+$O4+$P4+$Q4+$R4)*$G4,0) | T4: 46280 | U4: Email Quote 14-Sep | V4: 46346 | W4: =IF(ISBLANK($V4),"",IF($V4<TODAY(),1,0)) | X4: Approved | Y4: 46293 | Z4: USR-06
A5: PRC-0003 | B5: PRJ-2026-00125 | C5: MAT-001546 | D5: SUP-000087 | E5: USR-06 | F5: USD | G5: 500000 | H5: 2 | I5: 2500 | J5: 1 | K5: 45 | L5: 45 days | M5: CPT | N5: 30 | O5: 0 | P5: 0 | Q5: 0 | R5: 0 | S5: =ROUND(($I5+$N5+$O5+$P5+$Q5+$R5)*$G5,0) | T5: 46280 | U5: Signed Quote | V5: 46357 | W5: =IF(ISBLANK($V5),"",IF($V5<TODAY(),1,0)) | X5: Approved | Y5: 46293 | Z5: USR-06
A6: PRC-0004 | B6: PRJ-2026-00125 | C6: MAT-001548 | D6: SUP-000086 | E6: USR-06 | F6: IRR | G6: 1 | H6: 2 | I6: 12000000 | J6: 1 | K6: 10 | L6: cash | M6: EXW | N6: 0 | O6: 0 | P6: 0 | Q6: 0 | R6: 0 | S6: =ROUND(($I6+$N6+$O6+$P6+$Q6+$R6)*$G6,0) | T6: 46280 | U6: Price list | V6: 46376 | W6: =IF(ISBLANK($V6),"",IF($V6<TODAY(),1,0)) | X6: Approved | Y6: 46293 | Z6: USR-06

Sheet Purchase_Prices
A1: Purchase_Prices | B1: قیمت خرید با Revision؛ Expired_Flag=1 یعنی قیمت منقضی و از Costing کنار گذاشته می‌شود. Landed=(اجزا)×Fx.
A2: System_ID | B2: Material_ID | C2: Supplier_ID | D2: Revision | E2: Price_Date | F2: Price_Source | G2: Currency | H2: Fx_Rate | I2: Unit_Price | J2: Freight_Per_Unit | K2: Insurance_Per_Unit | L2: Customs_Per_Unit | M2: Handling_Per_Unit | N2: Other_Per_Unit | O2: Landed_Cost_Unit | P2: Valid_From | Q2: Valid_To | R2: Expired_Flag | S2: Status_ID | T2: Approved_By | U2: Create_Date | V2: Created_By
A3: PPR-000554 | B3: MAT-001542 | C3: SUP-000090 | D3: R01 | E3: 46280 | F3: Signed Quote | G3: USD | H3: 500000 | I3: 1.15 | J3: 0.05 | K3: 0 | L3: 0 | M3: 0 | N3: 0 | O3: =ROUND(($I3+$J3+$K3+$L3+$M3+$N3)*$H3,0) | P3: 46280 | Q3: 46356 | R3: =IF(ISBLANK($Q3),1,IF($Q3<TODAY(),1,0)) | S3: Approved | T3: USR-06 | U3: 46280 | V3: USR-06
A4: PPR-000555 | B4: MAT-001543 | C4: SUP-000090 | D4: R01 | E4: 46280 | F4: Signed Quote | G4: USD | H4: 500000 | I4: 3.2 | J4: 0.05 | K4: 0 | L4: 0 | M4: 0 | N4: 0 | O4: =ROUND(($I4+$J4+$K4+$L4+$M4+$N4)*$H4,0) | P4: 46280 | Q4: 46356 | R4: =IF(ISBLANK($Q4),1,IF($Q4<TODAY(),1,0)) | S4: Approved | T4: USR-06 | U4: 46280 | V4: USR-06
A5: PPR-000556 | B5: MAT-001544 | C5: SUP-000089 | D5: R01 | E5: 46280 | F5: Email Quote | G5: IRR | H5: 1 | I5: 95000000 | J5: 1200000 | K5: 0 | L5: 0 | M5: 0 | N5: 0 | O5: =ROUND(($I5+$J5+$K5+$L5+$M5+$N5)*$H5,0) | P5: 46280 | Q5: 46346 | R5: =IF(ISBLANK($Q5),1,IF($Q5<TODAY(),1,0)) | S5: Approved | T5: USR-06 | U5: 46280 | V5: USR-06
A6: PPR-000557 | B6: MAT-001545 | C6: SUP-000088 | D6: R01 | E6: 46280 | F6: Email Quote | G6: IRR | H6: 1 | I6: 185000000 | J6: 2000000 | K6: 0 | L6: 0 | M6: 0 | N6: 0 | O6: =ROUND(($I6+$J6+$K6+$L6+$M6+$N6)*$H6,0) | P6: 46280 | Q6: 46356 | R6: =IF(ISBLANK($Q6),1,IF($Q6<TODAY(),1,0)) | S6: Approved | T6: USR-06 | U6: 46280 | V6: USR-06
A7: PPR-000558 | B7: MAT-001546 | C7: SUP-000087 | D7: R01 | E7: 46280 | F7: Signed Quote | G7: USD | H7: 500000 | I7: 2500 | J7: 30 | K7: 0 | L7: 0 | M7: 0 | N7: 0 | O7: =ROUND(($I7+$J7+$K7+$L7+$M7+$N7)*$H7,0) | P7: 46280 | Q7: 46357 | R7: =IF(ISBLANK($Q7),1,IF($Q7<TODAY(),1,0)) | S7: Approved | T7: USR-06 | U7: 46280 | V7: USR-06
A8: PPR-000559 | B8: MAT-001547 | C8: SUP-000090 | D8: R01 | E8: 46280 | F8: Signed Quote | G8: IRR | H8: 1 | I8: 2200000 | J8: 0 | K8: 0 | L8: 0 | M8: 0 | N8: 0 | O8: =ROUND(($I8+$J8+$K8+$L8+$M8+$N8)*$H8,0) | P8: 46280 | Q8: 46275 | R8: =IF(ISBLANK($Q8),1,IF($Q8<TODAY(),1,0)) | S8: Expired | T8: USR-06 | U8: 46280 | V8: USR-06
A9: PPR-000560 | B9: MAT-001547 | C9: SUP-000090 | D9: R02 | E9: 46295 | F9: Revised Quote | G9: IRR | H9: 1 | I9: 2450000 | J9: 0 | K9: 0 | L9: 0 | M9: 0 | N9: 0 | O9: =ROUND(($I9+$J9+$K9+$L9+$M9+$N9)*$H9,0) | P9: 46296 | Q9: 46357 | R9: =IF(ISBLANK($Q9),1,IF($Q9<TODAY(),1,0)) | S9: Approved | T9: USR-06 | U9: 46295 | V9: USR-06
A10: PPR-000561 | B10: MAT-001548 | C10: SUP-000086 | D10: R01 | E10: 46280 | F10: Price list | G10: IRR | H10: 1 | I10: 12000000 | J10: 0 | K10: 0 | L10: 0 | M10: 0 | N10: 0 | O10: =ROUND(($I10+$J10+$K10+$L10+$M10+$N10)*$H10,0) | P10: 46280 | Q10: 46376 | R10: =IF(ISBLANK($Q10),1,IF($Q10<TODAY(),1,0)) | S10: Approved | T10: USR-06 | U10: 46280 | V10: USR-06

Sheet Planning
A1: Planning | B1: Required = Bom_Qty × (1+Scrap%) × Order_Qty. Order_Qty زنده از Order_Lines خوانده می‌شود. Need_Date = زمان‌بندی نیاز به اقلام برای تولید (ورودی برنامه‌ریزی)؛ تاریخ سفارش‌گذاری پیشنهادی = تاریخ نیاز − لیدتایم.
A2: System_ID | B2: Project_ID | C2: BOM_Revision_ID | D2: BOM_Line_ID | E2: Product_ID | F2: Material_ID | G2: Make_Buy | H2: Order_Qty | I2: Bom_Qty_Per | J2: Scrap_% | K2: Required_Qty | L2: Stock_On_Hand | M2: Reserved | N2: Deficit | O2: Buy_Qty | P2: Lead_Time_Days | Q2: Supply_Date | R2: Status_ID | S2: Need_Date | T2: Suggested_Order_Date | U2: Create_Date | V2: Created_By
A3: PLN-000001 | B3: PRJ-2026-00125 | C3: BOM-000215-R05 | D3: BLI-000988 | E3: PRD-000125 | F3: MAT-001542 | G3: Make | H3: =SUMIFS(Order_Lines!$E$3:$E$20,Order_Lines!$D$3:$D$20,$E3,Order_Lines!$B$3:$B$20,XLOOKUP($B3,Projects!$A$3:$A$10,Projects!$C$3:$C$10,0)) | I3: 180 | J3: 0.05 | K3: =ROUND($H3*$I3*(1+$J3),2) | L3: =IFERROR(XLOOKUP($F3,Inventory!$B$3:$B$20,Inventory!$C$3:$C$20,0),0) | M3: =IFERROR(XLOOKUP($F3,Inventory!$B$3:$B$20,Inventory!$D$3:$D$20,0),0) | N3: =MAX($K3-($L3-$M3),0) | O3: =$N3 | P3: 15 | Q3: =TODAY()+$P3 | R3: Approved | S3: 46344 | T3: =IF($S3="","",$S3-$P3) | U3: 46296 | V3: USR-05
A4: PLN-000002 | B4: PRJ-2026-00125 | C4: BOM-000215-R05 | D4: BLI-000989 | E4: PRD-000125 | F4: MAT-001543 | G4: Make | H4: =SUMIFS(Order_Lines!$E$3:$E$20,Order_Lines!$D$3:$D$20,$E4,Order_Lines!$B$3:$B$20,XLOOKUP($B4,Projects!$A$3:$A$10,Projects!$C$3:$C$10,0)) | I4: 55 | J4: 0.05 | K4: =ROUND($H4*$I4*(1+$J4),2) | L4: =IFERROR(XLOOKUP($F4,Inventory!$B$3:$B$20,Inventory!$C$3:$C$20,0),0) | M4: =IFERROR(XLOOKUP($F4,Inventory!$B$3:$B$20,Inventory!$D$3:$D$20,0),0) | N4: =MAX($K4-($L4-$M4),0) | O4: =$N4 | P4: 15 | Q4: =TODAY()+$P4 | R4: Approved | S4: 46344 | T4: =IF($S4="","",$S4-$P4) | U4: 46296 | V4: USR-05
A5: PLN-000003 | B5: PRJ-2026-00125 | C5: BOM-000215-R05 | D5: BLI-000990 | E5: PRD-000125 | F5: MAT-001547 | G5: Make | H5: =SUMIFS(Order_Lines!$E$3:$E$20,Order_Lines!$D$3:$D$20,$E5,Order_Lines!$B$3:$B$20,XLOOKUP($B5,Projects!$A$3:$A$10,Projects!$C$3:$C$10,0)) | I5: 22 | J5: 0.05 | K5: =ROUND($H5*$I5*(1+$J5),2) | L5: =IFERROR(XLOOKUP($F5,Inventory!$B$3:$B$20,Inventory!$C$3:$C$20,0),0) | M5: =IFERROR(XLOOKUP($F5,Inventory!$B$3:$B$20,Inventory!$D$3:$D$20,0),0) | N5: =MAX($K5-($L5-$M5),0) | O5: =$N5 | P5: 15 | Q5: =TODAY()+$P5 | R5: Approved | S5: 46344 | T5: =IF($S5="","",$S5-$P5) | U5: 46296 | V5: USR-05
A6: PLN-000004 | B6: PRJ-2026-00125 | C6: BOM-000215-R05 | D6: BLI-000991 | E6: PRD-000125 | F6: MAT-001544 | G6: Buy | H6: =SUMIFS(Order_Lines!$E$3:$E$20,Order_Lines!$D$3:$D$20,$E6,Order_Lines!$B$3:$B$20,XLOOKUP($B6,Projects!$A$3:$A$10,Projects!$C$3:$C$10,0)) | I6: 1 | J6: 0 | K6: =ROUND($H6*$I6*(1+$J6),2) | L6: =IFERROR(XLOOKUP($F6,Inventory!$B$3:$B$20,Inventory!$C$3:$C$20,0),0) | M6: =IFERROR(XLOOKUP($F6,Inventory!$B$3:$B$20,Inventory!$D$3:$D$20,0),0) | N6: =MAX($K6-($L6-$M6),0) | O6: =$N6 | P6: 15 | Q6: =TODAY()+$P6 | R6: Approved | S6: 46344 | T6: =IF($S6="","",$S6-$P6) | U6: 46296 | V6: USR-05
A7: PLN-000005 | B7: PRJ-2026-00125 | C7: BOM-000215-R05 | D7: BLI-000992 | E7: PRD-000125 | F7: MAT-001545 | G7: Buy | H7: =SUMIFS(Order_Lines!$E$3:$E$20,Order_Lines!$D$3:$D$20,$E7,Order_Lines!$B$3:$B$20,XLOOKUP($B7,Projects!$A$3:$A$10,Projects!$C$3:$C$10,0)) | I7: 1 | J7: 0 | K7: =ROUND($H7*$I7*(1+$J7),2) | L7: =IFERROR(XLOOKUP($F7,Inventory!$B$3:$B$20,Inventory!$C$3:$C$20,0),0) | M7: =IFERROR(XLOOKUP($F7,Inventory!$B$3:$B$20,Inventory!$D$3:$D$20,0),0) | N7: =MAX($K7-($L7-$M7),0) | O7: =$N7 | P7: 15 | Q7: =TODAY()+$P7 | R7: Approved | S7: 46344 | T7: =IF($S7="","",$S7-$P7) | U7: 46296 | V7: USR-05
